Workbook

Sheet Worksheet
A1: Student Id | B1: Name
A2: 20301033 | B2: Amlan Dutta | C2: Male | D2: CS | E2: 1859967435 | F2: amlan.dutta@g.bracu.ac.bd
A3: 22101425 | B3: Khandokar Yusuf Khalid | C3: Male | D3: CSE | E3: 1700628562 | F3: khandokar.yusuf.khalid@g.bracu.ac.bd
A4: 22101748 | B4: Mst. Zubaida Haque Jetu | C4: Female | D4: CSE | E4: 1566086142 | F4: zubaida.haque.jetu@g.bracu.ac.bd
A5: 22299296 | B5: Raihan Karim | C5: Male | D5: CSE | E5: 1758485240 | F5: raihan.karim@g.bracu.ac.bd
A6: 23101075 | B6: Abida Nowsheen | C6: Female | D6: CSE | E6: 1754757153 | F6: abida.nowsheen@g.bracu.ac.bd
A7: 23101101 | B7: Jubaida Jahan Prapti | C7: Female | D7: CSE | E7: 1613056655 | F7: jubaida.jahan.prapti@g.bracu.ac.bd
A8: 23101271 | B8: Sazid Chowdhury | C8: Male | D8: CS | E8: 1877698491 | F8: sazid.choudhury@g.bracu.ac.bd
A9: 23101378 | B9: Sharif Al Rezoan | C9: Male | D9: CSE | E9: 1648547158 | F9: sharif.al.rezoan@g.bracu.ac.bd
A10: 23141047 | B10: Mohammad Rashik Ruhullah Rafi | C10: Male | D10: CS | E10: 1866744410 | F10: rashik.ruhullah.rafi@g.bracu.ac.bd
A11: 23201093 | B11: S.A.Rahman | C11: Male | D11: CSE | E11: 1405196982 | F11: s.a.rahman@g.bracu.ac.bd
A12: 23201659 | B12: Maisha Sanjida Akhi | C12: Female | D12: CSE | E12: 1929122929 | F12: maisha.sanjida.akhi@g.bracu.ac.bd
A13: 23301410 | B13: Rafid Shahriar Auvro | C13: Male | D13: CSE | E13: 1733986999 | F13: rafid.shahriar.auvro@g.bracu.ac.bd
... A38: 24341137 | B38: G.M.A Alimul Hayat Shaikot. | C38: Male | D38: CS | E38: 1701060962 | F38: gma.alimul.hayat@g.bracu.ac.bd

Sheet Grade Sheet
C1: BRAC University
C2: Final Grade Sheet
C3: Summer 2025
C4: Department/ School: CSE
B5: Course No : | C5: CSE 221
B6: Course Title: | C6: Algorithms
B7: Section: | C7: 11
B8: Faculty Name: | C8: Abdullah Al Nakib
A9: Sl # | B9: ID # | C9: Name | D9: Atten. | E9: Quiz | F9: Assig. | G9: Lab | H9: Midterm | I9: Project 1 | J9: Project 2 | K9: Final | L9: Total | M9: Total | N9: Grades | O9: Suffix
D10: 0 | E10: 0.2 | F10: 0.05 | G10: 0.25 | H10: 0.2 | I10: 0 | J10: 0 | K10: 0.3 | L10: =SUM(D10:K10)*100 -> 100 | M10: =SUM(D10:K10) -> 1 | N10: (with suffix) | O10: (in words)
A11: 1 | B11: =Worksheet!A2 -> 20301033 | C11: =Worksheet!B2 -> Amlan Dutta | E11: =iferror(VLOOKUP(B11,'All Marks'!$A$2:$G$38,4,FALSE),0) -> 18 | F11: =VLOOKUP(B11,'All Marks'!$A$2:$G$39,3,FALSE) -> 3.75 | G11: =VLOOKUP(B11,'All Marks'!$A$2:$G$39,7,FALSE) -> 3.5 | H11: =VLOOKUP(B11,'All Marks'!$A$2:$G$39,5,FALSE) -> 7.5 | K11: =VLOOKUP(B11,'All Marks'!$A$2:$G$39,6,FALSE) -> 18.8 | L11: =SUM(E11:K11) -> 51.55 | M11: =IF(AND(L11>=96.5,L11<97),L11,ROUND(L11,0)) -> 52 | N11: =IF(M11<65,IF(M11<55,IF(M11<52,IF(M11<50,"F","D-"),"D"),IF(M11<57,"D+",IF(M11<60,"C-","C"))),IF(M11<75,IF(M11<70,"C+","B-"),IF(M11<85,IF(M11<80,"B","B+"),IF(M11<90,"A-",IF(M11<97,"A","A+"))))) -> D | O11: =IF(M11<65,IF(M11<55,IF(M11<52,IF(M11<50,"PLAIN","MINUS"),"PLAIN"),IF(M11<57,"PLUS",IF(M11<60,"MINUS","PLAIN"))),IF(M11<75,IF(M11<70,"PLUS","MINUS"),IF(M11<85,IF(M11<80,"PLAIN","PLUS"),IF(M11<90,"MINUS",IF(M11<97,"PLAIN","PLUS"))))) -> PLAIN | Q11: ='All Marks'!H2 -> 51.55 | R11: =EQ(Q11,L11) -> TRUE
A12: 2 | B12: =Worksheet!A3 -> 22101425 | C12: =Worksheet!B3 -> Khandokar Yusuf Khalid | E12: =iferror(VLOOKUP(B12,'All Marks'!$A$2:$G$38,4,FALSE),0) -> 16.66 | F12: =VLOOKUP(B12,'All Marks'!$A$2:$G$39,3,FALSE) -> 3.75 | G12: =VLOOKUP(B12,'All Marks'!$A$2:$G$39,7,FALSE) -> 3.59 | H12: =VLOOKUP(B12,'All Marks'!$A$2:$G$39,5,FALSE) -> 3.5 | K12: =VLOOKUP(B12,'All Marks'!$A$2:$G$39,6,FALSE) -> 18 | L12: =SUM(E12:K12) -> 45.5 | M12: =IF(AND(L12>=96.5,L12<97),L12,ROUND(L12,0)) -> 46 | N12: =IF(M12<65,IF(M12<55,IF(M12<52,IF(M12<50,"F","D-"),"D"),IF(M12<57,"D+",IF(M12<60,"C-","C"))),IF(M12<75,IF(M12<70,"C+","B-"),IF(M12<85,IF(M12<80,"B","B+"),IF(M12<90,"A-",IF(M12<97,"A","A+"))))) -> F | O12: =IF(M12<65,IF(M12<55,IF(M12<52,IF(M12<50,"PLAIN","MINUS"),"PLAIN"),IF(M12<57,"PLUS",IF(M12<60,"MINUS","PLAIN"))),IF(M12<75,IF(M12<70,"PLUS","MINUS"),IF(M12<85,IF(M12<80,"PLAIN","PLUS"),IF(M12<90,"MINUS",IF(M12<97,"PLAIN","PLUS"))))) -> PLAIN | Q12: ='All Marks'!H3 -> 45.5 | R12: =EQ(Q12,L12) -> TRUE
A13: 3 | B13: =Worksheet!A4 -> 22101748 | C13: =Worksheet!B4 -> Mst. Zubaida Haque Jetu | E13: =iferror(VLOOKUP(B13,'All Marks'!$A$2:$G$38,4,FALSE),0) -> 10 | F13: =VLOOKUP(B13,'All Marks'!$A$2:$G$39,3,FALSE) -> 5 | G13: =VLOOKUP(B13,'All Marks'!$A$2:$G$39,7,FALSE) -> 2.08 | H13: =VLOOKUP(B13,'All Marks'!$A$2:$G$39,5,FALSE) -> 8.3 | K13: =VLOOKUP(B13,'All Marks'!$A$2:$G$39,6,FALSE) -> 16.2 | L13: =SUM(E13:K13) -> 41.58 | M13: =IF(AND(L13>=96.5,L13<97),L13,ROUND(L13,0)) -> 42 | N13: =IF(M13<65,IF(M13<55,IF(M13<52,IF(M13<50,"F","D-"),"D"),IF(M13<57,"D+",IF(M13<60,"C-","C"))),IF(M13<75,IF(M13<70,"C+","B-"),IF(M13<85,IF(M13<80,"B","B+"),IF(M13<90,"A-",IF(M13<97,"A","A+"))))) -> F | O13: =IF(M13<65,IF(M13<55,IF(M13<52,IF(M13<50,"PLAIN","MINUS"),"PLAIN"),IF(M13<57,"PLUS",IF(M13<60,"MINUS","PLAIN"))),IF(M13<75,IF(M13<70,"PLUS","MINUS"),IF(M13<85,IF(M13<80,"PLAIN","PLUS"),IF(M13<90,"MINUS",IF(M13<97,"PLAIN","PLUS"))))) -> PLAIN | Q13: ='All Marks'!H4 -> 41.58 | R13: =EQ(Q13,L13) -> TRUE
A14: 4 | B14: =Worksheet!A5 -> 22299296 | C14: =Worksheet!B5 -> Raihan Karim | E14: =iferror(VLOOKUP(B14,'All Marks'!$A$2:$G$38,4,FALSE),0) -> 19.33 | F14: =VLOOKUP(B14,'All Marks'!$A$2:$G$39,3,FALSE) -> 5 | G14: =VLOOKUP(B14,'All Marks'!$A$2:$G$39,7,FALSE) -> 1.23 | H14: =VLOOKUP(B14,'All Marks'!$A$2:$G$39,5,FALSE) -> 7.2 | K14: =VLOOKUP(B14,'All Marks'!$A$2:$G$39,6,FALSE) -> 17.3 | L14: =SUM(E14:K14) -> 50.06 | M14: =IF(AND(L14>=96.5,L14<97),L14,ROUND(L14,0)) -> 50 | N14: =IF(M14<65,IF(M14<55,IF(M14<52,IF(M14<50,"F","D-"),"D"),IF(M14<57,"D+",IF(M14<60,"C-","C"))),IF(M14<75,IF(M14<70,"C+","B-"),IF(M14<85,IF(M14<80,"B","B+"),IF(M14<90,"A-",IF(M14<97,"A","A+"))))) -> D- | O14: =IF(M14<65,IF(M14<55,IF(M14<52,IF(M14<50,"PLAIN","MINUS"),"PLAIN"),IF(M14<57,"PLUS",IF(M14<60,"MINUS","PLAIN"))),IF(M14<75,IF(M14<70,"PLUS","MINUS"),IF(M14<85,IF(M14<80,"PLAIN","PLUS"),IF(M14<90,"MINUS",IF(M14<97,"PLAIN","PLUS"))))) -> MINUS | Q14: ='All Marks'!H5 -> 50.06 | R14: =EQ(Q14,L14) -> TRUE
A15: 5 | B15: =Worksheet!A6 -> 23101075 | C15: =Worksheet!B6 -> Abida Nowsheen | E15: =iferror(VLOOKUP(B15,'All Marks'!$A$2:$G$38,4,FALSE),0) -> 5.33 | F15: =VLOOKUP(B15,'All Marks'!$A$2:$G$39,3,FALSE) -> 0 | G15: =VLOOKUP(B15,'All Marks'!$A$2:$G$39,7,FALSE) -> 0 | H15: =VLOOKUP(B15,'All Marks'!$A$2:$G$39,5,FALSE) -> 2.9 | K15: =VLOOKUP(B15,'All Marks'!$A$2:$G$39,6,FALSE) -> 0 | L15: =SUM(E15:K15) -> 8.23 | M15: =IF(AND(L15>=96.5,L15<97),L15,ROUND(L15,0)) -> 8 | N15: =IF(M15<65,IF(M15<55,IF(M15<52,IF(M15<50,"F","D-"),"D"),IF(M15<57,"D+",IF(M15<60,"C-","C"))),IF(M15<75,IF(M15<70,"C+","B-"),IF(M15<85,IF(M15<80,"B","B+"),IF(M15<90,"A-",IF(M15<97,"A","A+"))))) -> F | O15: =IF(M15<65,IF(M15<55,IF(M15<52,IF(M15<50,"PLAIN","MINUS"),"PLAIN"),IF(M15<57,"PLUS",IF(M15<60,"MINUS","PLAIN"))),IF(M15<75,IF(M15<70,"PLUS","MINUS"),IF(M15<85,IF(M15<80,"PLAIN","PLUS"),IF(M15<90,"MINUS",IF(M15<97,"PLAIN","PLUS"))))) -> PLAIN | Q15: ='All Marks'!H6 -> 8.23 | R15: =EQ(Q15,L15) -> TRUE
A16: 6 | B16: =Worksheet!A7 -> 23101101 | C16: =Worksheet!B7 -> Jubaida Jahan Prapti | E16: =iferror(VLOOKUP(B16,'All Marks'!$A$2:$G$38,4,FALSE),0) -> 0 | F16: =VLOOKUP(B16,'All Marks'!$A$2:$G$39,3,FALSE) -> 1.25 | G16: =VLOOKUP(B16,'All Marks'!$A$2:$G$39,7,FALSE) -> 1.99 | H16: =VLOOKUP(B16,'All Marks'!$A$2:$G$39,5,FALSE) -> 4 | K16: =VLOOKUP(B16,'All Marks'!$A$2:$G$39,6,FALSE) -> 0 | L16: =SUM(E16:K16) -> 7.24 | M16: =IF(AND(L16>=96.5,L16<97),L16,ROUND(L16,0)) -> 7 | N16: =IF(M16<65,IF(M16<55,IF(M16<52,IF(M16<50,"F","D-"),"D"),IF(M16<57,"D+",IF(M16<60,"C-","C"))),IF(M16<75,IF(M16<70,"C+","B-"),IF(M16<85,IF(M16<80,"B","B+"),IF(M16<90,"A-",IF(M16<97,"A","A+"))))) -> F | O16: =IF(M16<65,IF(M16<55,IF(M16<52,IF(M16<50,"PLAIN","MINUS"),"PLAIN"),IF(M16<57,"PLUS",IF(M16<60,"MINUS","PLAIN"))),IF(M16<75,IF(M16<70,"PLUS","MINUS"),IF(M16<85,IF(M16<80,"PLAIN","PLUS"),IF(M16<90,"MINUS",IF(M16<97,"PLAIN","PLUS"))))) -> PLAIN | Q16: ='All Marks'!H7 -> 7.24 | R16: =EQ(Q16,L16) -> TRUE
A17: 7 | B17: =Worksheet!A8 -> 23101271 | C17: =Worksheet!B8 -> Sazid Chowdhury | E17: =iferror(VLOOKUP(B17,'All Marks'!$A$2:$G$38,4,FALSE),0) -> 14.66 | F17: =VLOOKUP(B17,'All Marks'!$A$2:$G$39,3,FALSE) -> 5 | G17: =VLOOKUP(B17,'All Marks'!$A$2:$G$39,7,FALSE) -> 11.7 | H17: =VLOOKUP(B17,'All Marks'!$A$2:$G$39,5,FALSE) -> 2.3 | K17: =VLOOKUP(B17,'All Marks'!$A$2:$G$39,6,FALSE) -> 18.4 | L17: =SUM(E17:K17) -> 52.06 | M17: =IF(AND(L17>=96.5,L17<97),L17,ROUND(L17,0)) -> 52 | N17: =IF(M17<65,IF(M17<55,IF(M17<52,IF(M17<50,"F","D-"),"D"),IF(M17<57,"D+",IF(M17<60,"C-","C"))),IF(M17<75,IF(M17<70,"C+","B-"),IF(M17<85,IF(M17<80,"B","B+"),IF(M17<90,"A-",IF(M17<97,"A","A+"))))) -> D | O17: =IF(M17<65,IF(M17<55,IF(M17<52,IF(M17<50,"PLAIN","MINUS"),"PLAIN"),IF(M17<57,"PLUS",IF(M17<60,"MINUS","PLAIN"))),IF(M17<75,IF(M17<70,"PLUS","MINUS"),IF(M17<85,IF(M17<80,"PLAIN","PLUS"),IF(M17<90,"MINUS",IF(M17<97,"PLAIN","PLUS"))))) -> PLAIN | Q17: ='All Marks'!H8 -> 52.06 | R17: =EQ(Q17,L17) -> TRUE
A18: 8 | B18: =Worksheet!A9 -> 23101378 | C18: =Worksheet!B9 -> Sharif Al Rezoan | E18: =iferror(VLOOKUP(B18,'All Marks'!$A$2:$G$38,4,FALSE),0) -> 17.33 | F18: =VLOOKUP(B18,'All Marks'!$A$2:$G$39,3,FALSE) -> 2.5 | G18: =VLOOKUP(B18,'All Marks'!$A$2:$G$39,7,FALSE) -> 11.44 | H18: =VLOOKUP(B18,'All Marks'!$A$2:$G$39,5,FALSE) -> 8.3 | K18: =VLOOKUP(B18,'All Marks'!$A$2:$G$39,6,FALSE) -> 20.3 | L18: =SUM(E18:K18) -> 59.87 | M18: =IF(AND(L18>=96.5,L18<97),L18,ROUND(L18,0)) -> 60 | N18: =IF(M18<65,IF(M18<55,IF(M18<52,IF(M18<50,"F","D-"),"D"),IF(M18<57,"D+",IF(M18<60,"C-","C"))),IF(M18<75,IF(M18<70,"C+","B-"),IF(M18<85,IF(M18<80,"B","B+"),IF(M18<90,"A-",IF(M18<97,"A","A+"))))) -> C | O18: =IF(M18<65,IF(M18<55,IF(M18<52,IF(M18<50,"PLAIN","MINUS"),"PLAIN"),IF(M18<57,"PLUS",IF(M18<60,"MINUS","PLAIN"))),IF(M18<75,IF(M18<70,"PLUS","MINUS"),IF(M18<85,IF(M18<80,"PLAIN","PLUS"),IF(M18<90,"MINUS",IF(M18<97,"PLAIN","PLUS"))))) -> PLAIN | Q18: ='All Marks'!H9 -> 59.87 | R18: =EQ(Q18,L18) -> TRUE
A19: 9 | B19: =Worksheet!A10 -> 23141047 | C19: =Worksheet!B10 -> Mohammad Rashik Ruhullah Rafi | E19: =iferror(VLOOKUP(B19,'All Marks'!$A$2:$G$38,4,FALSE),0) -> 11 | F19: =VLOOKUP(B19,'All Marks'!$A$2:$G$39,3,FALSE) -> 0 | G19: =VLOOKUP(B19,'All Marks'!$A$2:$G$39,7,FALSE) -> 1.23 | H19: =VLOOKUP(B19,'All Marks'!$A$2:$G$39,5,FALSE) -> 5.8 | K19: =VLOOKUP(B19,'All Marks'!$A$2:$G$39,6,FALSE) -> 0 | L19: =SUM(E19:K19) -> 18.03 | M19: =IF(AND(L19>=96.5,L19<97),L19,ROUND(L19,0)) -> 18 | N19: =IF(M19<65,IF(M19<55,IF(M19<52,IF(M19<50,"F","D-"),"D"),IF(M19<57,"D+",IF(M19<60,"C-","C"))),IF(M19<75,IF(M19<70,"C+","B-"),IF(M19<85,IF(M19<80,"B","B+"),IF(M19<90,"A-",IF(M19<97,"A","A+"))))) -> F | O19: =IF(M19<65,IF(M19<55,IF(M19<52,IF(M19<50,"PLAIN","MINUS"),"PLAIN"),IF(M19<57,"PLUS",IF(M19<60,"MINUS","PLAIN"))),IF(M19<75,IF(M19<70,"PLUS","MINUS"),IF(M19<85,IF(M19<80,"PLAIN","PLUS"),IF(M19<90,"MINUS",IF(M19<97,"PLAIN","PLUS"))))) -> PLAIN | Q19: ='All Marks'!H10 -> 18.03 | R19: =EQ(Q19,L19) -> TRUE
A20: 10 | B20: =Worksheet!A11 -> 23201093 | C20: =Worksheet!B11 -> S.A.Rahman | E20: =iferror(VLOOKUP(B20,'All Marks'!$A$2:$G$38,4,FALSE),0) -> 14.66 | F20: =VLOOKUP(B20,'All Marks'!$A$2:$G$39,3,FALSE) -> 2.5 | G20: =VLOOKUP(B20,'All Marks'!$A$2:$G$39,7,FALSE) -> 5 | H20: =VLOOKUP(B20,'All Marks'!$A$2:$G$39,5,FALSE) -> 2.3 | K20: =VLOOKUP(B20,'All Marks'!$A$2:$G$39,6,FALSE) -> 0 | L20: =SUM(E20:K20) -> 24.46 | M20: =IF(AND(L20>=96.5,L20<97),L20,ROUND(L20,0)) -> 24 | N20: =IF(M20<65,IF(M20<55,IF(M20<52,IF(M20<50,"F","D-"),"D"),IF(M20<57,"D+",IF(M20<60,"C-","C"))),IF(M20<75,IF(M20<70,"C+","B-"),IF(M20<85,IF(M20<80,"B","B+"),IF(M20<90,"A-",IF(M20<97,"A","A+"))))) -> F | O20: =IF(M20<65,IF(M20<55,IF(M20<52,IF(M20<50,"PLAIN","MINUS"),"PLAIN"),IF(M20<57,"PLUS",IF(M20<60,"MINUS","PLAIN"))),IF(M20<75,IF(M20<70,"PLUS","MINUS"),IF(M20<85,IF(M20<80,"PLAIN","PLUS"),IF(M20<90,"MINUS",IF(M20<97,"PLAIN","PLUS"))))) -> PLAIN | Q20: ='All Marks'!H11 -> 24.46 | R20: =EQ(Q20,L20) -> TRUE
A21: 11 | B21: =Worksheet!A12 -> 23201659 | C21: =Worksheet!B12 -> Maisha Sanjida Akhi | E21: =iferror(VLOOKUP(B21,'All Marks'!$A$2:$G$38,4,FALSE),0) -> 5 | F21: =VLOOKUP(B21,'All Marks'!$A$2:$G$39,3,FALSE) -> 0 | G21: =VLOOKUP(B21,'All Marks'!$A$2:$G$39,7,FALSE) -> 2.51 | H21: =VLOOKUP(B21,'All Marks'!$A$2:$G$39,5,FALSE) -> 0 | K21: =VLOOKUP(B21,'All Marks'!$A$2:$G$39,6,FALSE) -> 0 | L21: =SUM(E21:K21) -> 7.51 | M21: =IF(AND(L21>=96.5,L21<97),L21,ROUND(L21,0)) -> 8 | N21: =IF(M21<65,IF(M21<55,IF(M21<52,IF(M21<50,"F","D-"),"D"),IF(M21<57,"D+",IF(M21<60,"C-","C"))),IF(M21<75,IF(M21<70,"C+","B-"),IF(M21<85,IF(M21<80,"B","B+"),IF(M21<90,"A-",IF(M21<97,"A","A+"))))) -> F | O21: =IF(M21<65,IF(M21<55,IF(M21<52,IF(M21<50,"PLAIN","MINUS"),"PLAIN"),IF(M21<57,"PLUS",IF(M21<60,"MINUS","PLAIN"))),IF(M21<75,IF(M21<70,"PLUS","MINUS"),IF(M21<85,IF(M21<80,"PLAIN","PLUS"),IF(M21<90,"MINUS",IF(M21<97,"PLAIN","PLUS"))))) -> PLAIN | Q21: ='All Marks'!H12 -> 7.51 | R21: =EQ(Q21,L21) -> TRUE
A22: 12 | B22: =Worksheet!A13 -> 23301410 | C22: =Worksheet!B13 -> Rafid Shahriar Auvro | E22: =iferror(VLOOKUP(B22,'All Marks'!$A$2:$G$38,4,FALSE),0) -> 3.33 | F22: =VLOOKUP(B22,'All Marks'!$A$2:$G$39,3,FALSE) -> 0 | G22: =VLOOKUP(B22,'All Marks'!$A$2:$G$39,7,FALSE) -> 0 | H22: =VLOOKUP(B22,'All Marks'!$A$2:$G$39,5,FALSE) -> 9.5 | K22: =VLOOKUP(B22,'All Marks'!$A$2:$G$39,6,FALSE) -> 0 | L22: =SUM(E22:K22) -> 12.83 | M22: =IF(AND(L22>=96.5,L22<97),L22,ROUND(L22,0)) -> 13 | N22: =IF(M22<65,IF(M22<55,IF(M22<52,IF(M22<50,"F","D-"),"D"),IF(M22<57,"D+",IF(M22<60,"C-","C"))),IF(M22<75,IF(M22<70,"C+","B-"),IF(M22<85,IF(M22<80,"B","B+"),IF(M22<90,"A-",IF(M22<97,"A","A+"))))) -> F | O22: =IF(M22<65,IF(M22<55,IF(M22<52,IF(M22<50,"PLAIN","MINUS"),"PLAIN"),IF(M22<57,"PLUS",IF(M22<60,"MINUS","PLAIN"))),IF(M22<75,IF(M22<70,"PLUS","MINUS"),IF(M22<85,IF(M22<80,"PLAIN","PLUS"),IF(M22<90,"MINUS",IF(M22<97,"PLAIN","PLUS"))))) -> PLAIN | Q22: ='All Marks'!H13 -> 12.83 | R22: =EQ(Q22,L22) -> TRUE
... A47: 37 | B47: =Worksheet!A38 -> 24341137 | C47: =Worksheet!B38 -> G.M.A Alimul Hayat Shaikot. | E47: =iferror(VLOOKUP(B47,'All Marks'!$A$2:$G$38,4,FALSE),0) -> 0 | F47: =VLOOKUP(B47,'All Marks'!$A$2:$G$39,3,FALSE) -> 0 | G47: =VLOOKUP(B47,'All Marks'!$A$2:$G$39,7,FALSE) -> 0 | H47: =VLOOKUP(B47,'All Marks'!$A$2:$G$39,5,FALSE) -> 0 | K47: =VLOOKUP(B47,'All Marks'!$A$2:$G$39,6,FALSE) -> 0 | L47: =SUM(E47:K47) -> 0 | M47: =IF(AND(L47>=96.5,L47<97),L47,ROUND(L47,0)) -> 0 | N47: =IF(M47<65,IF(M47<55,IF(M47<52,IF(M47<50,"F","D-"),"D"),IF(M47<57,"D+",IF(M47<60,"C-","C"))),IF(M47<75,IF(M47<70,"C+","B-"),IF(M47<85,IF(M47<80,"B","B+"),IF(M47<90,"A-",IF(M47<97,"A","A+"))))) -> F | O47: =IF(M47<65,IF(M47<55,IF(M47<52,IF(M47<50,"PLAIN","MINUS"),"PLAIN"),IF(M47<57,"PLUS",IF(M47<60,"MINUS","PLAIN"))),IF(M47<75,IF(M47<70,"PLUS","MINUS"),IF(M47<85,IF(M47<80,"PLAIN","PLUS"),IF(M47<90,"MINUS",IF(M47<97,"PLAIN","PLUS"))))) -> PLAIN | Q47: ='All Marks'!H38 -> 0 | R47: =EQ(Q47,L47) -> TRUE
R48: =COUNTIF(R11:R47,"=TRUE") -> 37

Sheet All Marks
A1: Student ID | B1: Name | C1: =Assignment!G1 -> Assignment (out of 5) | D1: =Quiz!M1 -> Overall Quiz score (Out of 20) best (n-1) without bonus | E1: ='Mid+Final'!D2 -> Midterm (20) | F1: ='Mid+Final'!M2 -> Final(30) | G1: Lab (25) | H1: Total (out of 100)
A2: =Worksheet!A2 -> 20301033 | B2: =Worksheet!B2 -> Amlan Dutta | C2: =Assignment!G2 -> 3.75 | D2: =Quiz!M2 -> 18 | E2: ='Mid+Final'!D3 -> 7.5 | F2: ='Mid+Final'!M3 -> 18.8 | G2: =IFERROR(ROUNDUP(VLOOKUP(A2,Lab!$A$2:$B$39,2,False),2),0) -> 3.5 | H2: =RoundUp(sum(C2:G2),2) -> 51.55
A3: =Worksheet!A3 -> 22101425 | B3: =Worksheet!B3 -> Khandokar Yusuf Khalid | C3: =Assignment!G3 -> 3.75 | D3: =Quiz!M3 -> 16.66 | E3: ='Mid+Final'!D4 -> 3.5 | F3: ='Mid+Final'!M4 -> 18 | G3: =IFERROR(ROUNDUP(VLOOKUP(A3,Lab!$A$2:$B$39,2,False),2),0) -> 3.59 | H3: =RoundUp(sum(C3:G3),2) -> 45.5
A4: =Worksheet!A4 -> 22101748 | B4: =Worksheet!B4 -> Mst. Zubaida Haque Jetu | C4: =Assignment!G4 -> 5 | D4: =Quiz!M4 -> 10 | E4: ='Mid+Final'!D5 -> 8.3 | F4: ='Mid+Final'!M5 -> 16.2 | G4: =IFERROR(ROUNDUP(VLOOKUP(A4,Lab!$A$2:$B$39,2,False),2),0) -> 2.08 | H4: =RoundUp(sum(C4:G4),2) -> 41.58
A5: =Worksheet!A5 -> 22299296 | B5: =Worksheet!B5 -> Raihan Karim | C5: =Assignment!G5 -> 5 | D5: =Quiz!M5 -> 19.33 | E5: ='Mid+Final'!D6 -> 7.2 | F5: ='Mid+Final'!M6 -> 17.3 | G5: =IFERROR(ROUNDUP(VLOOKUP(A5,Lab!$A$2:$B$39,2,False),2),0) -> 1.23 | H5: =RoundUp(sum(C5:G5),2) -> 50.06
A6: =Worksheet!A6 -> 23101075 | B6: =Worksheet!B6 -> Abida Nowsheen | C6: =Assignment!G6 -> 0 | D6: =Quiz!M6 -> 5.33 | E6: ='Mid+Final'!D7 -> 2.9 | F6: ='Mid+Final'!M7 -> 0 | G6: =IFERROR(ROUNDUP(VLOOKUP(A6,Lab!$A$2:$B$39,2,False),2),0) -> 0 | H6: =RoundUp(sum(C6:G6),2) -> 8.23
A7: =Worksheet!A7 -> 23101101 | B7: =Worksheet!B7 -> Jubaida Jahan Prapti | C7: =Assignment!G7 -> 1.25 | D7: =Quiz!M7 -> 0 | E7: ='Mid+Final'!D8 -> 4 | F7: ='Mid+Final'!M8 -> 0 | G7: =IFERROR(ROUNDUP(VLOOKUP(A7,Lab!$A$2:$B$39,2,False),2),0) -> 1.99 | H7: =RoundUp(sum(C7:G7),2) -> 7.24
A8: =Worksheet!A8 -> 23101271 | B8: =Worksheet!B8 -> Sazid Chowdhury | C8: =Assignment!G8 -> 5 | D8: =Quiz!M8 -> 14.66 | E8: ='Mid+Final'!D9 -> 2.3 | F8: ='Mid+Final'!M9 -> 18.4 | G8: =IFERROR(ROUNDUP(VLOOKUP(A8,Lab!$A$2:$B$39,2,False),2),0) -> 11.7 | H8: =RoundUp(sum(C8:G8),2) -> 52.06
A9: =Worksheet!A9 -> 23101378 | B9: =Worksheet!B9 -> Sharif Al Rezoan | C9: =Assignment!G9 -> 2.5 | D9: =Quiz!M9 -> 17.33 | E9: ='Mid+Final'!D10 -> 8.3 | F9: ='Mid+Final'!M10 -> 20.3 | G9: =IFERROR(ROUNDUP(VLOOKUP(A9,Lab!$A$2:$B$39,2,False),2),0) -> 11.44 | H9: =RoundUp(sum(C9:G9),2) -> 59.87
A10: =Worksheet!A10 -> 23141047 | B10: =Worksheet!B10 -> Mohammad Rashik Ruhullah Rafi | C10: =Assignment!G10 -> 0 | D10: =Quiz!M10 -> 11 | E10: ='Mid+Final'!D11 -> 5.8 | F10: ='Mid+Final'!M11 -> 0 | G10: =IFERROR(ROUNDUP(VLOOKUP(A10,Lab!$A$2:$B$39,2,False),2),0) -> 1.23 | H10: =RoundUp(sum(C10:G10),2) -> 18.03
A11: =Worksheet!A11 -> 23201093 | B11: =Worksheet!B11 -> S.A.Rahman | C11: =Assignment!G11 -> 2.5 | D11: =Quiz!M11 -> 14.66 | E11: ='Mid+Final'!D12 -> 2.3 | F11: ='Mid+Final'!M12 -> 0 | G11: =IFERROR(ROUNDUP(VLOOKUP(A11,Lab!$A$2:$B$39,2,False),2),0) -> 5 | H11: =RoundUp(sum(C11:G11),2) -> 24.46
A12: =Worksheet!A12 -> 23201659 | B12: =Worksheet!B12 -> Maisha Sanjida Akhi | C12: =Assignment!G12 -> 0 | D12: =Quiz!M12 -> 5 | E12: ='Mid+Final'!D13 -> 0 | F12: ='Mid+Final'!M13 -> 0 | G12: =IFERROR(ROUNDUP(VLOOKUP(A12,Lab!$A$2:$B$39,2,False),2),0) -> 2.51 | H12: =RoundUp(sum(C12:G12),2) -> 7.51
A13: =Worksheet!A13 -> 23301410 | B13: =Worksheet!B13 -> Rafid Shahriar Auvro | C13: =Assignment!G13 -> 0 | D13: =Quiz!M13 -> 3.33 | E13: ='Mid+Final'!D14 -> 9.5 | F13: ='Mid+Final'!M14 -> 0 | G13: =IFERROR(ROUNDUP(VLOOKUP(A13,Lab!$A$2:$B$39,2,False),2),0) -> 0 | H13: =RoundUp(sum(C13:G13),2) -> 12.83
... A34: =Worksheet!A34 -> 24301197 | B34: =Worksheet!B34 -> Samin Yasar Nafi | C34: =Assignment!G34 -> 1.25 | D34: =Quiz!M34 -> 4.33 | E34: ='Mid+Final'!D35 -> 8 | F34: ='Mid+Final'!M35 -> 0 | G34: =IFERROR(ROUNDUP(VLOOKUP(A34,Lab!$A$2:$B$39,2,False),2),0) -> 2.18 | H34: =RoundUp(sum(C34:G34),2) -> 15.76
A35: =Worksheet!A35 -> 24301282 | B35: =Worksheet!B35 -> Samin Nuzaima | C35: =Assignment!G35 -> 5 | D35: =Quiz!M35 -> 16.66 | E35: =ROUNDUP('Mid+Final'!D36,0) -> 10 | F35: =ROUNDUP('Mid+Final'!M36,0) -> 20 | G35: =IFERROR(ROUNDUP(VLOOKUP(A35,Lab!$A$2:$B$39,2,False),2),0) -> 5 | H35: =RoundUp(sum(C35:G35),2) -> 56.66
A36: =Worksheet!A36 -> 24321232 | B36: =Worksheet!B36 -> Kazi Yasin Hridoy | C36: =Assignment!G36 -> 5 | D36: =Quiz!M36 -> 20 | E36: ='Mid+Final'!D37 -> 6 | F36: ='Mid+Final'!M37 -> 22.5 | G36: =IFERROR(ROUNDUP(VLOOKUP(A36,Lab!$A$2:$B$39,2,False),2),0) -> 11.11 | H36: =RoundUp(sum(C36:G36),2) -> 64.61
A37: =Worksheet!A37 -> 24321234 | B37: =Worksheet!B37 -> Al Jayed Rup | C37: =Assignment!G37 -> 5 | D37: =Quiz!M37 -> 17.33 | E37: ='Mid+Final'!D38 -> 12.9 | F37: ='Mid+Final'!M38 -> 23.3 | G37: =IFERROR(ROUNDUP(VLOOKUP(A37,Lab!$A$2:$B$39,2,False),2),0) -> 3.02 | H37: =RoundUp(sum(C37:G37),2) -> 61.55
A38: =Worksheet!A38 -> 24341137 | B38: =Worksheet!B38 -> G.M.A Alimul Hayat Shaikot. | C38: =Assignment!G38 -> 0 | D38: 0 | E38: 0 | F38: 0 | G38: =IFERROR(ROUNDUP(VLOOKUP(A38,Lab!$A$2:$B$39,2,False),2),0) -> 0 | H38: =RoundUp(sum(C38:G38),2) -> 0

Sheet Mid+Final
E1: CO2 | F1: CO1 | G1: CO2 | H1: CO2 | I1: CO1 | J1: CO3
A2: Student Id | C2: Midterm (35) | D2: Midterm (20) | E2: 1 a, b, c (10) | F2: 2 a,b,c (9) | G2: 2 d(1) | H2: 3 a, b(5) | I2: 4a(4) | J2: 4 b, c(6) | L2: Final out of 40 | M2: Final(30) | N2: 1 a,b,c,d CO1 Marks 10 | O2: 2 a, c CO1 Marks 6 | P2: 2 b CO3 Marks 2 | Q2: 2 d CO2 Marks 2 | R2: 3 a CO1 Marks 5 | S2: 3 b CO2 Marks 3 | T2: 3 c CO3 Marks 2 | U2: 4 CO1 marks 10
A3: =Worksheet!A2 -> 20301033 | B3: =Worksheet!B2 -> Amlan Dutta | C3: =SUM(E3:J3) -> 13 | D3: =roundup(SUM(E3:K3)/35*20,1) -> 7.5 | E3: 6 | F3: 1 | H3: 3 | I3: 2 | J3: 1 | L3: =SUM(N3:U3) -> 25 | M3: =roundup(L3/40*30,1) -> 18.8 | N3: 5 | O3: 3.5 | P3: 1 | Q3: 0 | R3: 5 | S3: 1.5 | T3: 1 | U3: 8
A4: =Worksheet!A3 -> 22101425 | B4: =Worksheet!B3 -> Khandokar Yusuf Khalid | C4: =SUM(E4:J4) -> 6 | D4: =roundup(SUM(E4:K4)/35*20,1) -> 3.5 | E4: 3 | H4: 1 | I4: 1 | J4: 1 | L4: =SUM(N4:U4) -> 24 | M4: =roundup(L4/40*30,1) -> 18 | N4: 4 | O4: 3 | P4: 2 | Q4: 1 | R4: 2 | S4: 0 | T4: 2 | U4: 10
A5: =Worksheet!A4 -> 22101748 | B5: =Worksheet!B4 -> Mst. Zubaida Haque Jetu | C5: =SUM(E5:J5) -> 14.5 | D5: =roundup(SUM(E5:K5)/35*20,1) -> 8.3 | E5: 5.5 | F5: 6 | H5: 2 | I5: 1 | L5: =SUM(N5:U5) -> 21.5 | M5: =roundup(L5/40*30,1) -> 16.2 | N5: 3 | O5: 3.5 | P5: 2 | Q5: 1 | R5: 4 | S5: 2 | T5: 1 | U5: 5
A6: =Worksheet!A5 -> 22299296 | B6: =Worksheet!B5 -> Raihan Karim | C6: =SUM(E6:J6) -> 12.5 | D6: =roundup(SUM(E6:K6)/35*20,1) -> 7.2 | E6: 3 | F6: 3.5 | I6: 3 | J6: 3 | L6: =SUM(N6:U6) -> 23 | M6: =roundup(L6/40*30,1) -> 17.3 | N6: 9 | O6: 3.5 | P6: 2 | Q6: 1 | R6: 3.5 | S6: 2 | T6: 1 | U6: 1
A7: =Worksheet!A6 -> 23101075 | B7: =Worksheet!B6 -> Abida Nowsheen | C7: =SUM(E7:J7) -> 5 | D7: =roundup(SUM(E7:K7)/35*20,1) -> 2.9 | E7: 3 | H7: 2 | L7: =SUM(N7:U7) -> 0 | M7: =roundup(L7/40*30,1) -> 0
A8: =Worksheet!A7 -> 23101101 | B8: =Worksheet!B7 -> Jubaida Jahan Prapti | C8: =SUM(E8:J8) -> 7 | D8: =roundup(SUM(E8:K8)/35*20,1) -> 4 | E8: 3 | F8: 2 | G8: 0 | H8: 2 | I8: 0 | J8: 0 | L8: =SUM(N8:U8) -> 0 | M8: =roundup(L8/40*30,1) -> 0
A9: =Worksheet!A8 -> 23101271 | B9: =Worksheet!B8 -> Sazid Chowdhury | C9: =SUM(E9:J9) -> 4 | D9: =roundup(SUM(E9:K9)/35*20,1) -> 2.3 | E9: 3 | G9: 1 | L9: =SUM(N9:U9) -> 24.5 | M9: =roundup(L9/40*30,1) -> 18.4 | N9: 7 | O9: 3 | P9: 0 | Q9: 0 | R9: 5 | S9: 3 | T9: 1.5 | U9: 5
A10: =Worksheet!A9 -> 23101378 | B10: =Worksheet!B9 -> Sharif Al Rezoan | C10: =SUM(E10:J10) -> 14.5 | D10: =roundup(SUM(E10:K10)/35*20,1) -> 8.3 | E10: 0.5 | F10: 7.5 | G10: 1 | H10: 0 | I10: 2.5 | J10: 3 | L10: =SUM(N10:U10) -> 27 | M10: =roundup(L10/40*30,1) -> 20.3 | N10: 6 | O10: 3 | P10: 0 | Q10: 0 | R10: 5 | S10: 3 | T10: 1 | U10: 9
A11: =Worksheet!A10 -> 23141047 | B11: =Worksheet!B10 -> Mohammad Rashik Ruhullah Rafi | C11: =SUM(E11:J11) -> 10 | D11: =roundup(SUM(E11:K11)/35*20,1) -> 5.8 | E11: 3 | F11: 4 | I11: 1 | J11: 2 | L11: =SUM(N11:U11) -> 0 | M11: =roundup(L11/40*30,1) -> 0
A12: =Worksheet!A11 -> 23201093 | B12: =Worksheet!B11 -> S.A.Rahman | C12: =SUM(E12:J12) -> 4 | D12: =roundup(SUM(E12:K12)/35*20,1) -> 2.3 | E12: 0 | F12: 2 | H12: 1 | I12: 1 | L12: =SUM(N12:U12) -> 0 | M12: =roundup(L12/40*30,1) -> 0
A13: =Worksheet!A12 -> 23201659 | B13: =Worksheet!B12 -> Maisha Sanjida Akhi | C13: =SUM(E13:J13) -> 0 | D13: =roundup(SUM(E13:K13)/35*20,1) -> 0 | E13: 0 | L13: =SUM(N13:U13) -> 0 | M13: =roundup(L13/40*30,1) -> 0
A14: =Worksheet!A13 -> 23301410 | B14: =Worksheet!B13 -> Rafid Shahriar Auvro | C14: =SUM(E14:J14) -> 16.5 | D14: =roundup(SUM(E14:K14)/35*20,1) -> 9.5 | E14: 6 | F14: 6 | I14: 1.5 | J14: 3 | L14: =SUM(N14:U14) -> 0 | M14: =roundup(L14/40*30,1) -> 0
A15: =Worksheet!A14 -> 23301602 | B15: =Worksheet!B14 -> Farhan Anjum | C15: =SUM(E15:J15) -> 11 | D15: =roundup(SUM(E15:K15)/35*20,1) -> 6.3 | E15: 7 | F15: 3 | G15: 0.5 | H15: 0.5 | L15: =SUM(N15:U15) -> 0 | M15: =roundup(L15/40*30,1) -> 0
A16: =Worksheet!A15 -> 24101390 | B16: =Worksheet!B15 -> P. M. Mushfiqur Shium | C16: =SUM(E16:J16) -> 24.5 | D16: =roundup(SUM(E16:K16)/35*20,1) -> 14 | E16: 8.5 | F16: 7.5 | H16: 1.5 | I16: 4 | J16: 3 | L16: =SUM(N16:U16) -> 29.5 | M16: =roundup(L16/40*30,1) -> 22.2 | N16: 9 | O16: 4 | P16: 0 | Q16: 2 | R16: 5 | S16: 1 | T16: 0 | U16: 8.5
A17: =Worksheet!A16 -> 24101392 | B17: =Worksheet!B16 -> Fardin Islam | C17: =SUM(E17:J17) -> 17 | D17: =roundup(SUM(E17:K17)/35*20,1) -> 9.8 | E17: 7 | F17: 3 | H17: 1 | I17: 2 | J17: 4 | L17: =SUM(N17:U17) -> 32 | M17: =roundup(L17/40*30,1) -> 24 | N17: 9 | O17: 4.5 | P17: 2 | Q17: 1.5 | R17: 5 | S17: 1 | T17: 2 | U17: 7
A18: =Worksheet!A17 -> 24101431 | B18: =Worksheet!B17 -> Raheeb Al Zabir | C18: =SUM(E18:J18) -> 12.5 | D18: =roundup(SUM(E18:K18)/35*20,1) -> 7.2 | E18: 6 | F18: 4 | G18: 1 | H18: 1.5 | L18: =SUM(N18:U18) -> 27 | M18: =roundup(L18/40*30,1) -> 20.3 | N18: 6 | O18: 5 | P18: 0 | Q18: 2 | R18: 4 | S18: 2 | T18: 1 | U18: 7
A19: =Worksheet!A18 -> 24101442 | B19: =Worksheet!B18 -> Abdullah Al Noman | C19: =SUM(E19:J19) -> 18.5 | D19: =roundup(SUM(E19:K19)/35*20,1) -> 10.6 | E19: 6 | F19: 4 | G19: 0.5 | H19: 1 | I19: 4 | J19: 3 | L19: =SUM(N19:U19) -> 29 | M19: =roundup(L19/40*30,1) -> 21.8 | N19: 9 | O19: 3 | P19: 0 | Q19: 0 | R19: 5 | S19: 3 | T19: 2 | U19: 7
A20: =Worksheet!A19 -> 24121353 | B20: =Worksheet!B19 -> Ayatullah Osama Khan | C20: =SUM(E20:J20) -> 12.5 | D20: =roundup(SUM(E20:K20)/35*20,1) -> 7.2 | E20: 6 | F20: 4 | G20: 0.5 | H20: 1 | I20: 1 | L20: =SUM(N20:U20) -> 27 | M20: =roundup(L20/40*30,1) -> 20.3 | N20: 7 | O20: 2 | P20: 1 | Q20: 0 | R20: 4 | S20: 2 | T20: 1 | U20: 10
A21: =Worksheet!A20 -> 24141008 | B21: =Worksheet!B20 -> Ashvin Al Afroz | C21: =SUM(E21:J21) -> 26.5 | D21: =roundup(SUM(E21:K21)/35*20,1) -> 15.2 | E21: 6 | F21: 8 | G21: 0.5 | H21: 5 | I21: 4 | J21: 3 | L21: =SUM(N21:U21) -> 0 | M21: =roundup(L21/40*30,1) -> 0
A22: =Worksheet!A21 -> 24141155 | B22: =Worksheet!B21 -> Md. Abrar Mahib Pritom | C22: =SUM(E22:J22) -> 10 | D22: =roundup(SUM(E22:K22)/35*20,1) -> 5.8 | E22: 3 | F22: 2 | G22: 0 | H22: 3 | I22: 2 | J22: 0 | L22: =SUM(N22:U22) -> 0 | M22: =roundup(L22/40*30,1) -> 0
A23: =Worksheet!A22 -> 24201090 | B23: =Worksheet!B22 -> Nafis As - Sami | C23: =SUM(E23:J23) -> 28.5 | D23: =roundup(SUM(E23:K23)/35*20,1) -> 16.3 | E23: 8.5 | F23: 8 | G23: 0.5 | H23: 4 | I23: 3.5 | J23: 4 | L23: =SUM(N23:U23) -> 35 | M23: =roundup(L23/40*30,1) -> 26.3 | N23: 9 | O23: 4 | P23: 1 | Q23: 2 | R23: 5 | S23: 2 | T23: 2 | U23: 10
A24: =Worksheet!A23 -> 24201165 | B24: =Worksheet!B23 -> Jahareen Tasmeem | C24: =SUM(E24:J24) -> 26 | D24: =roundup(SUM(E24:K24)/35*20,1) -> 14.9 | E24: 9 | F24: 7 | H24: 2 | I24: 4 | J24: 4 | L24: =SUM(N24:U24) -> 32.5 | M24: =roundup(L24/40*30,1) -> 24.4 | N24: 7 | O24: 3.5 | P24: 1 | Q24: 1 | R24: 5 | S24: 3 | T24: 2 | U24: 10
A25: =Worksheet!A24 -> 24201176 | B25: =Worksheet!B24 -> Maheer Tajwar | C25: =SUM(E25:J25) -> 29 | D25: =roundup(SUM(E25:K25)/35*20,1) -> 16.6 | E25: 10 | F25: 7 | G25: 0.5 | H25: 3.5 | I25: 4 | J25: 4 | L25: =SUM(N25:U25) -> 33.5 | M25: =roundup(L25/40*30,1) -> 25.2 | N25: 10 | O25: 6 | P25: 2 | Q25: 2 | R25: 4 | S25: 1.5 | T25: 1 | U25: 7
A26: =Worksheet!A25 -> 24201193 | B26: =Worksheet!B25 -> Md.Fardin Islam | C26: =SUM(E26:J26) -> 24.5 | D26: =roundup(SUM(E26:K26)/35*20,1) -> 14 | E26: 5 | F26: 6 | G26: 0.5 | H26: 4 | I26: 4 | J26: 5 | L26: =SUM(N26:U26) -> 34 | M26: =roundup(L26/40*30,1) -> 25.5 | N26: 9 | O26: 4 | P26: 2 | Q26: 1 | R26: 4 | S26: 2 | T26: 2 | U26: 10
A27: =Worksheet!A26 -> 24201199 | B27: =Worksheet!B26 -> Faiyaz Rahman | C27: =SUM(E27:J27) -> 23.5 | D27: =roundup(SUM(E27:K27)/35*20,1) -> 13.5 | E27: 7 | F27: 6 | G27: 0 | H27: 4 | I27: 2.5 | J27: 4 | L27: =SUM(N27:U27) -> 38 | M27: =roundup(L27/40*30,1) -> 28.5 | N27: 10 | O27: 5 | P27: 2 | Q27: 2 | R27: 5 | S27: 3 | T27: 1 | U27: 10
A28: =Worksheet!A27 -> 24201453 | B28: =Worksheet!B27 -> Md. Zayed Khan | C28: =SUM(E28:J28) -> 18.5 | D28: =roundup(SUM(E28:K28)/35*20,1) -> 10.6 | E28: 7 | F28: 3.5 | G28: 0 | H28: 2 | I28: 2 | J28: 4 | L28: =SUM(N28:U28) -> 23.5 | M28: =roundup(L28/40*30,1) -> 17.7 | N28: 6 | O28: 5 | P28: 0 | Q28: 0 | R28: 4 | S28: 2 | T28: 0 | U28: 6.5
A29: =Worksheet!A28 -> 24201455 | B29: =Worksheet!B28 -> Hossain Tasnim Rumki | C29: =SUM(E29:J29) -> 25 | D29: =roundup(SUM(E29:K29)/35*20,1) -> 14.3 | E29: 6 | F29: 7 | G29: 1 | H29: 4 | I29: 4 | J29: 3 | L29: =SUM(N29:U29) -> 35 | M29: =roundup(L29/40*30,1) -> 26.3 | N29: 10 | O29: 4 | P29: 2 | Q29: 1 | R29: 4 | S29: 3 | T29: 2 | U29: 9
A30: =Worksheet!A29 -> 24204199 | B30: =Worksheet!B29 -> Abdul Mumit Bin Jafor | C30: =SUM(E30:J30) -> 18.5 | D30: =roundup(SUM(E30:K30)/35*20,1) -> 10.6 | E30: 5 | F30: 4.5 | H30: 1 | I30: 4 | J30: 4 | L30: =SUM(N30:U30) -> 21.5 | M30: =roundup(L30/40*30,1) -> 16.2 | N30: 7 | O30: 3 | P30: 1 | Q30: 2 | R30: 3.5 | S30: 2 | T30: 1 | U30: 2
A31: =Worksheet!A30 -> 24301002 | B31: =Worksheet!B30 -> Wamiza Mehjabin | C31: =SUM(E31:J31) -> 15 | D31: =roundup(SUM(E31:K31)/35*20,1) -> 8.6 | E31: 6 | F31: 4 | H31: 2 | I31: 1 | J31: 2 | L31: =SUM(N31:U31) -> 0 | M31: =roundup(L31/40*30,1) -> 0
A32: =Worksheet!A31 -> 24301003 | B32: =Worksheet!B31 -> Shahir Sharaf Chowdhury | C32: =SUM(E32:J32) -> 0 | D32: =roundup(SUM(E32:K32)/35*20,1) -> 0 | E32: 0 | F32: 0 | G32: 0 | I32: 0 | J32: 0 | L32: =SUM(N32:U32) -> 4 | M32: =roundup(L32/40*30,1) -> 3 | N32: 0 | O32: 2 | P32: 1 | Q32: 0 | R32: 1 | S32: 0 | T32: 0 | U32: 0
A33: =Worksheet!A32 -> 24301116 | B33: =Worksheet!B32 -> Mahajabin Islam | C33: =SUM(E33:J33) -> 20.5 | D33: =roundup(SUM(E33:K33)/35*20,1) -> 11.8 | E33: 9.5 | F33: 2.5 | H33: 1 | I33: 3.5 | J33: 4 | L33: =SUM(N33:U33) -> 31 | M33: =roundup(L33/40*30,1) -> 23.3 | N33: 8 | O33: 4 | P33: 2 | Q33: 1 | R33: 3.5 | S33: 1.5 | T33: 2 | U33: 9
A34: =Worksheet!A33 -> 24301173 | B34: =Worksheet!B33 -> Shahida Rahman | C34: =SUM(E34:J34) -> 19.5 | D34: =roundup(SUM(E34:K34)/35*20,1) -> 11.2 | E34: 7 | F34: 5 | G34: 0.5 | H34: 1 | I34: 3 | J34: 3 | L34: =SUM(N34:U34) -> 31 | M34: =roundup(L34/40*30,1) -> 23.3 | N34: 9 | O34: 4.5 | P34: 1 | Q34: 1 | R34: 5 | S34: 2 | T34: 0 | U34: 8.5
A35: =Worksheet!A34 -> 24301197 | B35: =Worksheet!B34 -> Samin Yasar Nafi | C35: =SUM(E35:J35) -> 14 | D35: =roundup(SUM(E35:K35)/35*20,1) -> 8 | E35: 2 | F35: 5 | I35: 4 | J35: 3 | L35: =SUM(N35:U35) -> 0 | M35: =roundup(L35/40*30,1) -> 0
A36: =Worksheet!A35 -> 24301282 | B36: =Worksheet!B35 -> Samin Nuzaima | C36: =SUM(E36:J36) -> 16.5 | D36: =roundup(SUM(E36:K36)/35*20,1) -> 9.5 | E36: 4 | F36: 5 | G36: 0.5 | H36: 1 | I36: 4 | J36: 2 | L36: =SUM(N36:U36) -> 26 | M36: =roundup(L36/40*30,1) -> 19.5 | N36: 7 | O36: 4 | P36: 0 | Q36: 2 | R36: 4 | S36: 1 | T36: 0 | U36: 8
A37: =Worksheet!A36 -> 24321232 | B37: =Worksheet!B36 -> Kazi Yasin Hridoy | C37: =SUM(E37:J37) -> 10.5 | D37: =roundup(SUM(E37:K37)/35*20,1) -> 6 | E37: 2.5 | F37: 6.5 | I37: 1.5 | L37: =SUM(N37:U37) -> 30 | M37: =roundup(L37/40*30,1) -> 22.5 | N37: 8 | O37: 5 | P37: 2 | Q37: 0 | R37: 4 | S37: 1.5 | T37: 1 | U37: 8.5
A38: =Worksheet!A37 -> 24321234 | B38: =Worksheet!B37 -> Al Jayed Rup | C38: =SUM(E38:J38) -> 22.5 | D38: =roundup(SUM(E38:K38)/35*20,1) -> 12.9 | E38: 7 | F38: 5.5 | H38: 2 | I38: 4 | J38: 4 | L38: =SUM(N38:U38) -> 31 | M38: =roundup(L38/40*30,1) -> 23.3 | N38: 7 | O38: 5 | P38: 1 | Q38: 1 | R38: 4 | S38: 3 | T38: 1 | U38: 9
C39: =COUNTIF(C3:C38,">0") -> 34 | L39: =COUNTIF(L3:L38,">0") -> 25

Sheet Quiz
A1: Student Id | B1: Name | C1: Quiz 1 (out of 10) | D1: Quiz 2 (out of 10) | E1: Quiz 3 (out of 10) | F1: Quiz 4 (out of 10) | G1: Quiz 1 (out of 10) | H1: Quiz 2 (out of 10) | I1: Quiz 3 (out of 10) | J1: Quiz 4 (out of 10) | K1: Bonus | L1: Overall Quiz score (Out of 20) best (n-1) with bonus | M1: Overall Quiz score (Out of 20) best (n-1) without bonus
A2: =Worksheet!A2 -> 20301033 | B2: =Worksheet!B2 -> Amlan Dutta | C2: 6.5 | D2: 10 | E2: 8 | F2: 9 | G2: =C2 -> 6.5 | H2: =D2 -> 10 | I2: =E2 -> 8 | J2: =if(F2<10,F2,10) -> 9 | K2: =if(F2>10,F2-10,0) -> 0 | L2: =if((SUMPRODUCT(LARGE(G2:J2,{1,2,3})))/3*2>20,20,TRUNC((SUMPRODUCT(LARGE(G2:J2,{1,2,3})))/3*2,2)) -> 18 | M2: =if((SUMPRODUCT(LARGE(G2:J2,{1,2,3}))+K2/2)/3*2>20,20,TRUNC((SUMPRODUCT(LARGE(G2:J2,{1,2,3}))+K2/2)/3*2,2)) -> 18
A3: =Worksheet!A3 -> 22101425 | B3: =Worksheet!B3 -> Khandokar Yusuf Khalid | C3: 5 | D3: 5 | E3: 10 | F3: 10 | G3: =C3 -> 5 | H3: =D3 -> 5 | I3: =E3 -> 10 | J3: =if(F3<10,F3,10) -> 10 | K3: =if(F3>10,F3-10,0) -> 0 | L3: =if((SUMPRODUCT(LARGE(G3:J3,{1,2,3})))/3*2>20,20,TRUNC((SUMPRODUCT(LARGE(G3:J3,{1,2,3})))/3*2,2)) -> 16.66 | M3: =if((SUMPRODUCT(LARGE(G3:J3,{1,2,3}))+K3/2)/3*2>20,20,TRUNC((SUMPRODUCT(LARGE(G3:J3,{1,2,3}))+K3/2)/3*2,2)) -> 16.66
A4: =Worksheet!A4 -> 22101748 | B4: =Worksheet!B4 -> Mst. Zubaida Haque Jetu | D4: 5 | E4: 5 | F4: 5 | G4: =C4 | H4: =D4 -> 5 | I4: =E4 -> 5 | J4: =if(F4<10,F4,10) -> 5 | K4: =if(F4>10,F4-10,0) -> 0 | L4: =if((SUMPRODUCT(LARGE(G4:J4,{1,2,3})))/3*2>20,20,TRUNC((SUMPRODUCT(LARGE(G4:J4,{1,2,3})))/3*2,2)) -> 10 | M4: =if((SUMPRODUCT(LARGE(G4:J4,{1,2,3}))+K4/2)/3*2>20,20,TRUNC((SUMPRODUCT(LARGE(G4:J4,{1,2,3}))+K4/2)/3*2,2)) -> 10
A5: =Worksheet!A5 -> 22299296 | B5: =Worksheet!B5 -> Raihan Karim | C5: 8 | D5: 10 | E5: 3 | F5: 12 | G5: =C5 -> 8 | H5: =D5 -> 10 | I5: =E5 -> 3 | J5: =if(F5<10,F5,10) -> 10 | K5: =if(F5>10,F5-10,0) -> 2 | L5: =if((SUMPRODUCT(LARGE(G5:J5,{1,2,3})))/3*2>20,20,TRUNC((SUMPRODUCT(LARGE(G5:J5,{1,2,3})))/3*2,2)) -> 18.66 | M5: =if((SUMPRODUCT(LARGE(G5:J5,{1,2,3}))+K5/2)/3*2>20,20,TRUNC((SUMPRODUCT(LARGE(G5:J5,{1,2,3}))+K5/2)/3*2,2)) -> 19.33
A6: =Worksheet!A6 -> 23101075 | B6: =Worksheet!B6 -> Abida Nowsheen | C6: 0 | D6: 5 | E6: 3 | F6: 0 | G6: =C6 -> 0 | H6: =D6 -> 5 | I6: =E6 -> 3 | J6: =if(F6<10,F6,10) -> 0 | K6: =if(F6>10,F6-10,0) -> 0 | L6: =if((SUMPRODUCT(LARGE(G6:J6,{1,2,3})))/3*2>20,20,TRUNC((SUMPRODUCT(LARGE(G6:J6,{1,2,3})))/3*2,2)) -> 5.33 | M6: =if((SUMPRODUCT(LARGE(G6:J6,{1,2,3}))+K6/2)/3*2>20,20,TRUNC((SUMPRODUCT(LARGE(G6:J6,{1,2,3}))+K6/2)/3*2,2)) -> 5.33
A7: =Worksheet!A7 -> 23101101 | B7: =Worksheet!B7 -> Jubaida Jahan Prapti | C7: 0 | D7: 0 | E7: 0 | F7: 0 | G7: =C7 -> 0 | H7: =D7 -> 0 | I7: =E7 -> 0 | J7: =if(F7<10,F7,10) -> 0 | K7: =if(F7>10,F7-10,0) -> 0 | L7: =if((SUMPRODUCT(LARGE(G7:J7,{1,2,3})))/3*2>20,20,TRUNC((SUMPRODUCT(LARGE(G7:J7,{1,2,3})))/3*2,2)) -> 0 | M7: =if((SUMPRODUCT(LARGE(G7:J7,{1,2,3}))+K7/2)/3*2>20,20,TRUNC((SUMPRODUCT(LARGE(G7:J7,{1,2,3}))+K7/2)/3*2,2)) -> 0
A8: =Worksheet!A8 -> 23101271 | B8: =Worksheet!B8 -> Sazid Chowdhury | C8: 2 | D8: 5 | E8: 7 | F8: 10 | G8: =C8 -> 2 | H8: =D8 -> 5 | I8: =E8 -> 7 | J8: =if(F8<10,F8,10) -> 10 | K8: =if(F8>10,F8-10,0) -> 0 | L8: =if((SUMPRODUCT(LARGE(G8:J8,{1,2,3})))/3*2>20,20,TRUNC((SUMPRODUCT(LARGE(G8:J8,{1,2,3})))/3*2,2)) -> 14.66 | M8: =if((SUMPRODUCT(LARGE(G8:J8,{1,2,3}))+K8/2)/3*2>20,20,TRUNC((SUMPRODUCT(LARGE(G8:J8,{1,2,3}))+K8/2)/3*2,2)) -> 14.66
A9: =Worksheet!A9 -> 23101378 | B9: =Worksheet!B9 -> Sharif Al Rezoan | D9: 10 | E9: 5 | F9: 12 | G9: =C9 | H9: =D9 -> 10 | I9: =E9 -> 5 | J9: =if(F9<10,F9,10) -> 10 | K9: =if(F9>10,F9-10,0) -> 2 | L9: =if((SUMPRODUCT(LARGE(G9:J9,{1,2,3})))/3*2>20,20,TRUNC((SUMPRODUCT(LARGE(G9:J9,{1,2,3})))/3*2,2)) -> 16.66 | M9: =if((SUMPRODUCT(LARGE(G9:J9,{1,2,3}))+K9/2)/3*2>20,20,TRUNC((SUMPRODUCT(LARGE(G9:J9,{1,2,3}))+K9/2)/3*2,2)) -> 17.33
A10: =Worksheet!A10 -> 23141047 | B10: =Worksheet!B10 -> Mohammad Rashik Ruhullah Rafi | C10: 5.5 | D10: 5 | E10: 6 | G10: =C10 -> 5.5 | H10: =D10 -> 5 | I10: =E10 -> 6 | J10: =if(F10<10,F10,10) | K10: =if(F10>10,F10-10,0) -> 0 | L10: =if((SUMPRODUCT(LARGE(G10:J10,{1,2,3})))/3*2>20,20,TRUNC((SUMPRODUCT(LARGE(G10:J10,{1,2,3})))/3*2,2)) -> 11 | M10: =if((SUMPRODUCT(LARGE(G10:J10,{1,2,3}))+K10/2)/3*2>20,20,TRUNC((SUMPRODUCT(LARGE(G10:J10,{1,2,3}))+K10/2)/3*2,2)) -> 11
A11: =Worksheet!A11 -> 23201093 | B11: =Worksheet!B11 -> S.A.Rahman | C11: 4 | D11: 6 | E11: 6 | F11: 10 | G11: =C11 -> 4 | H11: =D11 -> 6 | I11: =E11 -> 6 | J11: =if(F11<10,F11,10) -> 10 | K11: =if(F11>10,F11-10,0) -> 0 | L11: =if((SUMPRODUCT(LARGE(G11:J11,{1,2,3})))/3*2>20,20,TRUNC((SUMPRODUCT(LARGE(G11:J11,{1,2,3})))/3*2,2)) -> 14.66 | M11: =if((SUMPRODUCT(LARGE(G11:J11,{1,2,3}))+K11/2)/3*2>20,20,TRUNC((SUMPRODUCT(LARGE(G11:J11,{1,2,3}))+K11/2)/3*2,2)) -> 14.66
A12: =Worksheet!A12 -> 23201659 | B12: =Worksheet!B12 -> Maisha Sanjida Akhi | C12: 7.5 | D12: 0 | E12: 0 | F12: 0 | G12: =C12 -> 7.5 | H12: =D12 -> 0 | I12: =E12 -> 0 | J12: =if(F12<10,F12,10) -> 0 | K12: =if(F12>10,F12-10,0) -> 0 | L12: =if((SUMPRODUCT(LARGE(G12:J12,{1,2,3})))/3*2>20,20,TRUNC((SUMPRODUCT(LARGE(G12:J12,{1,2,3})))/3*2,2)) -> 5 | M12: =if((SUMPRODUCT(LARGE(G12:J12,{1,2,3}))+K12/2)/3*2>20,20,TRUNC((SUMPRODUCT(LARGE(G12:J12,{1,2,3}))+K12/2)/3*2,2)) -> 5
A13: =Worksheet!A13 -> 23301410 | B13: =Worksheet!B13 -> Rafid Shahriar Auvro | C13: 5 | D13: 0 | E13: 0 | F13: 0 | G13: =C13 -> 5 | H13: =D13 -> 0 | I13: =E13 -> 0 | J13: =if(F13<10,F13,10) -> 0 | K13: =if(F13>10,F13-10,0) -> 0 | L13: =if((SUMPRODUCT(LARGE(G13:J13,{1,2,3})))/3*2>20,20,TRUNC((SUMPRODUCT(LARGE(G13:J13,{1,2,3})))/3*2,2)) -> 3.33 | M13: =if((SUMPRODUCT(LARGE(G13:J13,{1,2,3}))+K13/2)/3*2>20,20,TRUNC((SUMPRODUCT(LARGE(G13:J13,{1,2,3}))+K13/2)/3*2,2)) -> 3.33
A14: =Worksheet!A14 -> 23301602 | B14: =Worksheet!B14 -> Farhan Anjum | D14: 0 | E14: 0 | F14: 0 | G14: =C14 | H14: =D14 -> 0 | I14: =E14 -> 0 | J14: =if(F14<10,F14,10) -> 0 | K14: =if(F14>10,F14-10,0) -> 0 | L14: =if((SUMPRODUCT(LARGE(G14:J14,{1,2,3})))/3*2>20,20,TRUNC((SUMPRODUCT(LARGE(G14:J14,{1,2,3})))/3*2,2)) -> 0 | M14: =if((SUMPRODUCT(LARGE(G14:J14,{1,2,3}))+K14/2)/3*2>20,20,TRUNC((SUMPRODUCT(LARGE(G14:J14,{1,2,3}))+K14/2)/3*2,2)) -> 0
A15: =Worksheet!A15 -> 24101390 | B15: =Worksheet!B15 -> P. M. Mushfiqur Shium | C15: 9 | D15: 8 | E15: 10 | F15: 11 | G15: =C15 -> 9 | H15: =D15 -> 8 | I15: =E15 -> 10 | J15: =if(F15<10,F15,10) -> 10 | K15: =if(F15>10,F15-10,0) -> 1 | L15: =if((SUMPRODUCT(LARGE(G15:J15,{1,2,3})))/3*2>20,20,TRUNC((SUMPRODUCT(LARGE(G15:J15,{1,2,3})))/3*2,2)) -> 19.33 | M15: =if((SUMPRODUCT(LARGE(G15:J15,{1,2,3}))+K15/2)/3*2>20,20,TRUNC((SUMPRODUCT(LARGE(G15:J15,{1,2,3}))+K15/2)/3*2,2)) -> 19.66
A16: =Worksheet!A16 -> 24101392 | B16: =Worksheet!B16 -> Fardin Islam | C16: 5.5 | D16: 8 | E16: 3 | F16: 12 | G16: =C16 -> 5.5 | H16: =D16 -> 8 | I16: =E16 -> 3 | J16: =if(F16<10,F16,10) -> 10 | K16: =if(F16>10,F16-10,0) -> 2 | L16: =if((SUMPRODUCT(LARGE(G16:J16,{1,2,3})))/3*2>20,20,TRUNC((SUMPRODUCT(LARGE(G16:J16,{1,2,3})))/3*2,2)) -> 15.66 | M16: =if((SUMPRODUCT(LARGE(G16:J16,{1,2,3}))+K16/2)/3*2>20,20,TRUNC((SUMPRODUCT(LARGE(G16:J16,{1,2,3}))+K16/2)/3*2,2)) -> 16.33
A17: =Worksheet!A17 -> 24101431 | B17: =Worksheet!B17 -> Raheeb Al Zabir | C17: 4.5 | D17: 7 | E17: 7 | F17: 11 | G17: =C17 -> 4.5 | H17: =D17 -> 7 | I17: =E17 -> 7 | J17: =if(F17<10,F17,10) -> 10 | K17: =if(F17>10,F17-10,0) -> 1 | L17: =if((SUMPRODUCT(LARGE(G17:J17,{1,2,3})))/3*2>20,20,TRUNC((SUMPRODUCT(LARGE(G17:J17,{1,2,3})))/3*2,2)) -> 16 | M17: =if((SUMPRODUCT(LARGE(G17:J17,{1,2,3}))+K17/2)/3*2>20,20,TRUNC((SUMPRODUCT(LARGE(G17:J17,{1,2,3}))+K17/2)/3*2,2)) -> 16.33
A18: =Worksheet!A18 -> 24101442 | B18: =Worksheet!B18 -> Abdullah Al Noman | C18: 4.5 | D18: 8 | E18: 7 | F18: 1 | G18: =C18 -> 4.5 | H18: =D18 -> 8 | I18: =E18 -> 7 | J18: 10 | K18: =if(F18>10,F18-10,0) -> 0 | L18: =if((SUMPRODUCT(LARGE(G18:J18,{1,2,3})))/3*2>20,20,TRUNC((SUMPRODUCT(LARGE(G18:J18,{1,2,3})))/3*2,2)) -> 16.66 | M18: =if((SUMPRODUCT(LARGE(G18:J18,{1,2,3}))+K18/2)/3*2>20,20,TRUNC((SUMPRODUCT(LARGE(G18:J18,{1,2,3}))+K18/2)/3*2,2)) -> 16.66
A19: =Worksheet!A19 -> 24121353 | B19: =Worksheet!B19 -> Ayatullah Osama Khan | C19: 9 | D19: 5 | E19: 6 | F19: 8 | G19: =C19 -> 9 | H19: =D19 -> 5 | I19: =E19 -> 6 | J19: =if(F19<10,F19,10) -> 8 | K19: =if(F19>10,F19-10,0) -> 0 | L19: =if((SUMPRODUCT(LARGE(G19:J19,{1,2,3})))/3*2>20,20,TRUNC((SUMPRODUCT(LARGE(G19:J19,{1,2,3})))/3*2,2)) -> 15.33 | M19: =if((SUMPRODUCT(LARGE(G19:J19,{1,2,3}))+K19/2)/3*2>20,20,TRUNC((SUMPRODUCT(LARGE(G19:J19,{1,2,3}))+K19/2)/3*2,2)) -> 15.33
A20: =Worksheet!A20 -> 24141008 | B20: =Worksheet!B20 -> Ashvin Al Afroz | C20: 5 | D20: 0 | E20: 0 | F20: 0 | G20: =C20 -> 5 | H20: =D20 -> 0 | I20: =E20 -> 0 | J20: =if(F20<10,F20,10) -> 0 | K20: =if(F20>10,F20-10,0) -> 0 | L20: =if((SUMPRODUCT(LARGE(G20:J20,{1,2,3})))/3*2>20,20,TRUNC((SUMPRODUCT(LARGE(G20:J20,{1,2,3})))/3*2,2)) -> 3.33 | M20: =if((SUMPRODUCT(LARGE(G20:J20,{1,2,3}))+K20/2)/3*2>20,20,TRUNC((SUMPRODUCT(LARGE(G20:J20,{1,2,3}))+K20/2)/3*2,2)) -> 3.33
A21: =Worksheet!A21 -> 24141155 | B21: =Worksheet!B21 -> Md. Abrar Mahib Pritom | C21: 3.5 | D21: 0 | E21: 0 | F21: 0 | G21: =C21 -> 3.5 | H21: =D21 -> 0 | I21: =E21 -> 0 | J21: =if(F21<10,F21,10) -> 0 | K21: =if(F21>10,F21-10,0) -> 0 | L21: =if((SUMPRODUCT(LARGE(G21:J21,{1,2,3})))/3*2>20,20,TRUNC((SUMPRODUCT(LARGE(G21:J21,{1,2,3})))/3*2,2)) -> 2.33 | M21: =if((SUMPRODUCT(LARGE(G21:J21,{1,2,3}))+K21/2)/3*2>20,20,TRUNC((SUMPRODUCT(LARGE(G21:J21,{1,2,3}))+K21/2)/3*2,2)) -> 2.33
A22: =Worksheet!A22 -> 24201090 | B22: =Worksheet!B22 -> Nafis As - Sami | C22: 10 | D22: 7 | E22: 10 | F22: 14 | G22: =C22 -> 10 | H22: =D22 -> 7 | I22: =E22 -> 10 | J22: =if(F22<10,F22,10) -> 10 | K22: =if(F22>10,F22-10,0) -> 4 | L22: =if((SUMPRODUCT(LARGE(G22:J22,{1,2,3})))/3*2>20,20,TRUNC((SUMPRODUCT(LARGE(G22:J22,{1,2,3})))/3*2,2)) -> 20 | M22: =if((SUMPRODUCT(LARGE(G22:J22,{1,2,3}))+K22/2)/3*2>20,20,TRUNC((SUMPRODUCT(LARGE(G22:J22,{1,2,3}))+K22/2)/3*2,2)) -> 20
A23: =Worksheet!A23 -> 24201165 | B23: =Worksheet!B23 -> Jahareen Tasmeem | C23: 6.5 | D23: 10 | E23: 10 | F23: 13 | G23: =C23 -> 6.5 | H23: =D23 -> 10 | I23: =E23 -> 10 | J23: =if(F23<10,F23,10) -> 10 | K23: =if(F23>10,F23-10,0) -> 3 | L23: =if((SUMPRODUCT(LARGE(G23:J23,{1,2,3})))/3*2>20,20,TRUNC((SUMPRODUCT(LARGE(G23:J23,{1,2,3})))/3*2,2)) -> 20 | M23: =if((SUMPRODUCT(LARGE(G23:J23,{1,2,3}))+K23/2)/3*2>20,20,TRUNC((SUMPRODUCT(LARGE(G23:J23,{1,2,3}))+K23/2)/3*2,2)) -> 20
A24: =Worksheet!A24 -> 24201176 | B24: =Worksheet!B24 -> Maheer Tajwar | C24: 7 | D24: 5 | E24: 8 | F24: 10 | G24: =C24 -> 7 | H24: =D24 -> 5 | I24: =E24 -> 8 | J24: =if(F24<10,F24,10) -> 10 | K24: =if(F24>10,F24-10,0) -> 0 | L24: =if((SUMPRODUCT(LARGE(G24:J24,{1,2,3})))/3*2>20,20,TRUNC((SUMPRODUCT(LARGE(G24:J24,{1,2,3})))/3*2,2)) -> 16.66 | M24: =if((SUMPRODUCT(LARGE(G24:J24,{1,2,3}))+K24/2)/3*2>20,20,TRUNC((SUMPRODUCT(LARGE(G24:J24,{1,2,3}))+K24/2)/3*2,2)) -> 16.66
A25: =Worksheet!A25 -> 24201193 | B25: =Worksheet!B25 -> Md.Fardin Islam | C25: 8 | D25: 10 | E25: 7 | F25: 12 | G25: =C25 -> 8 | H25: =D25 -> 10 | I25: =E25 -> 7 | J25: =if(F25<10,F25,10) -> 10 | K25: =if(F25>10,F25-10,0) -> 2 | L25: =if((SUMPRODUCT(LARGE(G25:J25,{1,2,3})))/3*2>20,20,TRUNC((SUMPRODUCT(LARGE(G25:J25,{1,2,3})))/3*2,2)) -> 18.66 | M25: =if((SUMPRODUCT(LARGE(G25:J25,{1,2,3}))+K25/2)/3*2>20,20,TRUNC((SUMPRODUCT(LARGE(G25:J25,{1,2,3}))+K25/2)/3*2,2)) -> 19.33
A26: =Worksheet!A26 -> 24201199 | B26: =Worksheet!B26 -> Faiyaz Rahman | C26: 10 | D26: 10 | E26: 10 | F26: 14 | G26: =C26 -> 10 | H26: =D26 -> 10 | I26: =E26 -> 10 | J26: =if(F26<10,F26,10) -> 10 | K26: =if(F26>10,F26-10,0) -> 4 | L26: =if((SUMPRODUCT(LARGE(G26:J26,{1,2,3})))/3*2>20,20,TRUNC((SUMPRODUCT(LARGE(G26:J26,{1,2,3})))/3*2,2)) -> 20 | M26: =if((SUMPRODUCT(LARGE(G26:J26,{1,2,3}))+K26/2)/3*2>20,20,TRUNC((SUMPRODUCT(LARGE(G26:J26,{1,2,3}))+K26/2)/3*2,2)) -> 20
A27: =Worksheet!A27 -> 24201453 | B27: =Worksheet!B27 -> Md. Zayed Khan | C27: 10 | D27: 0 | E27: 9 | F27: 10 | G27: =C27 -> 10 | H27: =D27 -> 0 | I27: =E27 -> 9 | J27: =if(F27<10,F27,10) -> 10 | K27: =if(F27>10,F27-10,0) -> 0 | L27: =if((SUMPRODUCT(LARGE(G27:J27,{1,2,3})))/3*2>20,20,TRUNC((SUMPRODUCT(LARGE(G27:J27,{1,2,3})))/3*2,2)) -> 19.33 | M27: =if((SUMPRODUCT(LARGE(G27:J27,{1,2,3}))+K27/2)/3*2>20,20,TRUNC((SUMPRODUCT(LARGE(G27:J27,{1,2,3}))+K27/2)/3*2,2)) -> 19.33
A28: =Worksheet!A28 -> 24201455 | B28: =Worksheet!B28 -> Hossain Tasnim Rumki | C28: 8 | D28: 10 | E28: 9 | F28: 10 | G28: =C28 -> 8 | H28: =D28 -> 10 | I28: =E28 -> 9 | J28: =if(F28<10,F28,10) -> 10 | K28: =if(F28>10,F28-10,0) -> 0 | L28: =if((SUMPRODUCT(LARGE(G28:J28,{1,2,3})))/3*2>20,20,TRUNC((SUMPRODUCT(LARGE(G28:J28,{1,2,3})))/3*2,2)) -> 19.33 | M28: =if((SUMPRODUCT(LARGE(G28:J28,{1,2,3}))+K28/2)/3*2>20,20,TRUNC((SUMPRODUCT(LARGE(G28:J28,{1,2,3}))+K28/2)/3*2,2)) -> 19.33
A29: =Worksheet!A29 -> 24204199 | B29: =Worksheet!B29 -> Abdul Mumit Bin Jafor | C29: 6.5 | D29: 5 | E29: 8 | F29: 10 | G29: =C29 -> 6.5 | H29: =D29 -> 5 | I29: =E29 -> 8 | J29: =if(F29<10,F29,10) -> 10 | K29: =if(F29>10,F29-10,0) -> 0 | L29: =if((SUMPRODUCT(LARGE(G29:J29,{1,2,3})))/3*2>20,20,TRUNC((SUMPRODUCT(LARGE(G29:J29,{1,2,3})))/3*2,2)) -> 16.33 | M29: =if((SUMPRODUCT(LARGE(G29:J29,{1,2,3}))+K29/2)/3*2>20,20,TRUNC((SUMPRODUCT(LARGE(G29:J29,{1,2,3}))+K29/2)/3*2,2)) -> 16.33
A30: =Worksheet!A30 -> 24301002 | B30: =Worksheet!B30 -> Wamiza Mehjabin | C30: 6 | D30: 5 | E30: 7 | G30: =C30 -> 6 | H30: =D30 -> 5 | I30: =E30 -> 7 | J30: =if(F30<10,F30,10) | K30: =if(F30>10,F30-10,0) -> 0 | L30: =if((SUMPRODUCT(LARGE(G30:J30,{1,2,3})))/3*2>20,20,TRUNC((SUMPRODUCT(LARGE(G30:J30,{1,2,3})))/3*2,2)) -> 12 | M30: =if((SUMPRODUCT(LARGE(G30:J30,{1,2,3}))+K30/2)/3*2>20,20,TRUNC((SUMPRODUCT(LARGE(G30:J30,{1,2,3}))+K30/2)/3*2,2)) -> 12
A31: =Worksheet!A31 -> 24301003 | B31: =Worksheet!B31 -> Shahir Sharaf Chowdhury | C31: 9.5 | D31: 5 | F31: 3 | G31: =C31 -> 9.5 | H31: =D31 -> 5 | I31: =E31 | J31: =if(F31<10,F31,10) -> 3 | K31: =if(F31>10,F31-10,0) -> 0 | L31: =if((SUMPRODUCT(LARGE(G31:J31,{1,2,3})))/3*2>20,20,TRUNC((SUMPRODUCT(LARGE(G31:J31,{1,2,3})))/3*2,2)) -> 11.66 | M31: =if((SUMPRODUCT(LARGE(G31:J31,{1,2,3}))+K31/2)/3*2>20,20,TRUNC((SUMPRODUCT(LARGE(G31:J31,{1,2,3}))+K31/2)/3*2,2)) -> 11.66
A32: =Worksheet!A32 -> 24301116 | B32: =Worksheet!B32 -> Mahajabin Islam | C32: 10 | D32: 10 | E32: 8 | F32: 10 | G32: =C32 -> 10 | H32: =D32 -> 10 | I32: =E32 -> 8 | J32: =if(F32<10,F32,10) -> 10 | K32: =if(F32>10,F32-10,0) -> 0 | L32: =if((SUMPRODUCT(LARGE(G32:J32,{1,2,3})))/3*2>20,20,TRUNC((SUMPRODUCT(LARGE(G32:J32,{1,2,3})))/3*2,2)) -> 20 | M32: =if((SUMPRODUCT(LARGE(G32:J32,{1,2,3}))+K32/2)/3*2>20,20,TRUNC((SUMPRODUCT(LARGE(G32:J32,{1,2,3}))+K32/2)/3*2,2)) -> 20
A33: =Worksheet!A33 -> 24301173 | B33: =Worksheet!B33 -> Shahida Rahman | C33: 7 | D33: 10 | E33: 10 | F33: 10 | G33: =C33 -> 7 | H33: =D33 -> 10 | I33: =E33 -> 10 | J33: =if(F33<10,F33,10) -> 10 | K33: =if(F33>10,F33-10,0) -> 0 | L33: =if((SUMPRODUCT(LARGE(G33:J33,{1,2,3})))/3*2>20,20,TRUNC((SUMPRODUCT(LARGE(G33:J33,{1,2,3})))/3*2,2)) -> 20 | M33: =if((SUMPRODUCT(LARGE(G33:J33,{1,2,3}))+K33/2)/3*2>20,20,TRUNC((SUMPRODUCT(LARGE(G33:J33,{1,2,3}))+K33/2)/3*2,2)) -> 20
A34: =Worksheet!A34 -> 24301197 | B34: =Worksheet!B34 -> Samin Yasar Nafi | C34: 6.5 | D34: 0 | E34: 0 | F34: 0 | G34: =C34 -> 6.5 | H34: =D34 -> 0 | I34: =E34 -> 0 | J34: =if(F34<10,F34,10) -> 0 | K34: =if(F34>10,F34-10,0) -> 0 | L34: =if((SUMPRODUCT(LARGE(G34:J34,{1,2,3})))/3*2>20,20,TRUNC((SUMPRODUCT(LARGE(G34:J34,{1,2,3})))/3*2,2)) -> 4.33 | M34: =if((SUMPRODUCT(LARGE(G34:J34,{1,2,3}))+K34/2)/3*2>20,20,TRUNC((SUMPRODUCT(LARGE(G34:J34,{1,2,3}))+K34/2)/3*2,2)) -> 4.33
A35: =Worksheet!A35 -> 24301282 | B35: =Worksheet!B35 -> Samin Nuzaima | C35: 7 | D35: 8 | E35: 6 | F35: 10 | G35: =C35 -> 7 | H35: =D35 -> 8 | I35: =E35 -> 6 | J35: =if(F35<10,F35,10) -> 10 | K35: =if(F35>10,F35-10,0) -> 0 | L35: =if((SUMPRODUCT(LARGE(G35:J35,{1,2,3})))/3*2>20,20,TRUNC((SUMPRODUCT(LARGE(G35:J35,{1,2,3})))/3*2,2)) -> 16.66 | M35: =if((SUMPRODUCT(LARGE(G35:J35,{1,2,3}))+K35/2)/3*2>20,20,TRUNC((SUMPRODUCT(LARGE(G35:J35,{1,2,3}))+K35/2)/3*2,2)) -> 16.66
A36: =Worksheet!A36 -> 24321232 | B36: =Worksheet!B36 -> Kazi Yasin Hridoy | C36: 10 | D36: 10 | E36: 10 | F36: 8 | G36: =C36 -> 10 | H36: =D36 -> 10 | I36: =E36 -> 10 | J36: =if(F36<10,F36,10) -> 8 | K36: =if(F36>10,F36-10,0) -> 0 | L36: =if((SUMPRODUCT(LARGE(G36:J36,{1,2,3})))/3*2>20,20,TRUNC((SUMPRODUCT(LARGE(G36:J36,{1,2,3})))/3*2,2)) -> 20 | M36: =if((SUMPRODUCT(LARGE(G36:J36,{1,2,3}))+K36/2)/3*2>20,20,TRUNC((SUMPRODUCT(LARGE(G36:J36,{1,2,3}))+K36/2)/3*2,2)) -> 20
A37: =Worksheet!A37 -> 24321234 | B37: =Worksheet!B37 -> Al Jayed Rup | C37: 7 | D37: 7 | E37: 7 | F37: 14 | G37: =C37 -> 7 | H37: =D37 -> 7 | I37: =E37 -> 7 | J37: =if(F37<10,F37,10) -> 10 | K37: =if(F37>10,F37-10,0) -> 4 | L37: =if((SUMPRODUCT(LARGE(G37:J37,{1,2,3})))/3*2>20,20,TRUNC((SUMPRODUCT(LARGE(G37:J37,{1,2,3})))/3*2,2)) -> 16 | M37: =if((SUMPRODUCT(LARGE(G37:J37,{1,2,3}))+K37/2)/3*2>20,20,TRUNC((SUMPRODUCT(LARGE(G37:J37,{1,2,3}))+K37/2)/3*2,2)) -> 17.33

Sheet Assignment
A1: Student Id | C1: A1 | D1: A2 | E1: A3 | F1: A4 | G1: Assignment (out of 5)
A2: =IFERROR(__xludf.DUMMYFUNCTION("IMPORTRANGE(""https://docs.google.com/spreadsheets/d/1tmyDd48UzVWk1pBjmWjdHkBHYbZX9G9Y-Lh0NOCkbc8/edit?resourcekey=&gid=385477979#gid=385477979"", ""Sheet5!A2:F38"")"),2.0301033E7) -> 20301033 | B2: =IFERROR(__xludf.DUMMYFUNCTION("""COMPUTED_VALUE"""),"Amlan Dutta") -> Amlan Dutta | C2: =IFERROR(__xludf.DUMMYFUNCTION("""COMPUTED_VALUE"""),5.0) -> 5 | D2: =IFERROR(__xludf.DUMMYFUNCTION("""COMPUTED_VALUE"""),0.0) -> 0 | E2: =IFERROR(__xludf.DUMMYFUNCTION("""COMPUTED_VALUE"""),5.0) -> 5 | F2: =IFERROR(__xludf.DUMMYFUNCTION("""COMPUTED_VALUE"""),5.0) -> 5 | G2: =SUM(C2:F2)/4 -> 3.75
A3: =IFERROR(__xludf.DUMMYFUNCTION("""COMPUTED_VALUE"""),2.2101425E7) -> 22101425 | B3: =IFERROR(__xludf.DUMMYFUNCTION("""COMPUTED_VALUE"""),"Khandokar Yusuf Khalid") -> Khandokar Yusuf Khalid | C3: =IFERROR(__xludf.DUMMYFUNCTION("""COMPUTED_VALUE"""),5.0) -> 5 | D3: =IFERROR(__xludf.DUMMYFUNCTION("""COMPUTED_VALUE"""),0.0) -> 0 | E3: =IFERROR(__xludf.DUMMYFUNCTION("""COMPUTED_VALUE"""),5.0) -> 5 | F3: =IFERROR(__xludf.DUMMYFUNCTION("""COMPUTED_VALUE"""),5.0) -> 5 | G3: =SUM(C3:F3)/4 -> 3.75
A4: =IFERROR(__xludf.DUMMYFUNCTION("""COMPUTED_VALUE"""),2.2101748E7) -> 22101748 | B4: =IFERROR(__xludf.DUMMYFUNCTION("""COMPUTED_VALUE"""),"Mst. Zubaida Haque Jetu") -> Mst. Zubaida Haque Jetu | C4: =IFERROR(__xludf.DUMMYFUNCTION("""COMPUTED_VALUE"""),5.0) -> 5 | D4: =IFERROR(__xludf.DUMMYFUNCTION("""COMPUTED_VALUE"""),5.0) -> 5 | E4: =IFERROR(__xludf.DUMMYFUNCTION("""COMPUTED_VALUE"""),5.0) -> 5 | F4: =IFERROR(__xludf.DUMMYFUNCTION("""COMPUTED_VALUE"""),5.0) -> 5 | G4: =SUM(C4:F4)/4 -> 5
A5: =IFERROR(__xludf.DUMMYFUNCTION("""COMPUTED_VALUE"""),2.2299296E7) -> 22299296 | B5: =IFERROR(__xludf.DUMMYFUNCTION("""COMPUTED_VALUE"""),"Raihan Karim") -> Raihan Karim | C5: =IFERROR(__xludf.DUMMYFUNCTION("""COMPUTED_VALUE"""),5.0) -> 5 | D5: =IFERROR(__xludf.DUMMYFUNCTION("""COMPUTED_VALUE"""),5.0) -> 5 | E5: =IFERROR(__xludf.DUMMYFUNCTION("""COMPUTED_VALUE"""),5.0) -> 5 | F5: =IFERROR(__xludf.DUMMYFUNCTION("""COMPUTED_VALUE"""),5.0) -> 5 | G5: =SUM(C5:F5)/4 -> 5
A6: =IFERROR(__xludf.DUMMYFUNCTION("""COMPUTED_VALUE"""),2.3101075E7) -> 23101075 | B6: =IFERROR(__xludf.DUMMYFUNCTION("""COMPUTED_VALUE"""),"Abida Nowsheen") -> Abida Nowsheen | C6: =IFERROR(__xludf.DUMMYFUNCTION("""COMPUTED_VALUE"""),0.0) -> 0 | D6: =IFERROR(__xludf.DUMMYFUNCTION("""COMPUTED_VALUE"""),0.0) -> 0 | E6: =IFERROR(__xludf.DUMMYFUNCTION("""COMPUTED_VALUE"""),0.0) -> 0 | F6: =IFERROR(__xludf.DUMMYFUNCTION("""COMPUTED_VALUE"""),0.0) -> 0 | G6: =SUM(C6:F6)/4 -> 0
A7: =IFERROR(__xludf.DUMMYFUNCTION("""COMPUTED_VALUE"""),2.3101101E7) -> 23101101 | B7: =IFERROR(__xludf.DUMMYFUNCTION("""COMPUTED_VALUE"""),"Jubaida Jahan Prapti") -> Jubaida Jahan Prapti | C7: =IFERROR(__xludf.DUMMYFUNCTION("""COMPUTED_VALUE"""),0.0) -> 0 | D7: =IFERROR(__xludf.DUMMYFUNCTION("""COMPUTED_VALUE"""),5.0) -> 5 | E7: =IFERROR(__xludf.DUMMYFUNCTION("""COMPUTED_VALUE"""),0.0) -> 0 | F7: =IFERROR(__xludf.DUMMYFUNCTION("""COMPUTED_VALUE"""),0.0) -> 0 | G7: =SUM(C7:F7)/4 -> 1.25
A8: =IFERROR(__xludf.DUMMYFUNCTION("""COMPUTED_VALUE"""),2.3101271E7) -> 23101271 | B8: =IFERROR(__xludf.DUMMYFUNCTION("""COMPUTED_VALUE"""),"Sazid Chowdhury") -> Sazid Chowdhury | C8: =IFERROR(__xludf.DUMMYFUNCTION("""COMPUTED_VALUE"""),5.0) -> 5 | D8: =IFERROR(__xludf.DUMMYFUNCTION("""COMPUTED_VALUE"""),5.0) -> 5 | E8: =IFERROR(__xludf.DUMMYFUNCTION("""COMPUTED_VALUE"""),5.0) -> 5 | F8: =IFERROR(__xludf.DUMMYFUNCTION("""COMPUTED_VALUE"""),5.0) -> 5 | G8: =SUM(C8:F8)/4 -> 5
A9: =IFERROR(__xludf.DUMMYFUNCTION("""COMPUTED_VALUE"""),2.3101378E7) -> 23101378 | B9: =IFERROR(__xludf.DUMMYFUNCTION("""COMPUTED_VALUE"""),"Sharif Al Rezoan") -> Sharif Al Rezoan | C9: =IFERROR(__xludf.DUMMYFUNCTION("""COMPUTED_VALUE"""),5.0) -> 5 | D9: =IFERROR(__xludf.DUMMYFUNCTION("""COMPUTED_VALUE"""),5.0) -> 5 | E9: =IFERROR(__xludf.DUMMYFUNCTION("""COMPUTED_VALUE"""),0.0) -> 0 | F9: =IFERROR(__xludf.DUMMYFUNCTION("""COMPUTED_VALUE"""),0.0) -> 0 | G9: =SUM(C9:F9)/4 -> 2.5
A10: =IFERROR(__xludf.DUMMYFUNCTION("""COMPUTED_VALUE"""),2.3141047E7) -> 23141047 | B10: =IFERROR(__xludf.DUMMYFUNCTION("""COMPUTED_VALUE"""),"Mohammad Rashik Ruhullah Rafi") -> Mohammad Rashik Ruhullah Rafi | C10: =IFERROR(__xludf.DUMMYFUNCTION("""COMPUTED_VALUE"""),0.0) -> 0 | D10: =IFERROR(__xludf.DUMMYFUNCTION("""COMPUTED_VALUE"""),0.0) -> 0 | E10: =IFERROR(__xludf.DUMMYFUNCTION("""COMPUTED_VALUE"""),0.0) -> 0 | F10: =IFERROR(__xludf.DUMMYFUNCTION("""COMPUTED_VALUE"""),0.0) -> 0 | G10: =SUM(C10:F10)/4 -> 0
A11: =IFERROR(__xludf.DUMMYFUNCTION("""COMPUTED_VALUE"""),2.3201093E7) -> 23201093 | B11: =IFERROR(__xludf.DUMMYFUNCTION("""COMPUTED_VALUE"""),"S.A.Rahman") -> S.A.Rahman | C11: =IFERROR(__xludf.DUMMYFUNCTION("""COMPUTED_VALUE"""),5.0) -> 5 | D11: =IFERROR(__xludf.DUMMYFUNCTION("""COMPUTED_VALUE"""),5.0) -> 5 | E11: =IFERROR(__xludf.DUMMYFUNCTION("""COMPUTED_VALUE"""),0.0) -> 0 | F11: =IFERROR(__xludf.DUMMYFUNCTION("""COMPUTED_VALUE"""),0.0) -> 0 | G11: =SUM(C11:F11)/4 -> 2.5
A12: =IFERROR(__xludf.DUMMYFUNCTION("""COMPUTED_VALUE"""),2.3201659E7) -> 23201659 | B12: =IFERROR(__xludf.DUMMYFUNCTION("""COMPUTED_VALUE"""),"Maisha Sanjida Akhi") -> Maisha Sanjida Akhi | C12: =IFERROR(__xludf.DUMMYFUNCTION("""COMPUTED_VALUE"""),0.0) -> 0 | D12: =IFERROR(__xludf.DUMMYFUNCTION("""COMPUTED_VALUE"""),0.0) -> 0 | E12: =IFERROR(__xludf.DUMMYFUNCTION("""COMPUTED_VALUE"""),0.0) -> 0 | F12: =IFERROR(__xludf.DUMMYFUNCTION("""COMPUTED_VALUE"""),0.0) -> 0 | G12: =SUM(C12:F12)/4 -> 0
A13: =IFERROR(__xludf.DUMMYFUNCTION("""COMPUTED_VALUE"""),2.330141E7) -> 23301410 | B13: =IFERROR(__xludf.DUMMYFUNCTION("""COMPUTED_VALUE"""),"Rafid Shahriar Auvro") -> Rafid Shahriar Auvro | C13: =IFERROR(__xludf.DUMMYFUNCTION("""COMPUTED_VALUE"""),0.0) -> 0 | D13: =IFERROR(__xludf.DUMMYFUNCTION("""COMPUTED_VALUE"""),0.0) -> 0 | E13: =IFERROR(__xludf.DUMMYFUNCTION("""COMPUTED_VALUE"""),0.0) -> 0 | F13: =IFERROR(__xludf.DUMMYFUNCTION("""COMPUTED_VALUE"""),0.0) -> 0 | G13: =SUM(C13:F13)/4 -> 0
A14: =IFERROR(__xludf.DUMMYFUNCTION("""COMPUTED_VALUE"""),2.3301602E7) -> 23301602 | B14: =IFERROR(__xludf.DUMMYFUNCTION("""COMPUTED_VALUE"""),"Farhan Anjum") -> Farhan Anjum | C14: =IFERROR(__xludf.DUMMYFUNCTION("""COMPUTED_VALUE"""),5.0) -> 5 | D14: =IFERROR(__xludf.DUMMYFUNCTION("""COMPUTED_VALUE"""),0.0) -> 0 | E14: =IFERROR(__xludf.DUMMYFUNCTION("""COMPUTED_VALUE"""),0.0) -> 0 | F14: =IFERROR(__xludf.DUMMYFUNCTION("""COMPUTED_VALUE"""),0.0) -> 0 | G14: =SUM(C14:F14)/4 -> 1.25
A15: =IFERROR(__xludf.DUMMYFUNCTION("""COMPUTED_VALUE"""),2.410139E7) -> 24101390 | B15: =IFERROR(__xludf.DUMMYFUNCTION("""COMPUTED_VALUE"""),"P. M. Mushfiqur Shium") -> P. M. Mushfiqur Shium | C15: =IFERROR(__xludf.DUMMYFUNCTION("""COMPUTED_VALUE"""),5.0) -> 5 | D15: =IFERROR(__xludf.DUMMYFUNCTION("""COMPUTED_VALUE"""),5.0) -> 5 | E15: =IFERROR(__xludf.DUMMYFUNCTION("""COMPUTED_VALUE"""),5.0) -> 5 | F15: =IFERROR(__xludf.DUMMYFUNCTION("""COMPUTED_VALUE"""),5.0) -> 5 | G15: =SUM(C15:F15)/4 -> 5
A16: =IFERROR(__xludf.DUMMYFUNCTION("""COMPUTED_VALUE"""),2.4101392E7) -> 24101392 | B16: =IFERROR(__xludf.DUMMYFUNCTION("""COMPUTED_VALUE"""),"Fardin Islam") -> Fardin Islam | C16: =IFERROR(__xludf.DUMMYFUNCTION("""COMPUTED_VALUE"""),5.0) -> 5 | D16: =IFERROR(__xludf.DUMMYFUNCTION("""COMPUTED_VALUE"""),5.0) -> 5 | E16: =IFERROR(__xludf.DUMMYFUNCTION("""COMPUTED_VALUE"""),5.0) -> 5 | F16: =IFERROR(__xludf.DUMMYFUNCTION("""COMPUTED_VALUE"""),5.0) -> 5 | G16: =SUM(C16:F16)/4 -> 5
A17: =IFERROR(__xludf.DUMMYFUNCTION("""COMPUTED_VALUE"""),2.4101431E7) -> 24101431 | B17: =IFERROR(__xludf.DUMMYFUNCTION("""COMPUTED_VALUE"""),"Raheeb Al Zabir") -> Raheeb Al Zabir | C17: =IFERROR(__xludf.DUMMYFUNCTION("""COMPUTED_VALUE"""),5.0) -> 5 | D17: =IFERROR(__xludf.DUMMYFUNCTION("""COMPUTED_VALUE"""),5.0) -> 5 | E17: =IFERROR(__xludf.DUMMYFUNCTION("""COMPUTED_VALUE"""),5.0) -> 5 | F17: =IFERROR(__xludf.DUMMYFUNCTION("""COMPUTED_VALUE"""),5.0) -> 5 | G17: =SUM(C17:F17)/4 -> 5
A18: =IFERROR(__xludf.DUMMYFUNCTION("""COMPUTED_VALUE"""),2.4101442E7) -> 24101442 | B18: =IFERROR(__xludf.DUMMYFUNCTION("""COMPUTED_VALUE"""),"Abdullah Al Noman") -> Abdullah Al Noman | C18: =IFERROR(__xludf.DUMMYFUNCTION("""COMPUTED_VALUE"""),5.0) -> 5 | D18: =IFERROR(__xludf.DUMMYFUNCTION("""COMPUTED_VALUE"""),5.0) -> 5 | E18: =IFERROR(__xludf.DUMMYFUNCTION("""COMPUTED_VALUE"""),5.0) -> 5 | F18: =IFERROR(__xludf.DUMMYFUNCTION("""COMPUTED_VALUE"""),5.0) -> 5 | G18: =SUM(C18:F18)/4 -> 5
A19: =IFERROR(__xludf.DUMMYFUNCTION("""COMPUTED_VALUE"""),2.4121353E7) -> 24121353 | B19: =IFERROR(__xludf.DUMMYFUNCTION("""COMPUTED_VALUE"""),"Ayatullah Osama Khan") -> Ayatullah Osama Khan | C19: =IFERROR(__xludf.DUMMYFUNCTION("""COMPUTED_VALUE"""),5.0) -> 5 | D19: =IFERROR(__xludf.DUMMYFUNCTION("""COMPUTED_VALUE"""),5.0) -> 5 | E19: =IFERROR(__xludf.DUMMYFUNCTION("""COMPUTED_VALUE"""),5.0) -> 5 | F19: =IFERROR(__xludf.DUMMYFUNCTION("""COMPUTED_VALUE"""),5.0) -> 5 | G19: =SUM(C19:F19)/4 -> 5
A20: =IFERROR(__xludf.DUMMYFUNCTION("""COMPUTED_VALUE"""),2.4141008E7) -> 24141008 | B20: =IFERROR(__xludf.DUMMYFUNCTION("""COMPUTED_VALUE"""),"Ashvin Al Afroz") -> Ashvin Al Afroz | C20: =IFERROR(__xludf.DUMMYFUNCTION("""COMPUTED_VALUE"""),5.0) -> 5 | D20: =IFERROR(__xludf.DUMMYFUNCTION("""COMPUTED_VALUE"""),5.0) -> 5 | E20: =IFERROR(__xludf.DUMMYFUNCTION("""COMPUTED_VALUE"""),0.0) -> 0 | F20: =IFERROR(__xludf.DUMMYFUNCTION("""COMPUTED_VALUE"""),0.0) -> 0 | G20: =SUM(C20:F20)/4 -> 2.5
A21: =IFERROR(__xludf.DUMMYFUNCTION("""COMPUTED_VALUE"""),2.4141155E7) -> 24141155 | B21: =IFERROR(__xludf.DUMMYFUNCTION("""COMPUTED_VALUE"""),"Md. Abrar Mahib Pritom") -> Md. Abrar Mahib Pritom | C21: =IFERROR(__xludf.DUMMYFUNCTION("""COMPUTED_VALUE"""),0.0) -> 0 | D21: =IFERROR(__xludf.DUMMYFUNCTION("""COMPUTED_VALUE"""),0.0) -> 0 | E21: =IFERROR(__xludf.DUMMYFUNCTION("""COMPUTED_VALUE"""),0.0) -> 0 | F21: =IFERROR(__xludf.DUMMYFUNCTION("""COMPUTED_VALUE"""),0.0) -> 0 | G21: =SUM(C21:F21)/4 -> 0
A22: =IFERROR(__xludf.DUMMYFUNCTION("""COMPUTED_VALUE"""),2.420109E7) -> 24201090 | B22: =IFERROR(__xludf.DUMMYFUNCTION("""COMPUTED_VALUE"""),"Nafis As - Sami") -> Nafis As - Sami | C22: =IFERROR(__xludf.DUMMYFUNCTION("""COMPUTED_VALUE"""),5.0) -> 5 | D22: =IFERROR(__xludf.DUMMYFUNCTION("""COMPUTED_VALUE"""),5.0) -> 5 | E22: =IFERROR(__xludf.DUMMYFUNCTION("""COMPUTED_VALUE"""),5.0) -> 5 | F22: =IFERROR(__xludf.DUMMYFUNCTION("""COMPUTED_VALUE"""),5.0) -> 5 | G22: =SUM(C22:F22)/4 -> 5
A23: =IFERROR(__xludf.DUMMYFUNCTION("""COMPUTED_VALUE"""),2.4201165E7) -> 24201165 | B23: =IFERROR(__xludf.DUMMYFUNCTION("""COMPUTED_VALUE"""),"Jahareen Tasmeem") -> Jahareen Tasmeem | C23: =IFERROR(__xludf.DUMMYFUNCTION("""COMPUTED_VALUE"""),5.0) -> 5 | D23: =IFERROR(__xludf.DUMMYFUNCTION("""COMPUTED_VALUE"""),5.0) -> 5 | E23: =IFERROR(__xludf.DUMMYFUNCTION("""COMPUTED_VALUE"""),5.0) -> 5 | F23: =IFERROR(__xludf.DUMMYFUNCTION("""COMPUTED_VALUE"""),5.0) -> 5 | G23: =SUM(C23:F23)/4 -> 5
