Workbook

Sheet Worksheet
A1: Student Id | B1: Name
A2: 22101165 | B2: Asif Mahmud | D2: CSE
A3: 22101192 | B3: Maliha Anan Promi | C3: Female | D3: CSE | E3: 1842405184 | F3: maliha.anan.promi@g.bracu.ac.bd
A4: 22101297 | B4: Parthib Biswas | C4: Male | D4: CSE | E4: 1304896808 | F4: parthib.biswas@g.bracu.ac.bd
A5: 22201706 | B5: Sadnan Basher | C5: Male | D5: CSE | E5: 1953941972 | F5: sadnan.basher@g.bracu.ac.bd
A6: 22301485 | B6: Tamal Kumar Dey | C6: Male | D6: CSE | E6: 1535464722 | F6: tamal.kumar.dey@g.bracu.ac.bd
A7: 22301581 | B7: Rufaida Zoon Raiyan | C7: Female | D7: CS | E7: 1743399277 | F7: rufaida.zoon.raiyan@g.bracu.ac.bd
A8: 23101152 | B8: Shihabul Ishraq Tanim | C8: Male | D8: CS | E8: 1625865478 | F8: shihabul.ishraq.tanim@g.bracu.ac.bd
A9: 23101196 | B9: Nandini Das Jhumu | C9: Female | D9: CSE | E9: 1909151317 | F9: nandini.das.jhumu@g.bracu.ac.bd
A10: 23201055 | B10: Ridwanul Azim | C10: Male | D10: CSE | E10: 1912598849 | F10: ridwanul.azim@g.bracu.ac.bd
A11: 23301401 | B11: Saddat Hossain Sifat | C11: Male | D11: CSE | E11: 1715017247 | F11: saddat.hossain.sifat@g.bracu.ac.bd
A12: 24101043 | B12: Md Abu Noman Kabbo | C12: Male | D12: CSE | E12: 1312868266 | F12: abu.noman.kabbo@g.bracu.ac.bd
A13: 24101081 | B13: Adil Abdullah Mahdi | C13: Male | D13: CSE | E13: 1833156027 | F13: adil.abdullah.mahdi@g.bracu.ac.bd
A14: 24101103 | B14: Zunayed Amin | C14: Male | D14: CSE | E14: 1795346838 | F14: zunayed.amin@g.bracu.ac.bd
... A38: 24321222 | B38: Mir Mainul Ahmed | C38: Male | D38: CSE | E38: 1902595477 | F38: mir.mainul.ahmed@g.bracu.ac.bd

Sheet Grade Sheet
C1: BRAC University
C2: Final Grade Sheet
C3: Summer 2025
C4: Department/ School: CSE
B5: Course No : | C5: CSE 221
B6: Course Title: | C6: Algorithms
B7: Section: | C7: 13
B8: Faculty Name: | C8: Abdullah Al Nakib
A9: Sl # | B9: ID # | C9: Name | D9: Atten. | E9: Quiz | F9: Assig. | G9: Lab | H9: Midterm | I9: Project 1 | J9: Project 2 | K9: Final | L9: Total | M9: Total | N9: Grades | O9: Suffix
D10: 0 | E10: 0.2 | F10: 0.05 | G10: 0.25 | H10: 0.2 | I10: 0 | J10: 0 | K10: 0.3 | L10: =SUM(D10:K10)*100 -> 100 | M10: =SUM(D10:K10) -> 1 | N10: (with suffix) | O10: (in words)
A11: 1 | B11: =Worksheet!A2 -> 22101165 | C11: =Worksheet!B2 -> Asif Mahmud | E11: =VLOOKUP(B11,'All Marks'!$A$2:$G$39,4,FALSE) -> 15.66 | F11: =VLOOKUP(B11,'All Marks'!$A$2:$G$40,3,FALSE) -> 0 | G11: =VLOOKUP(B11,'All Marks'!$A$2:$G$40,7,FALSE) -> 2.56 | H11: =VLOOKUP(B11,'All Marks'!$A$2:$G$40,5,FALSE) -> 12.3 | K11: =VLOOKUP(B11,'All Marks'!$A$2:$G$40,6,FALSE) -> 19.9 | L11: =SUM(E11:K11) -> 50.42 | M11: =IF(AND(L11>=96.5,L11<97),L11,ROUND(L11,0)) -> 50 | N11: =IF(M11<65,IF(M11<55,IF(M11<52,IF(M11<50,"F","D-"),"D"),IF(M11<57,"D+",IF(M11<60,"C-","C"))),IF(M11<75,IF(M11<70,"C+","B-"),IF(M11<85,IF(M11<80,"B","B+"),IF(M11<90,"A-",IF(M11<97,"A","A+"))))) -> D- | O11: =IF(M11<65,IF(M11<55,IF(M11<52,IF(M11<50,"PLAIN","MINUS"),"PLAIN"),IF(M11<57,"PLUS",IF(M11<60,"MINUS","PLAIN"))),IF(M11<75,IF(M11<70,"PLUS","MINUS"),IF(M11<85,IF(M11<80,"PLAIN","PLUS"),IF(M11<90,"MINUS",IF(M11<97,"PLAIN","PLUS"))))) -> MINUS | Q11: ='All Marks'!H2 -> 50.42 | R11: =EQ(Q11,L11) -> TRUE
A12: 2 | B12: =Worksheet!A3 -> 22101192 | C12: =Worksheet!B3 -> Maliha Anan Promi | E12: =VLOOKUP(B12,'All Marks'!$A$3:$G$39,4,FALSE) -> 13.33 | F12: =VLOOKUP(B12,'All Marks'!$A$3:$G$40,3,FALSE) -> 5 | G12: =VLOOKUP(B12,'All Marks'!$A$3:$G$40,7,FALSE) -> 0.48 | H12: =VLOOKUP(B12,'All Marks'!$A$3:$G$40,5,FALSE) -> 8.9 | K12: =VLOOKUP(B12,'All Marks'!$A$3:$G$40,6,FALSE) -> 9.8 | L12: =SUM(E12:K12) -> 37.51 | M12: =IF(AND(L12>=96.5,L12<97),L12,ROUND(L12,0)) -> 38 | N12: =IF(M12<65,IF(M12<55,IF(M12<52,IF(M12<50,"F","D-"),"D"),IF(M12<57,"D+",IF(M12<60,"C-","C"))),IF(M12<75,IF(M12<70,"C+","B-"),IF(M12<85,IF(M12<80,"B","B+"),IF(M12<90,"A-",IF(M12<97,"A","A+"))))) -> F | O12: =IF(M12<65,IF(M12<55,IF(M12<52,IF(M12<50,"PLAIN","MINUS"),"PLAIN"),IF(M12<57,"PLUS",IF(M12<60,"MINUS","PLAIN"))),IF(M12<75,IF(M12<70,"PLUS","MINUS"),IF(M12<85,IF(M12<80,"PLAIN","PLUS"),IF(M12<90,"MINUS",IF(M12<97,"PLAIN","PLUS"))))) -> PLAIN | Q12: ='All Marks'!H3 -> 37.51 | R12: =EQ(Q12,L12) -> TRUE
A13: 3 | B13: =Worksheet!A4 -> 22101297 | C13: =Worksheet!B4 -> Parthib Biswas | E13: =VLOOKUP(B13,'All Marks'!$A$3:$G$39,4,FALSE) -> 9.33 | F13: =VLOOKUP(B13,'All Marks'!$A$3:$G$40,3,FALSE) -> 3.75 | G13: =VLOOKUP(B13,'All Marks'!$A$3:$G$40,7,FALSE) -> 4.82 | H13: =VLOOKUP(B13,'All Marks'!$A$3:$G$40,5,FALSE) -> 7.5 | K13: =VLOOKUP(B13,'All Marks'!$A$3:$G$40,6,FALSE) -> 14.3 | L13: =SUM(E13:K13) -> 39.7 | M13: =IF(AND(L13>=96.5,L13<97),L13,ROUND(L13,0)) -> 40 | N13: =IF(M13<65,IF(M13<55,IF(M13<52,IF(M13<50,"F","D-"),"D"),IF(M13<57,"D+",IF(M13<60,"C-","C"))),IF(M13<75,IF(M13<70,"C+","B-"),IF(M13<85,IF(M13<80,"B","B+"),IF(M13<90,"A-",IF(M13<97,"A","A+"))))) -> F | O13: =IF(M13<65,IF(M13<55,IF(M13<52,IF(M13<50,"PLAIN","MINUS"),"PLAIN"),IF(M13<57,"PLUS",IF(M13<60,"MINUS","PLAIN"))),IF(M13<75,IF(M13<70,"PLUS","MINUS"),IF(M13<85,IF(M13<80,"PLAIN","PLUS"),IF(M13<90,"MINUS",IF(M13<97,"PLAIN","PLUS"))))) -> PLAIN | Q13: ='All Marks'!H4 -> 39.7 | R13: =EQ(Q13,L13) -> TRUE
A14: 4 | B14: =Worksheet!A5 -> 22201706 | C14: =Worksheet!B5 -> Sadnan Basher | E14: =VLOOKUP(B14,'All Marks'!$A$3:$G$39,4,FALSE) -> 8.66 | F14: =VLOOKUP(B14,'All Marks'!$A$3:$G$40,3,FALSE) -> 3.75 | G14: =VLOOKUP(B14,'All Marks'!$A$3:$G$40,7,FALSE) -> 5 | H14: =VLOOKUP(B14,'All Marks'!$A$3:$G$40,5,FALSE) -> 2.9 | K14: =VLOOKUP(B14,'All Marks'!$A$3:$G$40,6,FALSE) -> 1.5 | L14: =SUM(E14:K14) -> 21.81 | M14: =IF(AND(L14>=96.5,L14<97),L14,ROUND(L14,0)) -> 22 | N14: =IF(M14<65,IF(M14<55,IF(M14<52,IF(M14<50,"F","D-"),"D"),IF(M14<57,"D+",IF(M14<60,"C-","C"))),IF(M14<75,IF(M14<70,"C+","B-"),IF(M14<85,IF(M14<80,"B","B+"),IF(M14<90,"A-",IF(M14<97,"A","A+"))))) -> F | O14: =IF(M14<65,IF(M14<55,IF(M14<52,IF(M14<50,"PLAIN","MINUS"),"PLAIN"),IF(M14<57,"PLUS",IF(M14<60,"MINUS","PLAIN"))),IF(M14<75,IF(M14<70,"PLUS","MINUS"),IF(M14<85,IF(M14<80,"PLAIN","PLUS"),IF(M14<90,"MINUS",IF(M14<97,"PLAIN","PLUS"))))) -> PLAIN | Q14: ='All Marks'!H5 -> 21.81 | R14: =EQ(Q14,L14) -> TRUE
A15: 5 | B15: =Worksheet!A6 -> 22301485 | C15: =Worksheet!B6 -> Tamal Kumar Dey | E15: =VLOOKUP(B15,'All Marks'!$A$3:$G$39,4,FALSE) -> 17.33 | F15: =VLOOKUP(B15,'All Marks'!$A$3:$G$40,3,FALSE) -> 5 | G15: =VLOOKUP(B15,'All Marks'!$A$3:$G$40,7,FALSE) -> 0.85 | H15: =VLOOKUP(B15,'All Marks'!$A$3:$G$40,5,FALSE) -> 8.9 | K15: =VLOOKUP(B15,'All Marks'!$A$3:$G$40,6,FALSE) -> 18 | L15: =SUM(E15:K15) -> 50.08 | M15: =IF(AND(L15>=96.5,L15<97),L15,ROUND(L15,0)) -> 50 | N15: =IF(M15<65,IF(M15<55,IF(M15<52,IF(M15<50,"F","D-"),"D"),IF(M15<57,"D+",IF(M15<60,"C-","C"))),IF(M15<75,IF(M15<70,"C+","B-"),IF(M15<85,IF(M15<80,"B","B+"),IF(M15<90,"A-",IF(M15<97,"A","A+"))))) -> D- | O15: =IF(M15<65,IF(M15<55,IF(M15<52,IF(M15<50,"PLAIN","MINUS"),"PLAIN"),IF(M15<57,"PLUS",IF(M15<60,"MINUS","PLAIN"))),IF(M15<75,IF(M15<70,"PLUS","MINUS"),IF(M15<85,IF(M15<80,"PLAIN","PLUS"),IF(M15<90,"MINUS",IF(M15<97,"PLAIN","PLUS"))))) -> MINUS | Q15: ='All Marks'!H6 -> 50.08 | R15: =EQ(Q15,L15) -> TRUE
A16: 6 | B16: =Worksheet!A7 -> 22301581 | C16: =Worksheet!B7 -> Rufaida Zoon Raiyan | E16: =VLOOKUP(B16,'All Marks'!$A$3:$G$39,4,FALSE) -> 13.66 | F16: =VLOOKUP(B16,'All Marks'!$A$3:$G$40,3,FALSE) -> 5 | G16: =VLOOKUP(B16,'All Marks'!$A$3:$G$40,7,FALSE) -> 0.67 | H16: =VLOOKUP(B16,'All Marks'!$A$3:$G$40,5,FALSE) -> 8.3 | K16: =VLOOKUP(B16,'All Marks'!$A$3:$G$40,6,FALSE) -> 22.9 | L16: =SUM(E16:K16) -> 50.53 | M16: =IF(AND(L16>=96.5,L16<97),L16,ROUND(L16,0)) -> 51 | N16: =IF(M16<65,IF(M16<55,IF(M16<52,IF(M16<50,"F","D-"),"D"),IF(M16<57,"D+",IF(M16<60,"C-","C"))),IF(M16<75,IF(M16<70,"C+","B-"),IF(M16<85,IF(M16<80,"B","B+"),IF(M16<90,"A-",IF(M16<97,"A","A+"))))) -> D- | O16: =IF(M16<65,IF(M16<55,IF(M16<52,IF(M16<50,"PLAIN","MINUS"),"PLAIN"),IF(M16<57,"PLUS",IF(M16<60,"MINUS","PLAIN"))),IF(M16<75,IF(M16<70,"PLUS","MINUS"),IF(M16<85,IF(M16<80,"PLAIN","PLUS"),IF(M16<90,"MINUS",IF(M16<97,"PLAIN","PLUS"))))) -> MINUS | Q16: ='All Marks'!H7 -> 50.53 | R16: =EQ(Q16,L16) -> TRUE
A17: 7 | B17: =Worksheet!A8 -> 23101152 | C17: =Worksheet!B8 -> Shihabul Ishraq Tanim | E17: =VLOOKUP(B17,'All Marks'!$A$3:$G$39,4,FALSE) -> 15.66 | F17: =VLOOKUP(B17,'All Marks'!$A$3:$G$40,3,FALSE) -> 5 | G17: =VLOOKUP(B17,'All Marks'!$A$3:$G$40,7,FALSE) -> 8.46 | H17: =VLOOKUP(B17,'All Marks'!$A$3:$G$40,5,FALSE) -> 7.5 | K17: =VLOOKUP(B17,'All Marks'!$A$3:$G$40,6,FALSE) -> 15 | L17: =SUM(E17:K17) -> 51.62 | M17: =IF(AND(L17>=96.5,L17<97),L17,ROUND(L17,0)) -> 52 | N17: =IF(M17<65,IF(M17<55,IF(M17<52,IF(M17<50,"F","D-"),"D"),IF(M17<57,"D+",IF(M17<60,"C-","C"))),IF(M17<75,IF(M17<70,"C+","B-"),IF(M17<85,IF(M17<80,"B","B+"),IF(M17<90,"A-",IF(M17<97,"A","A+"))))) -> D | O17: =IF(M17<65,IF(M17<55,IF(M17<52,IF(M17<50,"PLAIN","MINUS"),"PLAIN"),IF(M17<57,"PLUS",IF(M17<60,"MINUS","PLAIN"))),IF(M17<75,IF(M17<70,"PLUS","MINUS"),IF(M17<85,IF(M17<80,"PLAIN","PLUS"),IF(M17<90,"MINUS",IF(M17<97,"PLAIN","PLUS"))))) -> PLAIN | Q17: ='All Marks'!H8 -> 51.62 | R17: =EQ(Q17,L17) -> TRUE
A18: 8 | B18: =Worksheet!A9 -> 23101196 | C18: =Worksheet!B9 -> Nandini Das Jhumu | E18: =VLOOKUP(B18,'All Marks'!$A$3:$G$39,4,FALSE) -> 17.33 | F18: =VLOOKUP(B18,'All Marks'!$A$3:$G$40,3,FALSE) -> 5 | G18: =VLOOKUP(B18,'All Marks'!$A$3:$G$40,7,FALSE) -> 4.91 | H18: =VLOOKUP(B18,'All Marks'!$A$3:$G$40,5,FALSE) -> 11.5 | K18: =VLOOKUP(B18,'All Marks'!$A$3:$G$40,6,FALSE) -> 21 | L18: =SUM(E18:K18) -> 59.74 | M18: =IF(AND(L18>=96.5,L18<97),L18,ROUND(L18,0)) -> 60 | N18: =IF(M18<65,IF(M18<55,IF(M18<52,IF(M18<50,"F","D-"),"D"),IF(M18<57,"D+",IF(M18<60,"C-","C"))),IF(M18<75,IF(M18<70,"C+","B-"),IF(M18<85,IF(M18<80,"B","B+"),IF(M18<90,"A-",IF(M18<97,"A","A+"))))) -> C | O18: =IF(M18<65,IF(M18<55,IF(M18<52,IF(M18<50,"PLAIN","MINUS"),"PLAIN"),IF(M18<57,"PLUS",IF(M18<60,"MINUS","PLAIN"))),IF(M18<75,IF(M18<70,"PLUS","MINUS"),IF(M18<85,IF(M18<80,"PLAIN","PLUS"),IF(M18<90,"MINUS",IF(M18<97,"PLAIN","PLUS"))))) -> PLAIN | Q18: ='All Marks'!H9 -> 59.74 | R18: =EQ(Q18,L18) -> TRUE
A19: 9 | B19: =Worksheet!A10 -> 23201055 | C19: =Worksheet!B10 -> Ridwanul Azim | E19: =VLOOKUP(B19,'All Marks'!$A$3:$G$39,4,FALSE) -> 2 | F19: =VLOOKUP(B19,'All Marks'!$A$3:$G$40,3,FALSE) -> 0 | G19: =VLOOKUP(B19,'All Marks'!$A$3:$G$40,7,FALSE) -> 0 | H19: =VLOOKUP(B19,'All Marks'!$A$3:$G$40,5,FALSE) -> 0 | K19: =VLOOKUP(B19,'All Marks'!$A$3:$G$40,6,FALSE) -> 0 | L19: =SUM(E19:K19) -> 2 | M19: =IF(AND(L19>=96.5,L19<97),L19,ROUND(L19,0)) -> 2 | N19: =IF(M19<65,IF(M19<55,IF(M19<52,IF(M19<50,"F","D-"),"D"),IF(M19<57,"D+",IF(M19<60,"C-","C"))),IF(M19<75,IF(M19<70,"C+","B-"),IF(M19<85,IF(M19<80,"B","B+"),IF(M19<90,"A-",IF(M19<97,"A","A+"))))) -> F | O19: =IF(M19<65,IF(M19<55,IF(M19<52,IF(M19<50,"PLAIN","MINUS"),"PLAIN"),IF(M19<57,"PLUS",IF(M19<60,"MINUS","PLAIN"))),IF(M19<75,IF(M19<70,"PLUS","MINUS"),IF(M19<85,IF(M19<80,"PLAIN","PLUS"),IF(M19<90,"MINUS",IF(M19<97,"PLAIN","PLUS"))))) -> PLAIN | Q19: ='All Marks'!H10 -> 2 | R19: =EQ(Q19,L19) -> TRUE
A20: 10 | B20: =Worksheet!A11 -> 23301401 | C20: =Worksheet!B11 -> Saddat Hossain Sifat | E20: =VLOOKUP(B20,'All Marks'!$A$3:$G$39,4,FALSE) -> 19.33 | F20: =VLOOKUP(B20,'All Marks'!$A$3:$G$40,3,FALSE) -> 5 | G20: =VLOOKUP(B20,'All Marks'!$A$3:$G$40,7,FALSE) -> 21.29 | H20: =VLOOKUP(B20,'All Marks'!$A$3:$G$40,5,FALSE) -> 13.2 | K20: =VLOOKUP(B20,'All Marks'!$A$3:$G$40,6,FALSE) -> 27.8 | L20: =SUM(E20:K20) -> 86.62 | M20: =IF(AND(L20>=96.5,L20<97),L20,ROUND(L20,0)) -> 87 | N20: =IF(M20<65,IF(M20<55,IF(M20<52,IF(M20<50,"F","D-"),"D"),IF(M20<57,"D+",IF(M20<60,"C-","C"))),IF(M20<75,IF(M20<70,"C+","B-"),IF(M20<85,IF(M20<80,"B","B+"),IF(M20<90,"A-",IF(M20<97,"A","A+"))))) -> A- | O20: =IF(M20<65,IF(M20<55,IF(M20<52,IF(M20<50,"PLAIN","MINUS"),"PLAIN"),IF(M20<57,"PLUS",IF(M20<60,"MINUS","PLAIN"))),IF(M20<75,IF(M20<70,"PLUS","MINUS"),IF(M20<85,IF(M20<80,"PLAIN","PLUS"),IF(M20<90,"MINUS",IF(M20<97,"PLAIN","PLUS"))))) -> MINUS | Q20: ='All Marks'!H11 -> 86.62 | R20: =EQ(Q20,L20) -> TRUE
A21: 11 | B21: =Worksheet!A12 -> 24101043 | C21: =Worksheet!B12 -> Md Abu Noman Kabbo | E21: =VLOOKUP(B21,'All Marks'!$A$3:$G$39,4,FALSE) -> 5.33 | F21: =VLOOKUP(B21,'All Marks'!$A$3:$G$40,3,FALSE) -> 0 | G21: =VLOOKUP(B21,'All Marks'!$A$3:$G$40,7,FALSE) -> 4.09 | H21: =VLOOKUP(B21,'All Marks'!$A$3:$G$40,5,FALSE) -> 10.6 | K21: =VLOOKUP(B21,'All Marks'!$A$3:$G$40,6,FALSE) -> 0 | L21: =SUM(E21:K21) -> 20.02 | M21: =IF(AND(L21>=96.5,L21<97),L21,ROUND(L21,0)) -> 20 | N21: =IF(M21<65,IF(M21<55,IF(M21<52,IF(M21<50,"F","D-"),"D"),IF(M21<57,"D+",IF(M21<60,"C-","C"))),IF(M21<75,IF(M21<70,"C+","B-"),IF(M21<85,IF(M21<80,"B","B+"),IF(M21<90,"A-",IF(M21<97,"A","A+"))))) -> F | O21: =IF(M21<65,IF(M21<55,IF(M21<52,IF(M21<50,"PLAIN","MINUS"),"PLAIN"),IF(M21<57,"PLUS",IF(M21<60,"MINUS","PLAIN"))),IF(M21<75,IF(M21<70,"PLUS","MINUS"),IF(M21<85,IF(M21<80,"PLAIN","PLUS"),IF(M21<90,"MINUS",IF(M21<97,"PLAIN","PLUS"))))) -> PLAIN | Q21: ='All Marks'!H12 -> 20.02 | R21: =EQ(Q21,L21) -> TRUE
A22: 12 | B22: =Worksheet!A13 -> 24101081 | C22: =Worksheet!B13 -> Adil Abdullah Mahdi | E22: =VLOOKUP(B22,'All Marks'!$A$3:$G$39,4,FALSE) -> 17 | F22: =VLOOKUP(B22,'All Marks'!$A$3:$G$40,3,FALSE) -> 5 | G22: =VLOOKUP(B22,'All Marks'!$A$3:$G$40,7,FALSE) -> 2.84 | H22: =VLOOKUP(B22,'All Marks'!$A$3:$G$40,5,FALSE) -> 8.6 | K22: =VLOOKUP(B22,'All Marks'!$A$3:$G$40,6,FALSE) -> 23.3 | L22: =SUM(E22:K22) -> 56.74 | M22: =IF(AND(L22>=96.5,L22<97),L22,ROUND(L22,0)) -> 57 | N22: =IF(M22<65,IF(M22<55,IF(M22<52,IF(M22<50,"F","D-"),"D"),IF(M22<57,"D+",IF(M22<60,"C-","C"))),IF(M22<75,IF(M22<70,"C+","B-"),IF(M22<85,IF(M22<80,"B","B+"),IF(M22<90,"A-",IF(M22<97,"A","A+"))))) -> C- | O22: =IF(M22<65,IF(M22<55,IF(M22<52,IF(M22<50,"PLAIN","MINUS"),"PLAIN"),IF(M22<57,"PLUS",IF(M22<60,"MINUS","PLAIN"))),IF(M22<75,IF(M22<70,"PLUS","MINUS"),IF(M22<85,IF(M22<80,"PLAIN","PLUS"),IF(M22<90,"MINUS",IF(M22<97,"PLAIN","PLUS"))))) -> MINUS | Q22: ='All Marks'!H13 -> 56.74 | R22: =EQ(Q22,L22) -> TRUE
A23: 13 | B23: =Worksheet!A14 -> 24101103 | C23: =Worksheet!B14 -> Zunayed Amin | E23: =VLOOKUP(B23,'All Marks'!$A$3:$G$39,4,FALSE) -> 18.66 | F23: =VLOOKUP(B23,'All Marks'!$A$3:$G$40,3,FALSE) -> 5 | G23: =VLOOKUP(B23,'All Marks'!$A$3:$G$40,7,FALSE) -> 3.97 | H23: =VLOOKUP(B23,'All Marks'!$A$3:$G$40,5,FALSE) -> 7.8 | K23: =VLOOKUP(B23,'All Marks'!$A$3:$G$40,6,FALSE) -> 21.8 | L23: =SUM(E23:K23) -> 57.23 | M23: =IF(AND(L23>=96.5,L23<97),L23,ROUND(L23,0)) -> 57 | N23: =IF(M23<65,IF(M23<55,IF(M23<52,IF(M23<50,"F","D-"),"D"),IF(M23<57,"D+",IF(M23<60,"C-","C"))),IF(M23<75,IF(M23<70,"C+","B-"),IF(M23<85,IF(M23<80,"B","B+"),IF(M23<90,"A-",IF(M23<97,"A","A+"))))) -> C- | O23: =IF(M23<65,IF(M23<55,IF(M23<52,IF(M23<50,"PLAIN","MINUS"),"PLAIN"),IF(M23<57,"PLUS",IF(M23<60,"MINUS","PLAIN"))),IF(M23<75,IF(M23<70,"PLUS","MINUS"),IF(M23<85,IF(M23<80,"PLAIN","PLUS"),IF(M23<90,"MINUS",IF(M23<97,"PLAIN","PLUS"))))) -> MINUS | Q23: ='All Marks'!H14 -> 57.23 | R23: =EQ(Q23,L23) -> TRUE
... A47: 37 | B47: =Worksheet!A38 -> 24321222 | C47: =Worksheet!B38 -> Mir Mainul Ahmed | E47: =VLOOKUP(B47,'All Marks'!$A$3:$G$39,4,FALSE) -> 20 | F47: =VLOOKUP(B47,'All Marks'!$A$3:$G$40,3,FALSE) -> 5 | G47: =VLOOKUP(B47,'All Marks'!$A$3:$G$40,7,FALSE) -> 18.34 | H47: =VLOOKUP(B47,'All Marks'!$A$3:$G$40,5,FALSE) -> 11.8 | K47: =VLOOKUP(B47,'All Marks'!$A$3:$G$40,6,FALSE) -> 24.4 | L47: =SUM(E47:K47) -> 79.54 | M47: =IF(AND(L47>=96.5,L47<97),L47,ROUND(L47,0)) -> 80 | N47: =IF(M47<65,IF(M47<55,IF(M47<52,IF(M47<50,"F","D-"),"D"),IF(M47<57,"D+",IF(M47<60,"C-","C"))),IF(M47<75,IF(M47<70,"C+","B-"),IF(M47<85,IF(M47<80,"B","B+"),IF(M47<90,"A-",IF(M47<97,"A","A+"))))) -> B+ | O47: =IF(M47<65,IF(M47<55,IF(M47<52,IF(M47<50,"PLAIN","MINUS"),"PLAIN"),IF(M47<57,"PLUS",IF(M47<60,"MINUS","PLAIN"))),IF(M47<75,IF(M47<70,"PLUS","MINUS"),IF(M47<85,IF(M47<80,"PLAIN","PLUS"),IF(M47<90,"MINUS",IF(M47<97,"PLAIN","PLUS"))))) -> PLUS | Q47: ='All Marks'!H38 -> 79.54 | R47: =EQ(Q47,L47) -> TRUE
R48: =COUNTIF(R11:R47,"=TRUE") -> 37

Sheet All Marks
A1: Student ID | B1: Name | C1: =Assignment!G1 -> Assignment (out of 5) | D1: =Quiz!M1 -> Overall Quiz score (Out of 20) best (n-1) without bonus | E1: ='Mid+Final'!D2 -> Midterm (20) | F1: ='Mid+Final'!M2 -> Final(30) | G1: Lab (25) | H1: Total (out of 100)
A2: =Worksheet!A2 -> 22101165 | B2: =Worksheet!B2 -> Asif Mahmud | C2: =Assignment!G2 -> 0 | D2: =Quiz!M2 -> 15.66 | E2: ='Mid+Final'!D3 -> 12.3 | F2: ='Mid+Final'!M3 -> 19.9 | G2: =IFERROR(ROUNDUP(VLOOKUP(A2,Lab!$A$2:$B$39,2,False),2),0) -> 2.56 | H2: =RoundUp(sum(C2:G2),2) -> 50.42
A3: =Worksheet!A3 -> 22101192 | B3: =Worksheet!B3 -> Maliha Anan Promi | C3: =Assignment!G3 -> 5 | D3: =Quiz!M3 -> 13.33 | E3: ='Mid+Final'!D4 -> 8.9 | F3: ='Mid+Final'!M4 -> 9.8 | G3: =IFERROR(ROUNDUP(VLOOKUP(A3,Lab!$A$2:$B$39,2,False),2),0) -> 0.48 | H3: =RoundUp(sum(C3:G3),2) -> 37.51
A4: =Worksheet!A4 -> 22101297 | B4: =Worksheet!B4 -> Parthib Biswas | C4: =Assignment!G4 -> 3.75 | D4: =Quiz!M4 -> 9.33 | E4: ='Mid+Final'!D5 -> 7.5 | F4: ='Mid+Final'!M5 -> 14.3 | G4: =IFERROR(ROUNDUP(VLOOKUP(A4,Lab!$A$2:$B$39,2,False),2),0) -> 4.82 | H4: =RoundUp(sum(C4:G4),2) -> 39.7
A5: =Worksheet!A5 -> 22201706 | B5: =Worksheet!B5 -> Sadnan Basher | C5: =Assignment!G5 -> 3.75 | D5: =Quiz!M5 -> 8.66 | E5: ='Mid+Final'!D6 -> 2.9 | F5: ='Mid+Final'!M6 -> 1.5 | G5: =IFERROR(ROUNDUP(VLOOKUP(A5,Lab!$A$2:$B$39,2,False),2),0) -> 5 | H5: =RoundUp(sum(C5:G5),2) -> 21.81
A6: =Worksheet!A6 -> 22301485 | B6: =Worksheet!B6 -> Tamal Kumar Dey | C6: =Assignment!G6 -> 5 | D6: =Quiz!M6 -> 17.33 | E6: ='Mid+Final'!D7 -> 8.9 | F6: ='Mid+Final'!M7 -> 18 | G6: =IFERROR(ROUNDUP(VLOOKUP(A6,Lab!$A$2:$B$39,2,False),2),0) -> 0.85 | H6: =RoundUp(sum(C6:G6),2) -> 50.08
A7: =Worksheet!A7 -> 22301581 | B7: =Worksheet!B7 -> Rufaida Zoon Raiyan | C7: =Assignment!G7 -> 5 | D7: =Quiz!M7 -> 13.66 | E7: ='Mid+Final'!D8 -> 8.3 | F7: ='Mid+Final'!M8 -> 22.9 | G7: =IFERROR(ROUNDUP(VLOOKUP(A7,Lab!$A$2:$B$39,2,False),2),0) -> 0.67 | H7: =RoundUp(sum(C7:G7),2) -> 50.53
A8: =Worksheet!A8 -> 23101152 | B8: =Worksheet!B8 -> Shihabul Ishraq Tanim | C8: =Assignment!G8 -> 5 | D8: =Quiz!M8 -> 15.66 | E8: ='Mid+Final'!D9 -> 7.5 | F8: ='Mid+Final'!M9 -> 15 | G8: =IFERROR(ROUNDUP(VLOOKUP(A8,Lab!$A$2:$B$39,2,False),2),0) -> 8.46 | H8: =RoundUp(sum(C8:G8),2) -> 51.62
A9: =Worksheet!A9 -> 23101196 | B9: =Worksheet!B9 -> Nandini Das Jhumu | C9: =Assignment!G9 -> 5 | D9: =Quiz!M9 -> 17.33 | E9: ='Mid+Final'!D10 -> 11.5 | F9: ='Mid+Final'!M10 -> 21 | G9: =IFERROR(ROUNDUP(VLOOKUP(A9,Lab!$A$2:$B$39,2,False),2),0) -> 4.91 | H9: =RoundUp(sum(C9:G9),2) -> 59.74
A10: =Worksheet!A10 -> 23201055 | B10: =Worksheet!B10 -> Ridwanul Azim | C10: =Assignment!G10 -> 0 | D10: =Quiz!M10 -> 2 | E10: ='Mid+Final'!D11 -> 0 | F10: ='Mid+Final'!M11 -> 0 | G10: =IFERROR(ROUNDUP(VLOOKUP(A10,Lab!$A$2:$B$39,2,False),2),0) -> 0 | H10: =RoundUp(sum(C10:G10),2) -> 2
A11: =Worksheet!A11 -> 23301401 | B11: =Worksheet!B11 -> Saddat Hossain Sifat | C11: =Assignment!G11 -> 5 | D11: =Quiz!M11 -> 19.33 | E11: ='Mid+Final'!D12 -> 13.2 | F11: ='Mid+Final'!M12 -> 27.8 | G11: =IFERROR(ROUNDUP(VLOOKUP(A11,Lab!$A$2:$B$39,2,False),2),0) -> 21.29 | H11: =RoundUp(sum(C11:G11),2) -> 86.62
A12: =Worksheet!A12 -> 24101043 | B12: =Worksheet!B12 -> Md Abu Noman Kabbo | C12: =Assignment!G12 -> 0 | D12: =Quiz!M12 -> 5.33 | E12: ='Mid+Final'!D13 -> 10.6 | F12: ='Mid+Final'!M13 -> 0 | G12: =IFERROR(ROUNDUP(VLOOKUP(A12,Lab!$A$2:$B$39,2,False),2),0) -> 4.09 | H12: =RoundUp(sum(C12:G12),2) -> 20.02
A13: =Worksheet!A13 -> 24101081 | B13: =Worksheet!B13 -> Adil Abdullah Mahdi | C13: =Assignment!G13 -> 5 | D13: =Quiz!M13 -> 17 | E13: ='Mid+Final'!D14 -> 8.6 | F13: ='Mid+Final'!M14 -> 23.3 | G13: =IFERROR(ROUNDUP(VLOOKUP(A13,Lab!$A$2:$B$39,2,False),2),0) -> 2.84 | H13: =RoundUp(sum(C13:G13),2) -> 56.74
... A24: =Worksheet!A24 -> 24301202 | B24: =Worksheet!B24 -> Dibyo Singho Barua Subrajit | C24: =Assignment!G24 -> 5 | D24: =Quiz!M24 -> 16.66 | E24: ='Mid+Final'!D25 -> 8 | F24: ='Mid+Final'!M25 -> 22.9 | G24: =IFERROR(ROUNDUP(VLOOKUP(A24,Lab!$A$2:$B$39,2,False),2),0) -> 17.58 | H24: =RoundUp(sum(C24:G24),2) -> 70.14
A25: =Worksheet!A25 -> 24301306 | B25: =Worksheet!B25 -> Md Fahmudur Rahman Fahim | C25: =Assignment!G25 -> 5 | D25: 12 | E25: ='Mid+Final'!D26 -> 8.3 | F25: ='Mid+Final'!M26 -> 18.8 | G25: =IFERROR(ROUNDUP(VLOOKUP(A25,Lab!$A$2:$B$39,2,False),2),0) -> 6.78 | H25: =RoundUp(sum(C25:G25),2) -> 50.88
A26: =Worksheet!A26 -> 24301320 | B26: =Worksheet!B26 -> Md Rafi Hasan | C26: =Assignment!G26 -> 5 | D26: =Quiz!M26 -> 17.33 | E26: ='Mid+Final'!D27 -> 17.8 | F26: ='Mid+Final'!M27 -> 24.8 | G26: =IFERROR(ROUNDUP(VLOOKUP(A26,Lab!$A$2:$B$39,2,False),2),0) -> 25 | H26: =RoundUp(sum(C26:G26),2) -> 89.93
A27: =Worksheet!A27 -> 24301321 | B27: =Worksheet!B27 -> Nazif Ahmed Khan | C27: =Assignment!G27 -> 5 | D27: =Quiz!M27 -> 13.33 | E27: ='Mid+Final'!D28 -> 6.9 | F27: ='Mid+Final'!M28 -> 19.2 | G27: =IFERROR(ROUNDUP(VLOOKUP(A27,Lab!$A$2:$B$39,2,False),2),0) -> 17.96 | H27: =RoundUp(sum(C27:G27),2) -> 62.39
A28: =Worksheet!A28 -> 24301358 | B28: =Worksheet!B28 -> Multazim Nazifa | C28: =Assignment!G28 -> 5 | D28: =Quiz!M28 -> 20 | E28: ='Mid+Final'!D29 -> 15.5 | F28: ='Mid+Final'!M29 -> 26.7 | G28: =IFERROR(ROUNDUP(VLOOKUP(A28,Lab!$A$2:$B$39,2,False),2),0) -> 7.34 | H28: =RoundUp(sum(C28:G28),2) -> 74.54
A29: =Worksheet!A29 -> 24301367 | B29: =Worksheet!B29 -> Wazed Alam Wafi | C29: =Assignment!G29 -> 5 | D29: =Quiz!M29 -> 14.66 | E29: ='Mid+Final'!D30 -> 13.8 | F29: ='Mid+Final'!M30 -> 21 | G29: =IFERROR(ROUNDUP(VLOOKUP(A29,Lab!$A$2:$B$39,2,False),2),0) -> 5.25 | H29: =RoundUp(sum(C29:G29),2) -> 59.71
A30: =Worksheet!A30 -> 24301375 | B30: =Worksheet!B30 -> Mohammad Riham Alam | C30: =Assignment!G30 -> 5 | D30: =Quiz!M30 -> 15.33 | E30: ='Mid+Final'!D31 -> 10 | F30: ='Mid+Final'!M31 -> 25.2 | G30: =IFERROR(ROUNDUP(VLOOKUP(A30,Lab!$A$2:$B$39,2,False),2),0) -> 9.34 | H30: =RoundUp(sum(C30:G30),2) -> 64.87
A31: =Worksheet!A31 -> 24301420 | B31: =Worksheet!B31 -> Aronno Bless Rebeiro | C31: =Assignment!G31 -> 5 | D31: =Quiz!M31 -> 13.33 | E31: ='Mid+Final'!D32 -> 8.6 | F31: ='Mid+Final'!M32 -> 22.9 | G31: =IFERROR(ROUNDUP(VLOOKUP(A31,Lab!$A$2:$B$39,2,False),2),0) -> 5.24 | H31: =RoundUp(sum(C31:G31),2) -> 55.07
A32: =Worksheet!A32 -> 24301451 | B32: =Worksheet!B32 -> Sampurna Dey | C32: =Assignment!G32 -> 5 | D32: =Quiz!M32 -> 20 | E32: ='Mid+Final'!D33 -> 9.8 | F32: ='Mid+Final'!M33 -> 22.5 | G32: =IFERROR(ROUNDUP(VLOOKUP(A32,Lab!$A$2:$B$39,2,False),2),0) -> 5 | H32: =RoundUp(sum(C32:G32),2) -> 62.3
A33: =Worksheet!A33 -> 24301484 | B33: =Worksheet!B33 -> Md. Iftekhar Haque Iftee | C33: =Assignment!G33 -> 5 | D33: =Quiz!M33 -> 20 | E33: ='Mid+Final'!D34 -> 16 | F33: ='Mid+Final'!M34 -> 26.7 | G33: =IFERROR(ROUNDUP(VLOOKUP(A33,Lab!$A$2:$B$39,2,False),2),0) -> 17.16 | H33: =RoundUp(sum(C33:G33),2) -> 84.86
A34: =Worksheet!A34 -> 24301499 | B34: =Worksheet!B34 -> Zarifah Morshed Nuren | C34: =Assignment!G34 -> 5 | D34: =Quiz!M34 -> 20 | E34: ='Mid+Final'!D35 -> 13.5 | F34: ='Mid+Final'!M35 -> 26.3 | G34: =IFERROR(ROUNDUP(VLOOKUP(A34,Lab!$A$2:$B$39,2,False),2),0) -> 5 | H34: =RoundUp(sum(C34:G34),2) -> 69.8
A35: =Worksheet!A35 -> 24301519 | B35: =Worksheet!B35 -> Monira Mehjabeen Eva | C35: =Assignment!G35 -> 5 | D35: =Quiz!M35 -> 20 | E35: ='Mid+Final'!D36 -> 11.8 | F35: ='Mid+Final'!M36 -> 25.5 | G35: =IFERROR(ROUNDUP(VLOOKUP(A35,Lab!$A$2:$B$39,2,False),2),0) -> 5 | H35: =RoundUp(sum(C35:G35),2) -> 67.3
A36: =Worksheet!A36 -> 24301546 | B36: =Worksheet!B36 -> Manjurul Ahsan Hemel | C36: =Assignment!G36 -> 5 | D36: =Quiz!M36 -> 16.66 | E36: =ROUNDUP('Mid+Final'!D37,0) -> 5 | F36: =ROUNDUP('Mid+Final'!M37,0) -> 20 | G36: =IFERROR(ROUNDUP(VLOOKUP(A36,Lab!$A$2:$B$39,2,False),2),0) -> 3.65 | H36: =RoundUp(sum(C36:G36),2) -> 50.31
A37: =Worksheet!A37 -> 24315010 | B37: =Worksheet!B37 -> Saadat Khan | C37: =Assignment!G37 -> 5 | D37: =Quiz!M37 -> 14 | E37: ='Mid+Final'!D38 -> 9.2 | F37: ='Mid+Final'!M38 -> 16.5 | G37: =IFERROR(ROUNDUP(VLOOKUP(A37,Lab!$A$2:$B$39,2,False),2),0) -> 10.34 | H37: =RoundUp(sum(C37:G37),2) -> 55.04
A38: =Worksheet!A38 -> 24321222 | B38: =Worksheet!B38 -> Mir Mainul Ahmed | C38: =Assignment!G38 -> 5 | D38: =Quiz!M38 -> 20 | E38: ='Mid+Final'!D39 -> 11.8 | F38: ='Mid+Final'!M39 -> 24.4 | G38: =IFERROR(ROUNDUP(VLOOKUP(A38,Lab!$A$2:$B$39,2,False),2),0) -> 18.34 | H38: =RoundUp(sum(C38:G38),2) -> 79.54

Sheet Mid+Final
E1: CO2 | F1: CO1 | G1: CO2 | H1: CO2 | I1: CO1 | J1: CO3
A2: Student Id | C2: Midterm (35) | D2: Midterm (20) | E2: 1 a, b, c (10) | F2: 2 a,b,c (9) | G2: 2 d(1) | H2: 3 a, b(5) | I2: 4a(4) | J2: 4 b, c(6) | L2: Final out of 40 | M2: Final(30) | N2: 1 a,b,c,d CO1 Marks 10 | O2: 2 a, c CO1 Marks 6 | P2: 2 b CO3 Marks 2 | Q2: 2 d CO2 Marks 2 | R2: 3 a CO1 Marks 5 | S2: 3 b CO2 Marks 3 | T2: 3 c CO3 Marks 2 | U2: 4 CO1 marks 10
A3: =Worksheet!A2 -> 22101165 | B3: =Worksheet!B2 -> Asif Mahmud | C3: =SUM(E3:J3) -> 21.5 | D3: =roundup(SUM(E3:K3)/35*20,1) -> 12.3 | E3: 6 | F3: 7 | G3: 0 | H3: 0 | I3: 4 | J3: 4.5 | L3: =SUM(N3:U3) -> 26.5 | M3: =roundup(L3/40*30,1) -> 19.9 | N3: 9 | O3: 2 | P3: 1 | Q3: 0 | R3: 3.5 | S3: 1 | T3: 1 | U3: 9
A4: =Worksheet!A3 -> 22101192 | B4: =Worksheet!B3 -> Maliha Anan Promi | C4: =SUM(E4:J4) -> 15.5 | D4: =roundup(SUM(E4:K4)/35*20,1) -> 8.9 | E4: 3 | F4: 3 | G4: 0 | H4: 3 | I4: 3.5 | J4: 3 | L4: =SUM(N4:U4) -> 13 | M4: =roundup(L4/40*30,1) -> 9.8 | N4: 6 | O4: 3 | P4: 0 | Q4: 0 | R4: 0 | S4: 0 | T4: 0 | U4: 4
A5: =Worksheet!A4 -> 22101297 | B5: =Worksheet!B4 -> Parthib Biswas | C5: =SUM(E5:J5) -> 13 | D5: =roundup(SUM(E5:K5)/35*20,1) -> 7.5 | E5: 4 | F5: 5 | G5: 0 | H5: 0 | I5: 1 | J5: 3 | L5: =SUM(N5:U5) -> 19 | M5: =roundup(L5/40*30,1) -> 14.3 | N5: 5 | O5: 4 | P5: 2 | Q5: 1 | R5: 1 | S5: 1 | T5: 2 | U5: 3
A6: =Worksheet!A5 -> 22201706 | B6: =Worksheet!B5 -> Sadnan Basher | C6: =SUM(E6:J6) -> 5 | D6: =roundup(SUM(E6:K6)/35*20,1) -> 2.9 | E6: 1 | F6: 4 | G6: 0 | H6: 0 | I6: 0 | J6: 0 | L6: =SUM(N6:U6) -> 2 | M6: =roundup(L6/40*30,1) -> 1.5 | N6: 0 | O6: 2 | P6: 0 | Q6: 0 | R6: 0 | S6: 0 | T6: 0 | U6: 0
A7: =Worksheet!A6 -> 22301485 | B7: =Worksheet!B6 -> Tamal Kumar Dey | C7: =SUM(E7:J7) -> 15.5 | D7: =roundup(SUM(E7:K7)/35*20,1) -> 8.9 | E7: 4 | F7: 4 | G7: 0 | H7: 1 | I7: 3.5 | J7: 3 | L7: =SUM(N7:U7) -> 24 | M7: =roundup(L7/40*30,1) -> 18 | N7: 9 | O7: 3 | P7: 0 | Q7: 0 | R7: 4 | S7: 1 | T7: 0 | U7: 7
A8: =Worksheet!A7 -> 22301581 | B8: =Worksheet!B7 -> Rufaida Zoon Raiyan | C8: =SUM(E8:J8) -> 14.5 | D8: =roundup(SUM(E8:K8)/35*20,1) -> 8.3 | E8: 3 | F8: 4 | G8: 0 | H8: 0 | I8: 3 | J8: 4.5 | L8: =SUM(N8:U8) -> 30.5 | M8: =roundup(L8/40*30,1) -> 22.9 | N8: 8 | O8: 4 | P8: 2 | Q8: 1 | R8: 4 | S8: 2 | T8: 0 | U8: 9.5
A9: =Worksheet!A8 -> 23101152 | B9: =Worksheet!B8 -> Shihabul Ishraq Tanim | C9: =SUM(E9:J9) -> 13 | D9: =roundup(SUM(E9:K9)/35*20,1) -> 7.5 | E9: 1 | F9: 4 | G9: 0 | H9: 0 | I9: 4 | J9: 4 | L9: =SUM(N9:U9) -> 20 | M9: =roundup(L9/40*30,1) -> 15 | N9: 7 | O9: 3 | P9: 0 | Q9: 1 | R9: 2 | S9: 1 | T9: 0 | U9: 6
A10: =Worksheet!A9 -> 23101196 | B10: =Worksheet!B9 -> Nandini Das Jhumu | C10: =SUM(E10:J10) -> 20 | D10: =roundup(SUM(E10:K10)/35*20,1) -> 11.5 | E10: 5 | F10: 6 | G10: 0 | H10: 3 | I10: 3 | J10: 3 | L10: =SUM(N10:U10) -> 28 | M10: =roundup(L10/40*30,1) -> 21 | N10: 8 | O10: 5 | P10: 1 | Q10: 1 | R10: 5 | S10: 1.5 | T10: 2 | U10: 4.5
A11: =Worksheet!A10 -> 23201055 | B11: =Worksheet!B10 -> Ridwanul Azim | C11: =SUM(E11:J11) -> 0 | D11: =roundup(SUM(E11:K11)/35*20,1) -> 0 | E11: 0 | F11: 0 | G11: 0 | H11: 0 | I11: 0 | J11: 0 | L11: =SUM(N11:U11) -> 0 | M11: =roundup(L11/40*30,1) -> 0 | N11: 0 | O11: 0 | P11: 0 | Q11: 0 | R11: 0 | S11: 0 | T11: 0 | U11: 0
A12: =Worksheet!A11 -> 23301401 | B12: =Worksheet!B11 -> Saddat Hossain Sifat | C12: =SUM(E12:J12) -> 23 | D12: =roundup(SUM(E12:K12)/35*20,1) -> 13.2 | E12: 6 | F12: 7.5 | G12: 0.5 | H12: 2 | I12: 3 | J12: 4 | L12: =SUM(N12:U12) -> 37 | M12: =roundup(L12/40*30,1) -> 27.8 | N12: 9 | O12: 6 | P12: 2 | Q12: 2 | R12: 5 | S12: 1 | T12: 2 | U12: 10
A13: =Worksheet!A12 -> 24101043 | B13: =Worksheet!B12 -> Md Abu Noman Kabbo | C13: =SUM(E13:J13) -> 18.5 | D13: =roundup(SUM(E13:K13)/35*20,1) -> 10.6 | E13: 3 | F13: 6 | G13: 0 | H13: 3 | I13: 3.5 | J13: 3 | L13: =SUM(N13:U13) -> 0 | M13: =roundup(L13/40*30,1) -> 0
A14: =Worksheet!A13 -> 24101081 | B14: =Worksheet!B13 -> Adil Abdullah Mahdi | C14: =SUM(E14:J14) -> 15 | D14: =roundup(SUM(E14:K14)/35*20,1) -> 8.6 | E14: 6 | F14: 7 | G14: 0 | H14: 1 | I14: 1 | J14: 0 | L14: =SUM(N14:U14) -> 31 | M14: =roundup(L14/40*30,1) -> 23.3 | N14: 7 | O14: 3 | P14: 2 | Q14: 1 | R14: 5 | S14: 2 | T14: 2 | U14: 9
A15: =Worksheet!A14 -> 24101103 | B15: =Worksheet!B14 -> Zunayed Amin | C15: =SUM(E15:J15) -> 13.5 | D15: =roundup(SUM(E15:K15)/35*20,1) -> 7.8 | E15: 4 | F15: 4 | G15: 0 | H15: 1 | I15: 3 | J15: 1.5 | L15: =SUM(N15:U15) -> 29 | M15: =roundup(L15/40*30,1) -> 21.8 | N15: 8 | O15: 4 | P15: 1 | Q15: 0 | R15: 5 | S15: 1 | T15: 1 | U15: 9
A16: =Worksheet!A15 -> 24110031 | B16: =Worksheet!B15 -> Sm Mostofa Morshed Sayeem | C16: =SUM(E16:J16) -> 8 | D16: =roundup(SUM(E16:K16)/35*20,1) -> 4.6 | E16: 3 | F16: 4 | G16: 1 | H16: 0 | I16: 0 | J16: 0 | L16: =SUM(N16:U16) -> 0 | M16: =roundup(L16/40*30,1) -> 0
A17: =Worksheet!A16 -> 24201140 | B17: =Worksheet!B16 -> Mehrab Rashid Mugdha | C17: =SUM(E17:J17) -> 23.5 | D17: =roundup(SUM(E17:K17)/35*20,1) -> 13.5 | E17: 7.5 | F17: 6 | G17: 0 | H17: 4 | I17: 2 | J17: 4 | L17: =SUM(N17:U17) -> 37 | M17: =roundup(L17/40*30,1) -> 27.8 | N17: 9 | O17: 5.5 | P17: 2 | Q17: 2 | R17: 5 | S17: 2 | T17: 2 | U17: 9.5
A18: =Worksheet!A17 -> 24301023 | B18: =Worksheet!B17 -> Md Muhtasim Chowdhury | C18: =SUM(E18:J18) -> 18 | D18: =roundup(SUM(E18:K18)/35*20,1) -> 10.3 | E18: 5 | F18: 3 | G18: 0 | H18: 2 | I18: 4 | J18: 4 | L18: =SUM(N18:U18) -> 0 | M18: =roundup(L18/40*30,1) -> 0
A19: =Worksheet!A18 -> 24301062 | B19: =Worksheet!B18 -> Tahseen Zaman | C19: =SUM(E19:J19) -> 18 | D19: =roundup(SUM(E19:K19)/35*20,1) -> 10.3 | E19: 5 | F19: 5 | G19: 0 | H19: 2 | I19: 3 | J19: 3 | L19: =SUM(N19:U19) -> 16 | M19: =roundup(L19/40*30,1) -> 12 | O19: 4 | R19: 2 | S19: 1 | U19: 9
A20: =Worksheet!A19 -> 24301066 | B20: =Worksheet!B19 -> Lamia Iqbal | C20: =SUM(E20:J20) -> 25.5 | D20: =roundup(SUM(E20:K20)/35*20,1) -> 14.6 | E20: 9 | F20: 8.5 | G20: 0.5 | H20: 1 | I20: 3.5 | J20: 3 | L20: =SUM(N20:U20) -> 35.5 | M20: =roundup(L20/40*30,1) -> 26.7 | N20: 9 | O20: 6 | P20: 2 | Q20: 2 | R20: 3 | S20: 3 | T20: 1.5 | U20: 9
A21: =Worksheet!A20 -> 24301073 | B21: =Worksheet!B20 -> Rafid Bin Nasir | C21: =SUM(E21:J21) -> 24.5 | D21: =roundup(SUM(E21:K21)/35*20,1) -> 14 | E21: 6 | F21: 7 | G21: 0.5 | H21: 5 | I21: 2 | J21: 4 | L21: =SUM(N21:U21) -> 34.5 | M21: =roundup(L21/40*30,1) -> 25.9 | N21: 10 | O21: 5.5 | P21: 2 | Q21: 2 | R21: 5 | S21: 3 | T21: 1 | U21: 6
A22: =Worksheet!A21 -> 24301181 | B22: =Worksheet!B21 -> Md Mahi Hyder | C22: =SUM(E22:J22) -> 18 | D22: =roundup(SUM(E22:K22)/35*20,1) -> 10.3 | E22: 5 | F22: 7 | G22: 0 | H22: 1 | I22: 4 | J22: 1 | L22: =SUM(N22:U22) -> 35 | M22: =roundup(L22/40*30,1) -> 26.3 | N22: 10 | O22: 5.5 | P22: 2 | Q22: 0 | R22: 4 | S22: 2 | T22: 1.5 | U22: 10
A23: =Worksheet!A22 -> 24301184 | B23: =Worksheet!B22 -> Md. Abrar Faiyaz | C23: =SUM(E23:J23) -> 28.5 | D23: =roundup(SUM(E23:K23)/35*20,1) -> 16.3 | E23: 7.5 | F23: 9 | G23: 1 | H23: 4 | I23: 4 | J23: 3 | L23: =SUM(N23:U23) -> 35 | M23: =roundup(L23/40*30,1) -> 26.3 | N23: 9 | O23: 6 | P23: 2 | Q23: 0 | R23: 4 | S23: 3 | T23: 2 | U23: 9
A24: =Worksheet!A23 -> 24301192 | B24: =Worksheet!B23 -> Mashfiqur Rahman Khan | C24: =SUM(E24:J24) -> 13.5 | D24: =roundup(SUM(E24:K24)/35*20,1) -> 7.8 | E24: 2.5 | F24: 4 | G24: 1 | H24: 2 | I24: 2 | J24: 2 | L24: =SUM(N24:U24) -> 32.5 | M24: =roundup(L24/40*30,1) -> 24.4 | N24: 9 | O24: 5 | P24: 1 | Q24: 1 | R24: 5 | S24: 3 | T24: 2 | U24: 6.5
A25: =Worksheet!A24 -> 24301202 | B25: =Worksheet!B24 -> Dibyo Singho Barua Subrajit | C25: =SUM(E25:J25) -> 14 | D25: =roundup(SUM(E25:K25)/35*20,1) -> 8 | E25: 2 | F25: 4 | G25: 1 | H25: 0 | I25: 3 | J25: 4 | L25: =SUM(N25:U25) -> 30.5 | M25: =roundup(L25/40*30,1) -> 22.9 | N25: 8 | O25: 5.5 | P25: 2 | Q25: 0 | R25: 5 | S25: 2 | T25: 2 | U25: 6
A26: =Worksheet!A25 -> 24301306 | B26: =Worksheet!B25 -> Md Fahmudur Rahman Fahim | C26: =SUM(E26:J26) -> 14.5 | D26: =roundup(SUM(E26:K26)/35*20,1) -> 8.3 | E26: 3 | F26: 4.5 | G26: 0.5 | H26: 0 | I26: 3.5 | J26: 3 | L26: =SUM(N26:U26) -> 25 | M26: =roundup(L26/40*30,1) -> 18.8 | N26: 7 | O26: 3 | P26: 0 | Q26: 0 | R26: 4 | S26: 0 | T26: 2 | U26: 9
A27: =Worksheet!A26 -> 24301320 | B27: =Worksheet!B26 -> Md Rafi Hasan | C27: =SUM(E27:J27) -> 31 | D27: =roundup(SUM(E27:K27)/35*20,1) -> 17.8 | E27: 7.5 | F27: 9 | G27: 0.5 | H27: 5 | I27: 4 | J27: 5 | L27: =SUM(N27:U27) -> 33 | M27: =roundup(L27/40*30,1) -> 24.8 | N27: 9 | O27: 4 | P27: 1 | Q27: 1 | R27: 5 | S27: 2 | T27: 2 | U27: 9
A28: =Worksheet!A27 -> 24301321 | B28: =Worksheet!B27 -> Nazif Ahmed Khan | C28: =SUM(E28:J28) -> 12 | D28: =roundup(SUM(E28:K28)/35*20,1) -> 6.9 | E28: 4 | F28: 7 | G28: 0 | H28: 1 | I28: 0 | J28: 0 | L28: =SUM(N28:U28) -> 25.5 | M28: =roundup(L28/40*30,1) -> 19.2 | N28: 9 | O28: 2 | P28: 0 | Q28: 0 | R28: 5 | S28: 3 | T28: 0 | U28: 6.5
A29: =Worksheet!A28 -> 24301358 | B29: =Worksheet!B28 -> Multazim Nazifa | C29: =SUM(E29:J29) -> 27 | D29: =roundup(SUM(E29:K29)/35*20,1) -> 15.5 | E29: 8 | F29: 9 | G29: 0.5 | H29: 1 | I29: 3.5 | J29: 5 | L29: =SUM(N29:U29) -> 35.5 | M29: =roundup(L29/40*30,1) -> 26.7 | N29: 8 | O29: 6 | P29: 2 | Q29: 2 | R29: 5 | S29: 1.5 | T29: 2 | U29: 9
A30: =Worksheet!A29 -> 24301367 | B30: =Worksheet!B29 -> Wazed Alam Wafi | C30: =SUM(E30:J30) -> 24 | D30: =roundup(SUM(E30:K30)/35*20,1) -> 13.8 | E30: 7 | F30: 7 | G30: 1 | H30: 3 | I30: 3 | J30: 3 | L30: =SUM(N30:U30) -> 28 | M30: =roundup(L30/40*30,1) -> 21 | N30: 9 | O30: 6 | P30: 2 | Q30: 1.5 | R30: 3 | S30: 0 | T30: 0.5 | U30: 6
A31: =Worksheet!A30 -> 24301375 | B31: =Worksheet!B30 -> Mohammad Riham Alam | C31: =SUM(E31:J31) -> 17.5 | D31: =roundup(SUM(E31:K31)/35*20,1) -> 10 | E31: 7 | F31: 5 | G31: 0 | H31: 0 | I31: 2.5 | J31: 3 | L31: =SUM(N31:U31) -> 33.5 | M31: =roundup(L31/40*30,1) -> 25.2 | N31: 7 | O31: 6 | P31: 2 | Q31: 2 | R31: 4 | S31: 2 | T31: 2 | U31: 8.5
... A39: =Worksheet!A38 -> 24321222 | B39: =Worksheet!B38 -> Mir Mainul Ahmed | C39: =SUM(E39:J39) -> 20.5 | D39: =roundup(SUM(E39:K39)/35*20,1) -> 11.8 | E39: 7 | F39: 6 | G39: 0.5 | H39: 0 | I39: 4 | J39: 3 | L39: =SUM(N39:U39) -> 32.5 | M39: =roundup(L39/40*30,1) -> 24.4 | N39: 10 | O39: 5 | P39: 1 | Q39: 1 | R39: 3.5 | S39: 2 | T39: 2 | U39: 8
C40: =COUNTIF(C3:C39,">0") -> 36 | E40: CO2 | F40: CO1 | G40: CO2 | H40: CO2 | I40: CO1 | J40: CO3 | L40: =COUNTIF(L3:L39,">0") -> 33
E41: 1 a, b, c (10) | F41: 2 a,b,c (9) | G41: 2 d(1) | H41: 3 a, b(5) | I41: 4a(4) | J41: 4 b, c(6)

Sheet Quiz
A1: Student Id | C1: Quiz 1 (out of 10) | D1: Quiz 2 (out of 10) | E1: Quiz 3 (out of 10) | F1: Quiz 4 (out of 10) | G1: Quiz 1 (out of 10) | H1: Quiz 2 (out of 10) | I1: Quiz 3 (out of 10) | J1: Quiz 4 (out of 10) | K1: Bonus | L1: Overall Quiz score (Out of 20) best (n-1) with bonus | M1: Overall Quiz score (Out of 20) best (n-1) without bonus
A2: =Worksheet!A2 -> 22101165 | B2: =Worksheet!B2 -> Asif Mahmud | C2: 0 | D2: 5 | E2: 6 | F2: 15 | G2: =C2 -> 0 | H2: =D2 -> 5 | I2: =E2 -> 6 | J2: =if(F2<10,F2,10) -> 10 | K2: =if(F2>10,F2-10,0) -> 5 | L2: =if((SUMPRODUCT(LARGE(G2:J2,{1,2,3})))/3*2>20,20,TRUNC((SUMPRODUCT(LARGE(G2:J2,{1,2,3})))/3*2,2)) -> 14 | M2: =if((SUMPRODUCT(LARGE(G2:J2,{1,2,3}))+K2/2)/3*2>20,20,TRUNC((SUMPRODUCT(LARGE(G2:J2,{1,2,3}))+K2/2)/3*2,2)) -> 15.66
A3: =Worksheet!A3 -> 22101192 | B3: =Worksheet!B3 -> Maliha Anan Promi | C3: 5 | D3: 5 | E3: 6 | F3: 9 | G3: =C3 -> 5 | H3: =D3 -> 5 | I3: =E3 -> 6 | J3: =if(F3<10,F3,10) -> 9 | K3: =if(F3>10,F3-10,0) -> 0 | L3: =if((SUMPRODUCT(LARGE(G3:J3,{1,2,3})))/3*2>20,20,TRUNC((SUMPRODUCT(LARGE(G3:J3,{1,2,3})))/3*2,2)) -> 13.33 | M3: =if((SUMPRODUCT(LARGE(G3:J3,{1,2,3}))+K3/2)/3*2>20,20,TRUNC((SUMPRODUCT(LARGE(G3:J3,{1,2,3}))+K3/2)/3*2,2)) -> 13.33
A4: =Worksheet!A4 -> 22101297 | B4: =Worksheet!B4 -> Parthib Biswas | C4: 4 | D4: 7 | E4: 3 | F4: 0 | G4: =C4 -> 4 | H4: =D4 -> 7 | I4: =E4 -> 3 | J4: =if(F4<10,F4,10) -> 0 | K4: =if(F4>10,F4-10,0) -> 0 | L4: =if((SUMPRODUCT(LARGE(G4:J4,{1,2,3})))/3*2>20,20,TRUNC((SUMPRODUCT(LARGE(G4:J4,{1,2,3})))/3*2,2)) -> 9.33 | M4: =if((SUMPRODUCT(LARGE(G4:J4,{1,2,3}))+K4/2)/3*2>20,20,TRUNC((SUMPRODUCT(LARGE(G4:J4,{1,2,3}))+K4/2)/3*2,2)) -> 9.33
A5: =Worksheet!A5 -> 22201706 | B5: =Worksheet!B5 -> Sadnan Basher | C5: 5 | D5: 5 | E5: 3 | F5: 0 | G5: =C5 -> 5 | H5: =D5 -> 5 | I5: =E5 -> 3 | J5: =if(F5<10,F5,10) -> 0 | K5: =if(F5>10,F5-10,0) -> 0 | L5: =if((SUMPRODUCT(LARGE(G5:J5,{1,2,3})))/3*2>20,20,TRUNC((SUMPRODUCT(LARGE(G5:J5,{1,2,3})))/3*2,2)) -> 8.66 | M5: =if((SUMPRODUCT(LARGE(G5:J5,{1,2,3}))+K5/2)/3*2>20,20,TRUNC((SUMPRODUCT(LARGE(G5:J5,{1,2,3}))+K5/2)/3*2,2)) -> 8.66
A6: =Worksheet!A6 -> 22301485 | B6: =Worksheet!B6 -> Tamal Kumar Dey | C6: 0 | D6: 7 | E6: 9 | F6: 10 | G6: =C6 -> 0 | H6: =D6 -> 7 | I6: =E6 -> 9 | J6: =if(F6<10,F6,10) -> 10 | K6: =if(F6>10,F6-10,0) -> 0 | L6: =if((SUMPRODUCT(LARGE(G6:J6,{1,2,3})))/3*2>20,20,TRUNC((SUMPRODUCT(LARGE(G6:J6,{1,2,3})))/3*2,2)) -> 17.33 | M6: =if((SUMPRODUCT(LARGE(G6:J6,{1,2,3}))+K6/2)/3*2>20,20,TRUNC((SUMPRODUCT(LARGE(G6:J6,{1,2,3}))+K6/2)/3*2,2)) -> 17.33
A7: =Worksheet!A7 -> 22301581 | B7: =Worksheet!B7 -> Rufaida Zoon Raiyan | C7: 0 | D7: 8 | E7: 0 | F7: 15 | G7: =C7 -> 0 | H7: =D7 -> 8 | I7: =E7 -> 0 | J7: =if(F7<10,F7,10) -> 10 | K7: =if(F7>10,F7-10,0) -> 5 | L7: =if((SUMPRODUCT(LARGE(G7:J7,{1,2,3})))/3*2>20,20,TRUNC((SUMPRODUCT(LARGE(G7:J7,{1,2,3})))/3*2,2)) -> 12 | M7: =if((SUMPRODUCT(LARGE(G7:J7,{1,2,3}))+K7/2)/3*2>20,20,TRUNC((SUMPRODUCT(LARGE(G7:J7,{1,2,3}))+K7/2)/3*2,2)) -> 13.66
A8: =Worksheet!A8 -> 23101152 | B8: =Worksheet!B8 -> Shihabul Ishraq Tanim | C8: 2 | D8: 5 | E8: 7 | F8: 13 | G8: =C8 -> 2 | H8: =D8 -> 5 | I8: =E8 -> 7 | J8: =if(F8<10,F8,10) -> 10 | K8: =if(F8>10,F8-10,0) -> 3 | L8: =if((SUMPRODUCT(LARGE(G8:J8,{1,2,3})))/3*2>20,20,TRUNC((SUMPRODUCT(LARGE(G8:J8,{1,2,3})))/3*2,2)) -> 14.66 | M8: =if((SUMPRODUCT(LARGE(G8:J8,{1,2,3}))+K8/2)/3*2>20,20,TRUNC((SUMPRODUCT(LARGE(G8:J8,{1,2,3}))+K8/2)/3*2,2)) -> 15.66
A9: =Worksheet!A9 -> 23101196 | B9: =Worksheet!B9 -> Nandini Das Jhumu | C9: 8 | D9: 5 | E9: 8 | F9: 10 | G9: =C9 -> 8 | H9: =D9 -> 5 | I9: =E9 -> 8 | J9: =if(F9<10,F9,10) -> 10 | K9: =if(F9>10,F9-10,0) -> 0 | L9: =if((SUMPRODUCT(LARGE(G9:J9,{1,2,3})))/3*2>20,20,TRUNC((SUMPRODUCT(LARGE(G9:J9,{1,2,3})))/3*2,2)) -> 17.33 | M9: =if((SUMPRODUCT(LARGE(G9:J9,{1,2,3}))+K9/2)/3*2>20,20,TRUNC((SUMPRODUCT(LARGE(G9:J9,{1,2,3}))+K9/2)/3*2,2)) -> 17.33
A10: =Worksheet!A10 -> 23201055 | B10: =Worksheet!B10 -> Ridwanul Azim | C10: 0 | D10: 3 | E10: 0 | F10: 0 | G10: =C10 -> 0 | H10: =D10 -> 3 | I10: =E10 -> 0 | J10: =if(F10<10,F10,10) -> 0 | K10: =if(F10>10,F10-10,0) -> 0 | L10: =if((SUMPRODUCT(LARGE(G10:J10,{1,2,3})))/3*2>20,20,TRUNC((SUMPRODUCT(LARGE(G10:J10,{1,2,3})))/3*2,2)) -> 2 | M10: =if((SUMPRODUCT(LARGE(G10:J10,{1,2,3}))+K10/2)/3*2>20,20,TRUNC((SUMPRODUCT(LARGE(G10:J10,{1,2,3}))+K10/2)/3*2,2)) -> 2
A11: =Worksheet!A11 -> 23301401 | B11: =Worksheet!B11 -> Saddat Hossain Sifat | C11: 8 | D11: 10 | E11: 7 | F11: 12 | G11: =C11 -> 8 | H11: =D11 -> 10 | I11: =E11 -> 7 | J11: =if(F11<10,F11,10) -> 10 | K11: =if(F11>10,F11-10,0) -> 2 | L11: =if((SUMPRODUCT(LARGE(G11:J11,{1,2,3})))/3*2>20,20,TRUNC((SUMPRODUCT(LARGE(G11:J11,{1,2,3})))/3*2,2)) -> 18.66 | M11: =if((SUMPRODUCT(LARGE(G11:J11,{1,2,3}))+K11/2)/3*2>20,20,TRUNC((SUMPRODUCT(LARGE(G11:J11,{1,2,3}))+K11/2)/3*2,2)) -> 19.33
A12: =Worksheet!A12 -> 24101043 | B12: =Worksheet!B12 -> Md Abu Noman Kabbo | C12: 0 | D12: 5 | E12: 3 | G12: =C12 -> 0 | H12: =D12 -> 5 | I12: =E12 -> 3 | J12: =if(F12<10,F12,10) | K12: =if(F12>10,F12-10,0) -> 0 | L12: =if((SUMPRODUCT(LARGE(G12:J12,{1,2,3})))/3*2>20,20,TRUNC((SUMPRODUCT(LARGE(G12:J12,{1,2,3})))/3*2,2)) -> 5.33 | M12: =if((SUMPRODUCT(LARGE(G12:J12,{1,2,3}))+K12/2)/3*2>20,20,TRUNC((SUMPRODUCT(LARGE(G12:J12,{1,2,3}))+K12/2)/3*2,2)) -> 5.33
A13: =Worksheet!A13 -> 24101081 | B13: =Worksheet!B13 -> Adil Abdullah Mahdi | C13: 9.5 | D13: 5 | E13: 6 | F13: 10 | G13: =C13 -> 9.5 | H13: =D13 -> 5 | I13: =E13 -> 6 | J13: =if(F13<10,F13,10) -> 10 | K13: =if(F13>10,F13-10,0) -> 0 | L13: =if((SUMPRODUCT(LARGE(G13:J13,{1,2,3})))/3*2>20,20,TRUNC((SUMPRODUCT(LARGE(G13:J13,{1,2,3})))/3*2,2)) -> 17 | M13: =if((SUMPRODUCT(LARGE(G13:J13,{1,2,3}))+K13/2)/3*2>20,20,TRUNC((SUMPRODUCT(LARGE(G13:J13,{1,2,3}))+K13/2)/3*2,2)) -> 17
A14: =Worksheet!A14 -> 24101103 | B14: =Worksheet!B14 -> Zunayed Amin | C14: 5.5 | D14: 10 | E14: 8 | F14: 10 | G14: =C14 -> 5.5 | H14: =D14 -> 10 | I14: =E14 -> 8 | J14: =if(F14<10,F14,10) -> 10 | K14: =if(F14>10,F14-10,0) -> 0 | L14: =if((SUMPRODUCT(LARGE(G14:J14,{1,2,3})))/3*2>20,20,TRUNC((SUMPRODUCT(LARGE(G14:J14,{1,2,3})))/3*2,2)) -> 18.66 | M14: =if((SUMPRODUCT(LARGE(G14:J14,{1,2,3}))+K14/2)/3*2>20,20,TRUNC((SUMPRODUCT(LARGE(G14:J14,{1,2,3}))+K14/2)/3*2,2)) -> 18.66
A15: =Worksheet!A15 -> 24110031 | B15: =Worksheet!B15 -> Sm Mostofa Morshed Sayeem | C15: 3 | D15: 0 | E15: 0 | F15: 0 | G15: =C15 -> 3 | H15: =D15 -> 0 | I15: =E15 -> 0 | J15: =if(F15<10,F15,10) -> 0 | K15: =if(F15>10,F15-10,0) -> 0 | L15: =if((SUMPRODUCT(LARGE(G15:J15,{1,2,3})))/3*2>20,20,TRUNC((SUMPRODUCT(LARGE(G15:J15,{1,2,3})))/3*2,2)) -> 2 | M15: =if((SUMPRODUCT(LARGE(G15:J15,{1,2,3}))+K15/2)/3*2>20,20,TRUNC((SUMPRODUCT(LARGE(G15:J15,{1,2,3}))+K15/2)/3*2,2)) -> 2
A16: =Worksheet!A16 -> 24201140 | B16: =Worksheet!B16 -> Mehrab Rashid Mugdha | C16: 8 | D16: 10 | E16: 10 | F16: 12 | G16: =C16 -> 8 | H16: =D16 -> 10 | I16: =E16 -> 10 | J16: =if(F16<10,F16,10) -> 10 | K16: =if(F16>10,F16-10,0) -> 2 | L16: =if((SUMPRODUCT(LARGE(G16:J16,{1,2,3})))/3*2>20,20,TRUNC((SUMPRODUCT(LARGE(G16:J16,{1,2,3})))/3*2,2)) -> 20 | M16: =if((SUMPRODUCT(LARGE(G16:J16,{1,2,3}))+K16/2)/3*2>20,20,TRUNC((SUMPRODUCT(LARGE(G16:J16,{1,2,3}))+K16/2)/3*2,2)) -> 20
A17: =Worksheet!A17 -> 24301023 | B17: =Worksheet!B17 -> Md Muhtasim Chowdhury | C17: 6 | D17: 5 | E17: 0 | G17: =C17 -> 6 | H17: =D17 -> 5 | I17: =E17 -> 0 | J17: =if(F17<10,F17,10) | K17: =if(F17>10,F17-10,0) -> 0 | L17: =if((SUMPRODUCT(LARGE(G17:J17,{1,2,3})))/3*2>20,20,TRUNC((SUMPRODUCT(LARGE(G17:J17,{1,2,3})))/3*2,2)) -> 7.33 | M17: =if((SUMPRODUCT(LARGE(G17:J17,{1,2,3}))+K17/2)/3*2>20,20,TRUNC((SUMPRODUCT(LARGE(G17:J17,{1,2,3}))+K17/2)/3*2,2)) -> 7.33
A18: =Worksheet!A18 -> 24301062 | B18: =Worksheet!B18 -> Tahseen Zaman | C18: 9.5 | D18: 10 | E18: 9 | G18: =C18 -> 9.5 | H18: =D18 -> 10 | I18: =E18 -> 9 | J18: =if(F18<10,F18,10) | K18: =if(F18>10,F18-10,0) -> 0 | L18: =if((SUMPRODUCT(LARGE(G18:J18,{1,2,3})))/3*2>20,20,TRUNC((SUMPRODUCT(LARGE(G18:J18,{1,2,3})))/3*2,2)) -> 19 | M18: =if((SUMPRODUCT(LARGE(G18:J18,{1,2,3}))+K18/2)/3*2>20,20,TRUNC((SUMPRODUCT(LARGE(G18:J18,{1,2,3}))+K18/2)/3*2,2)) -> 19
A19: =Worksheet!A19 -> 24301066 | B19: =Worksheet!B19 -> Lamia Iqbal | C19: 5.5 | D19: 10 | E19: 10 | F19: 12 | G19: =C19 -> 5.5 | H19: =D19 -> 10 | I19: =E19 -> 10 | J19: =if(F19<10,F19,10) -> 10 | K19: =if(F19>10,F19-10,0) -> 2 | L19: =if((SUMPRODUCT(LARGE(G19:J19,{1,2,3})))/3*2>20,20,TRUNC((SUMPRODUCT(LARGE(G19:J19,{1,2,3})))/3*2,2)) -> 20 | M19: =if((SUMPRODUCT(LARGE(G19:J19,{1,2,3}))+K19/2)/3*2>20,20,TRUNC((SUMPRODUCT(LARGE(G19:J19,{1,2,3}))+K19/2)/3*2,2)) -> 20
A20: =Worksheet!A20 -> 24301073 | B20: =Worksheet!B20 -> Rafid Bin Nasir | C20: 5 | D20: 5 | E20: 10 | F20: 14 | G20: =C20 -> 5 | H20: =D20 -> 5 | I20: =E20 -> 10 | J20: =if(F20<10,F20,10) -> 10 | K20: =if(F20>10,F20-10,0) -> 4 | L20: =if((SUMPRODUCT(LARGE(G20:J20,{1,2,3})))/3*2>20,20,TRUNC((SUMPRODUCT(LARGE(G20:J20,{1,2,3})))/3*2,2)) -> 16.66 | M20: =if((SUMPRODUCT(LARGE(G20:J20,{1,2,3}))+K20/2)/3*2>20,20,TRUNC((SUMPRODUCT(LARGE(G20:J20,{1,2,3}))+K20/2)/3*2,2)) -> 18
A21: =Worksheet!A21 -> 24301181 | B21: =Worksheet!B21 -> Md Mahi Hyder | C21: 6 | D21: 5 | E21: 6 | F21: 10 | G21: =C21 -> 6 | H21: =D21 -> 5 | I21: =E21 -> 6 | J21: =if(F21<10,F21,10) -> 10 | K21: =if(F21>10,F21-10,0) -> 0 | L21: =if((SUMPRODUCT(LARGE(G21:J21,{1,2,3})))/3*2>20,20,TRUNC((SUMPRODUCT(LARGE(G21:J21,{1,2,3})))/3*2,2)) -> 14.66 | M21: =if((SUMPRODUCT(LARGE(G21:J21,{1,2,3}))+K21/2)/3*2>20,20,TRUNC((SUMPRODUCT(LARGE(G21:J21,{1,2,3}))+K21/2)/3*2,2)) -> 14.66
A22: =Worksheet!A22 -> 24301184 | B22: =Worksheet!B22 -> Md. Abrar Faiyaz | C22: 10 | D22: 10 | E22: 10 | F22: 16 | G22: =C22 -> 10 | H22: =D22 -> 10 | I22: =E22 -> 10 | J22: =if(F22<10,F22,10) -> 10 | K22: =if(F22>10,F22-10,0) -> 6 | L22: =if((SUMPRODUCT(LARGE(G22:J22,{1,2,3})))/3*2>20,20,TRUNC((SUMPRODUCT(LARGE(G22:J22,{1,2,3})))/3*2,2)) -> 20 | M22: =if((SUMPRODUCT(LARGE(G22:J22,{1,2,3}))+K22/2)/3*2>20,20,TRUNC((SUMPRODUCT(LARGE(G22:J22,{1,2,3}))+K22/2)/3*2,2)) -> 20
A23: =Worksheet!A23 -> 24301192 | B23: =Worksheet!B23 -> Mashfiqur Rahman Khan | C23: 6.5 | D23: 10 | E23: 10 | F23: 15 | G23: =C23 -> 6.5 | H23: =D23 -> 10 | I23: =E23 -> 10 | J23: =if(F23<10,F23,10) -> 10 | K23: =if(F23>10,F23-10,0) -> 5 | L23: =if((SUMPRODUCT(LARGE(G23:J23,{1,2,3})))/3*2>20,20,TRUNC((SUMPRODUCT(LARGE(G23:J23,{1,2,3})))/3*2,2)) -> 20 | M23: =if((SUMPRODUCT(LARGE(G23:J23,{1,2,3}))+K23/2)/3*2>20,20,TRUNC((SUMPRODUCT(LARGE(G23:J23,{1,2,3}))+K23/2)/3*2,2)) -> 20
A24: =Worksheet!A24 -> 24301202 | B24: =Worksheet!B24 -> Dibyo Singho Barua Subrajit | C24: 6 | D24: 5 | E24: 7 | F24: 14 | G24: =C24 -> 6 | H24: =D24 -> 5 | I24: =E24 -> 7 | J24: =if(F24<10,F24,10) -> 10 | K24: =if(F24>10,F24-10,0) -> 4 | L24: =if((SUMPRODUCT(LARGE(G24:J24,{1,2,3})))/3*2>20,20,TRUNC((SUMPRODUCT(LARGE(G24:J24,{1,2,3})))/3*2,2)) -> 15.33 | M24: =if((SUMPRODUCT(LARGE(G24:J24,{1,2,3}))+K24/2)/3*2>20,20,TRUNC((SUMPRODUCT(LARGE(G24:J24,{1,2,3}))+K24/2)/3*2,2)) -> 16.66
A25: =Worksheet!A25 -> 24301306 | B25: =Worksheet!B25 -> Md Fahmudur Rahman Fahim | C25: 9 | D25: 3 | E25: 3 | F25: 8 | G25: =C25 -> 9 | H25: =D25 -> 3 | I25: =E25 -> 3 | J25: =if(F25<10,F25,10) -> 8 | K25: =if(F25>10,F25-10,0) -> 0 | L25: =if((SUMPRODUCT(LARGE(G25:J25,{1,2,3})))/3*2>20,20,TRUNC((SUMPRODUCT(LARGE(G25:J25,{1,2,3})))/3*2,2)) -> 13.33 | M25: =if((SUMPRODUCT(LARGE(G25:J25,{1,2,3}))+K25/2)/3*2>20,20,TRUNC((SUMPRODUCT(LARGE(G25:J25,{1,2,3}))+K25/2)/3*2,2)) -> 13.33
A26: =Worksheet!A26 -> 24301320 | B26: =Worksheet!B26 -> Md Rafi Hasan | C26: 9 | D26: 10 | E26: 3 | F26: 7 | G26: =C26 -> 9 | H26: =D26 -> 10 | I26: =E26 -> 3 | J26: =if(F26<10,F26,10) -> 7 | K26: =if(F26>10,F26-10,0) -> 0 | L26: =if((SUMPRODUCT(LARGE(G26:J26,{1,2,3})))/3*2>20,20,TRUNC((SUMPRODUCT(LARGE(G26:J26,{1,2,3})))/3*2,2)) -> 17.33 | M26: =if((SUMPRODUCT(LARGE(G26:J26,{1,2,3}))+K26/2)/3*2>20,20,TRUNC((SUMPRODUCT(LARGE(G26:J26,{1,2,3}))+K26/2)/3*2,2)) -> 17.33
A27: =Worksheet!A27 -> 24301321 | B27: =Worksheet!B27 -> Nazif Ahmed Khan | C27: 6 | D27: 6 | E27: 3 | F27: 8 | G27: =C27 -> 6 | H27: =D27 -> 6 | I27: =E27 -> 3 | J27: =if(F27<10,F27,10) -> 8 | K27: =if(F27>10,F27-10,0) -> 0 | L27: =if((SUMPRODUCT(LARGE(G27:J27,{1,2,3})))/3*2>20,20,TRUNC((SUMPRODUCT(LARGE(G27:J27,{1,2,3})))/3*2,2)) -> 13.33 | M27: =if((SUMPRODUCT(LARGE(G27:J27,{1,2,3}))+K27/2)/3*2>20,20,TRUNC((SUMPRODUCT(LARGE(G27:J27,{1,2,3}))+K27/2)/3*2,2)) -> 13.33
A28: =Worksheet!A28 -> 24301358 | B28: =Worksheet!B28 -> Multazim Nazifa | C28: 6.5 | D28: 10 | E28: 10 | F28: 10 | G28: =C28 -> 6.5 | H28: =D28 -> 10 | I28: =E28 -> 10 | J28: =if(F28<10,F28,10) -> 10 | K28: =if(F28>10,F28-10,0) -> 0 | L28: =if((SUMPRODUCT(LARGE(G28:J28,{1,2,3})))/3*2>20,20,TRUNC((SUMPRODUCT(LARGE(G28:J28,{1,2,3})))/3*2,2)) -> 20 | M28: =if((SUMPRODUCT(LARGE(G28:J28,{1,2,3}))+K28/2)/3*2>20,20,TRUNC((SUMPRODUCT(LARGE(G28:J28,{1,2,3}))+K28/2)/3*2,2)) -> 20
A29: =Worksheet!A29 -> 24301367 | B29: =Worksheet!B29 -> Wazed Alam Wafi | C29: 10 | D29: 9 | E29: 3 | G29: =C29 -> 10 | H29: =D29 -> 9 | I29: =E29 -> 3 | J29: =if(F29<10,F29,10) | K29: =if(F29>10,F29-10,0) -> 0 | L29: =if((SUMPRODUCT(LARGE(G29:J29,{1,2,3})))/3*2>20,20,TRUNC((SUMPRODUCT(LARGE(G29:J29,{1,2,3})))/3*2,2)) -> 14.66 | M29: =if((SUMPRODUCT(LARGE(G29:J29,{1,2,3}))+K29/2)/3*2>20,20,TRUNC((SUMPRODUCT(LARGE(G29:J29,{1,2,3}))+K29/2)/3*2,2)) -> 14.66
A30: =Worksheet!A30 -> 24301375 | B30: =Worksheet!B30 -> Mohammad Riham Alam | C30: 8 | D30: 5 | E30: 3 | F30: 10 | G30: =C30 -> 8 | H30: =D30 -> 5 | I30: =E30 -> 3 | J30: =if(F30<10,F30,10) -> 10 | K30: =if(F30>10,F30-10,0) -> 0 | L30: =if((SUMPRODUCT(LARGE(G30:J30,{1,2,3})))/3*2>20,20,TRUNC((SUMPRODUCT(LARGE(G30:J30,{1,2,3})))/3*2,2)) -> 15.33 | M30: =if((SUMPRODUCT(LARGE(G30:J30,{1,2,3}))+K30/2)/3*2>20,20,TRUNC((SUMPRODUCT(LARGE(G30:J30,{1,2,3}))+K30/2)/3*2,2)) -> 15.33
A31: =Worksheet!A31 -> 24301420 | B31: =Worksheet!B31 -> Aronno Bless Rebeiro | C31: 0 | D31: 9 | E31: 3 | F31: 8 | G31: =C31 -> 0 | H31: =D31 -> 9 | I31: =E31 -> 3 | J31: =if(F31<10,F31,10) -> 8 | K31: =if(F31>10,F31-10,0) -> 0 | L31: =if((SUMPRODUCT(LARGE(G31:J31,{1,2,3})))/3*2>20,20,TRUNC((SUMPRODUCT(LARGE(G31:J31,{1,2,3})))/3*2,2)) -> 13.33 | M31: =if((SUMPRODUCT(LARGE(G31:J31,{1,2,3}))+K31/2)/3*2>20,20,TRUNC((SUMPRODUCT(LARGE(G31:J31,{1,2,3}))+K31/2)/3*2,2)) -> 13.33
A32: =Worksheet!A32 -> 24301451 | B32: =Worksheet!B32 -> Sampurna Dey | C32: 9 | D32: 10 | E32: 10 | F32: 12 | G32: =C32 -> 9 | H32: =D32 -> 10 | I32: =E32 -> 10 | J32: =if(F32<10,F32,10) -> 10 | K32: =if(F32>10,F32-10,0) -> 2 | L32: =if((SUMPRODUCT(LARGE(G32:J32,{1,2,3})))/3*2>20,20,TRUNC((SUMPRODUCT(LARGE(G32:J32,{1,2,3})))/3*2,2)) -> 20 | M32: =if((SUMPRODUCT(LARGE(G32:J32,{1,2,3}))+K32/2)/3*2>20,20,TRUNC((SUMPRODUCT(LARGE(G32:J32,{1,2,3}))+K32/2)/3*2,2)) -> 20
A33: =Worksheet!A33 -> 24301484 | B33: =Worksheet!B33 -> Md. Iftekhar Haque Iftee | C33: 4.5 | D33: 9 | E33: 10 | F33: 12 | G33: =C33 -> 4.5 | H33: =D33 -> 9 | I33: =E33 -> 10 | J33: =if(F33<10,F33,10) -> 10 | K33: =if(F33>10,F33-10,0) -> 2 | L33: =if((SUMPRODUCT(LARGE(G33:J33,{1,2,3})))/3*2>20,20,TRUNC((SUMPRODUCT(LARGE(G33:J33,{1,2,3})))/3*2,2)) -> 19.33 | M33: =if((SUMPRODUCT(LARGE(G33:J33,{1,2,3}))+K33/2)/3*2>20,20,TRUNC((SUMPRODUCT(LARGE(G33:J33,{1,2,3}))+K33/2)/3*2,2)) -> 20
A34: =Worksheet!A34 -> 24301499 | B34: =Worksheet!B34 -> Zarifah Morshed Nuren | C34: 5 | D34: 10 | E34: 10 | F34: 14 | G34: =C34 -> 5 | H34: =D34 -> 10 | I34: =E34 -> 10 | J34: =if(F34<10,F34,10) -> 10 | K34: =if(F34>10,F34-10,0) -> 4 | L34: =if((SUMPRODUCT(LARGE(G34:J34,{1,2,3})))/3*2>20,20,TRUNC((SUMPRODUCT(LARGE(G34:J34,{1,2,3})))/3*2,2)) -> 20 | M34: =if((SUMPRODUCT(LARGE(G34:J34,{1,2,3}))+K34/2)/3*2>20,20,TRUNC((SUMPRODUCT(LARGE(G34:J34,{1,2,3}))+K34/2)/3*2,2)) -> 20
A35: =Worksheet!A35 -> 24301519 | B35: =Worksheet!B35 -> Monira Mehjabeen Eva | C35: 9.5 | D35: 10 | E35: 10 | F35: 14 | G35: =C35 -> 9.5 | H35: =D35 -> 10 | I35: =E35 -> 10 | J35: =if(F35<10,F35,10) -> 10 | K35: =if(F35>10,F35-10,0) -> 4 | L35: =if((SUMPRODUCT(LARGE(G35:J35,{1,2,3})))/3*2>20,20,TRUNC((SUMPRODUCT(LARGE(G35:J35,{1,2,3})))/3*2,2)) -> 20 | M35: =if((SUMPRODUCT(LARGE(G35:J35,{1,2,3}))+K35/2)/3*2>20,20,TRUNC((SUMPRODUCT(LARGE(G35:J35,{1,2,3}))+K35/2)/3*2,2)) -> 20
A36: =Worksheet!A36 -> 24301546 | B36: =Worksheet!B36 -> Manjurul Ahsan Hemel | C36: 5 | D36: 10 | E36: 3 | F36: 10 | G36: =C36 -> 5 | H36: =D36 -> 10 | I36: =E36 -> 3 | J36: =if(F36<10,F36,10) -> 10 | K36: =if(F36>10,F36-10,0) -> 0 | L36: =if((SUMPRODUCT(LARGE(G36:J36,{1,2,3})))/3*2>20,20,TRUNC((SUMPRODUCT(LARGE(G36:J36,{1,2,3})))/3*2,2)) -> 16.66 | M36: =if((SUMPRODUCT(LARGE(G36:J36,{1,2,3}))+K36/2)/3*2>20,20,TRUNC((SUMPRODUCT(LARGE(G36:J36,{1,2,3}))+K36/2)/3*2,2)) -> 16.66
A37: =Worksheet!A37 -> 24315010 | B37: =Worksheet!B37 -> Saadat Khan | C37: 8 | D37: 5 | E37: 8 | G37: =C37 -> 8 | H37: =D37 -> 5 | I37: =E37 -> 8 | J37: =if(F37<10,F37,10) | K37: =if(F37>10,F37-10,0) -> 0 | L37: =if((SUMPRODUCT(LARGE(G37:J37,{1,2,3})))/3*2>20,20,TRUNC((SUMPRODUCT(LARGE(G37:J37,{1,2,3})))/3*2,2)) -> 14 | M37: =if((SUMPRODUCT(LARGE(G37:J37,{1,2,3}))+K37/2)/3*2>20,20,TRUNC((SUMPRODUCT(LARGE(G37:J37,{1,2,3}))+K37/2)/3*2,2)) -> 14
A38: =Worksheet!A38 -> 24321222 | B38: =Worksheet!B38 -> Mir Mainul Ahmed | C38: 9 | D38: 10 | E38: 10 | F38: 12 | G38: =C38 -> 9 | H38: =D38 -> 10 | I38: =E38 -> 10 | J38: =if(F38<10,F38,10) -> 10 | K38: =if(F38>10,F38-10,0) -> 2 | L38: =if((SUMPRODUCT(LARGE(G38:J38,{1,2,3})))/3*2>20,20,TRUNC((SUMPRODUCT(LARGE(G38:J38,{1,2,3})))/3*2,2)) -> 20 | M38: =if((SUMPRODUCT(LARGE(G38:J38,{1,2,3}))+K38/2)/3*2>20,20,TRUNC((SUMPRODUCT(LARGE(G38:J38,{1,2,3}))+K38/2)/3*2,2)) -> 20

Sheet Assignment
A1: Student Id | C1: A1 | D1: A2 | E1: A3 | F1: A4 | G1: Assignment (out of 5)
A2: =IFERROR(__xludf.DUMMYFUNCTION("IMPORTRANGE(""https://docs.google.com/spreadsheets/d/1tmyDd48UzVWk1pBjmWjdHkBHYbZX9G9Y-Lh0NOCkbc8/edit?resourcekey=&gid=385477979#gid=385477979"", ""Sheet5!A77:F113"")"),2.2101165E7) -> 22101165 | B2: =IFERROR(__xludf.DUMMYFUNCTION("""COMPUTED_VALUE"""),"Asif Mahmud") -> Asif Mahmud | C2: =IFERROR(__xludf.DUMMYFUNCTION("""COMPUTED_VALUE"""),0.0) -> 0 | D2: =IFERROR(__xludf.DUMMYFUNCTION("""COMPUTED_VALUE"""),0.0) -> 0 | E2: =IFERROR(__xludf.DUMMYFUNCTION("""COMPUTED_VALUE"""),0.0) -> 0 | F2: =IFERROR(__xludf.DUMMYFUNCTION("""COMPUTED_VALUE"""),0.0) -> 0 | G2: =SUM(C2:F2)/4 -> 0
A3: =IFERROR(__xludf.DUMMYFUNCTION("""COMPUTED_VALUE"""),2.2101192E7) -> 22101192 | B3: =IFERROR(__xludf.DUMMYFUNCTION("""COMPUTED_VALUE"""),"Maliha Anan Promi") -> Maliha Anan Promi | C3: =IFERROR(__xludf.DUMMYFUNCTION("""COMPUTED_VALUE"""),5.0) -> 5 | D3: =IFERROR(__xludf.DUMMYFUNCTION("""COMPUTED_VALUE"""),5.0) -> 5 | E3: =IFERROR(__xludf.DUMMYFUNCTION("""COMPUTED_VALUE"""),5.0) -> 5 | F3: =IFERROR(__xludf.DUMMYFUNCTION("""COMPUTED_VALUE"""),5.0) -> 5 | G3: =SUM(C3:F3)/4 -> 5
A4: =IFERROR(__xludf.DUMMYFUNCTION("""COMPUTED_VALUE"""),2.2101297E7) -> 22101297 | B4: =IFERROR(__xludf.DUMMYFUNCTION("""COMPUTED_VALUE"""),"Parthib Biswas") -> Parthib Biswas | C4: =IFERROR(__xludf.DUMMYFUNCTION("""COMPUTED_VALUE"""),0.0) -> 0 | D4: =IFERROR(__xludf.DUMMYFUNCTION("""COMPUTED_VALUE"""),5.0) -> 5 | E4: =IFERROR(__xludf.DUMMYFUNCTION("""COMPUTED_VALUE"""),5.0) -> 5 | F4: =IFERROR(__xludf.DUMMYFUNCTION("""COMPUTED_VALUE"""),5.0) -> 5 | G4: =SUM(C4:F4)/4 -> 3.75
A5: =IFERROR(__xludf.DUMMYFUNCTION("""COMPUTED_VALUE"""),2.2201706E7) -> 22201706 | B5: =IFERROR(__xludf.DUMMYFUNCTION("""COMPUTED_VALUE"""),"Sadnan Basher") -> Sadnan Basher | C5: =IFERROR(__xludf.DUMMYFUNCTION("""COMPUTED_VALUE"""),5.0) -> 5 | D5: =IFERROR(__xludf.DUMMYFUNCTION("""COMPUTED_VALUE"""),5.0) -> 5 | E5: =IFERROR(__xludf.DUMMYFUNCTION("""COMPUTED_VALUE"""),5.0) -> 5 | F5: =IFERROR(__xludf.DUMMYFUNCTION("""COMPUTED_VALUE"""),0.0) -> 0 | G5: =SUM(C5:F5)/4 -> 3.75
A6: =IFERROR(__xludf.DUMMYFUNCTION("""COMPUTED_VALUE"""),2.2301485E7) -> 22301485 | B6: =IFERROR(__xludf.DUMMYFUNCTION("""COMPUTED_VALUE"""),"Tamal Kumar Dey") -> Tamal Kumar Dey | C6: =IFERROR(__xludf.DUMMYFUNCTION("""COMPUTED_VALUE"""),5.0) -> 5 | D6: =IFERROR(__xludf.DUMMYFUNCTION("""COMPUTED_VALUE"""),5.0) -> 5 | E6: =IFERROR(__xludf.DUMMYFUNCTION("""COMPUTED_VALUE"""),5.0) -> 5 | F6: =IFERROR(__xludf.DUMMYFUNCTION("""COMPUTED_VALUE"""),5.0) -> 5 | G6: =SUM(C6:F6)/4 -> 5
A7: =IFERROR(__xludf.DUMMYFUNCTION("""COMPUTED_VALUE"""),2.2301581E7) -> 22301581 | B7: =IFERROR(__xludf.DUMMYFUNCTION("""COMPUTED_VALUE"""),"Rufaida Zoon Raiyan") -> Rufaida Zoon Raiyan | C7: =IFERROR(__xludf.DUMMYFUNCTION("""COMPUTED_VALUE"""),5.0) -> 5 | D7: =IFERROR(__xludf.DUMMYFUNCTION("""COMPUTED_VALUE"""),5.0) -> 5 | E7: =IFERROR(__xludf.DUMMYFUNCTION("""COMPUTED_VALUE"""),5.0) -> 5 | F7: =IFERROR(__xludf.DUMMYFUNCTION("""COMPUTED_VALUE"""),5.0) -> 5 | G7: =SUM(C7:F7)/4 -> 5
A8: =IFERROR(__xludf.DUMMYFUNCTION("""COMPUTED_VALUE"""),2.3101152E7) -> 23101152 | B8: =IFERROR(__xludf.DUMMYFUNCTION("""COMPUTED_VALUE"""),"Shihabul Ishraq Tanim") -> Shihabul Ishraq Tanim | C8: =IFERROR(__xludf.DUMMYFUNCTION("""COMPUTED_VALUE"""),5.0) -> 5 | D8: =IFERROR(__xludf.DUMMYFUNCTION("""COMPUTED_VALUE"""),5.0) -> 5 | E8: =IFERROR(__xludf.DUMMYFUNCTION("""COMPUTED_VALUE"""),5.0) -> 5 | F8: =IFERROR(__xludf.DUMMYFUNCTION("""COMPUTED_VALUE"""),5.0) -> 5 | G8: =SUM(C8:F8)/4 -> 5
A9: =IFERROR(__xludf.DUMMYFUNCTION("""COMPUTED_VALUE"""),2.3101196E7) -> 23101196 | B9: =IFERROR(__xludf.DUMMYFUNCTION("""COMPUTED_VALUE"""),"Nandini Das Jhumu") -> Nandini Das Jhumu | C9: =IFERROR(__xludf.DUMMYFUNCTION("""COMPUTED_VALUE"""),5.0) -> 5 | D9: =IFERROR(__xludf.DUMMYFUNCTION("""COMPUTED_VALUE"""),5.0) -> 5 | E9: =IFERROR(__xludf.DUMMYFUNCTION("""COMPUTED_VALUE"""),5.0) -> 5 | F9: =IFERROR(__xludf.DUMMYFUNCTION("""COMPUTED_VALUE"""),5.0) -> 5 | G9: =SUM(C9:F9)/4 -> 5
A10: =IFERROR(__xludf.DUMMYFUNCTION("""COMPUTED_VALUE"""),2.3201055E7) -> 23201055 | B10: =IFERROR(__xludf.DUMMYFUNCTION("""COMPUTED_VALUE"""),"Ridwanul Azim") -> Ridwanul Azim | C10: =IFERROR(__xludf.DUMMYFUNCTION("""COMPUTED_VALUE"""),0.0) -> 0 | D10: =IFERROR(__xludf.DUMMYFUNCTION("""COMPUTED_VALUE"""),0.0) -> 0 | E10: =IFERROR(__xludf.DUMMYFUNCTION("""COMPUTED_VALUE"""),0.0) -> 0 | F10: =IFERROR(__xludf.DUMMYFUNCTION("""COMPUTED_VALUE"""),0.0) -> 0 | G10: =SUM(C10:F10)/4 -> 0
A11: =IFERROR(__xludf.DUMMYFUNCTION("""COMPUTED_VALUE"""),2.3301401E7) -> 23301401 | B11: =IFERROR(__xludf.DUMMYFUNCTION("""COMPUTED_VALUE"""),"Saddat Hossain Sifat") -> Saddat Hossain Sifat | C11: =IFERROR(__xludf.DUMMYFUNCTION("""COMPUTED_VALUE"""),5.0) -> 5 | D11: =IFERROR(__xludf.DUMMYFUNCTION("""COMPUTED_VALUE"""),5.0) -> 5 | E11: =IFERROR(__xludf.DUMMYFUNCTION("""COMPUTED_VALUE"""),5.0) -> 5 | F11: =IFERROR(__xludf.DUMMYFUNCTION("""COMPUTED_VALUE"""),5.0) -> 5 | G11: =SUM(C11:F11)/4 -> 5
A12: =IFERROR(__xludf.DUMMYFUNCTION("""COMPUTED_VALUE"""),2.4101043E7) -> 24101043 | B12: =IFERROR(__xludf.DUMMYFUNCTION("""COMPUTED_VALUE"""),"Md Abu Noman Kabbo") -> Md Abu Noman Kabbo | C12: =IFERROR(__xludf.DUMMYFUNCTION("""COMPUTED_VALUE"""),0.0) -> 0 | D12: =IFERROR(__xludf.DUMMYFUNCTION("""COMPUTED_VALUE"""),0.0) -> 0 | E12: =IFERROR(__xludf.DUMMYFUNCTION("""COMPUTED_VALUE"""),0.0) -> 0 | F12: =IFERROR(__xludf.DUMMYFUNCTION("""COMPUTED_VALUE"""),0.0) -> 0 | G12: =SUM(C12:F12)/4 -> 0
A13: =IFERROR(__xludf.DUMMYFUNCTION("""COMPUTED_VALUE"""),2.4101081E7) -> 24101081 | B13: =IFERROR(__xludf.DUMMYFUNCTION("""COMPUTED_VALUE"""),"Adil Abdullah Mahdi") -> Adil Abdullah Mahdi | C13: =IFERROR(__xludf.DUMMYFUNCTION("""COMPUTED_VALUE"""),5.0) -> 5 | D13: =IFERROR(__xludf.DUMMYFUNCTION("""COMPUTED_VALUE"""),5.0) -> 5 | E13: =IFERROR(__xludf.DUMMYFUNCTION("""COMPUTED_VALUE"""),5.0) -> 5 | F13: =IFERROR(__xludf.DUMMYFUNCTION("""COMPUTED_VALUE"""),5.0) -> 5 | G13: =SUM(C13:F13)/4 -> 5
A14: =IFERROR(__xludf.DUMMYFUNCTION("""COMPUTED_VALUE"""),2.4101103E7) -> 24101103 | B14: =IFERROR(__xludf.DUMMYFUNCTION("""COMPUTED_VALUE"""),"Zunayed Amin") -> Zunayed Amin | C14: =IFERROR(__xludf.DUMMYFUNCTION("""COMPUTED_VALUE"""),5.0) -> 5 | D14: =IFERROR(__xludf.DUMMYFUNCTION("""COMPUTED_VALUE"""),5.0) -> 5 | E14: =IFERROR(__xludf.DUMMYFUNCTION("""COMPUTED_VALUE"""),5.0) -> 5 | F14: =IFERROR(__xludf.DUMMYFUNCTION("""COMPUTED_VALUE"""),5.0) -> 5 | G14: =SUM(C14:F14)/4 -> 5
A15: =IFERROR(__xludf.DUMMYFUNCTION("""COMPUTED_VALUE"""),2.4110031E7) -> 24110031 | B15: =IFERROR(__xludf.DUMMYFUNCTION("""COMPUTED_VALUE"""),"Sm Mostofa Morshed Sayeem") -> Sm Mostofa Morshed Sayeem | C15: =IFERROR(__xludf.DUMMYFUNCTION("""COMPUTED_VALUE"""),0.0) -> 0 | D15: =IFERROR(__xludf.DUMMYFUNCTION("""COMPUTED_VALUE"""),0.0) -> 0 | E15: =IFERROR(__xludf.DUMMYFUNCTION("""COMPUTED_VALUE"""),0.0) -> 0 | F15: =IFERROR(__xludf.DUMMYFUNCTION("""COMPUTED_VALUE"""),0.0) -> 0 | G15: =SUM(C15:F15)/4 -> 0
A16: =IFERROR(__xludf.DUMMYFUNCTION("""COMPUTED_VALUE"""),2.420114E7) -> 24201140 | B16: =IFERROR(__xludf.DUMMYFUNCTION("""COMPUTED_VALUE"""),"Mehrab Rashid Mugdha") -> Mehrab Rashid Mugdha | C16: =IFERROR(__xludf.DUMMYFUNCTION("""COMPUTED_VALUE"""),5.0) -> 5 | D16: =IFERROR(__xludf.DUMMYFUNCTION("""COMPUTED_VALUE"""),5.0) -> 5 | E16: =IFERROR(__xludf.DUMMYFUNCTION("""COMPUTED_VALUE"""),5.0) -> 5 | F16: =IFERROR(__xludf.DUMMYFUNCTION("""COMPUTED_VALUE"""),5.0) -> 5 | G16: =SUM(C16:F16)/4 -> 5
